Workbook

Sheet 0. Instructions
A1: FOREST CARBON CALCULATOR
B2: WWF-Canada Carbon Measurement · Forest Carbon Workshop
A4: What this workbook does | B4: Turns field measurements of trees, understory and soil into a carbon stock in kg C/m², then scales plots to sites and to your whole study area. It follows 'Measuring Carbon in Trees' and 'Measuring Carbon in Non-Peat Soils' (WWF-Canada, 2026).
A6: COLOUR KEY
A7: Yellow | B7: TYPE HERE — field measurements you record.
A8: Blue | B8: TYPE HERE — lab results, once they come back.
A9: Grey | B9: Calculated for you. Do not type in grey cells.
A10: Green | B10: Summary output.
A11: Red | B11: A quality-control flag. Read it before trusting the row.
A13: ORDER OF WORK
A14: 1 | B14: Fill '1. Plot & Site Log' FIRST — one row per plot. Everything else joins to it on Plot ID.
A15: 2 | B15: Fill '2. Tree Data', '3. Understory Data' and '4. Soil Data' as the field data comes in.
A16: 3 | B16: Add lab results (blue columns) to '3. Understory Data' and '4. Soil Data' when they return.
A17: 4 | B17: Read '5. Plot Summary' and '6. Site Summary'. Both calculate themselves.
A19: ⚠ PLOT IDs MUST MATCH | B19: Plot ID is the key that joins every sheet. If a Plot ID on the Tree, Understory or Soil sheet does not appear in the Plot & Site Log, that row's plot area cannot be looked up and its carbon will not reach the summary. The QC flag column will tell you.
A21: UNITS
A22: DBH | B22: centimetres (cm), measured at 1.3 m above ground
A23: Tree height | B23: metres (m)
A24: Shrub L / W / H | B24: metres (m)
A25: Depths | B25: centimetres (cm), measured down from the soil surface
A26: Bulk density | B26: g/cm³ — oven-dry fine earth (<2 mm) ÷ total sample volume (see '4. Soil Data')
A27: Carbon content | B27: per cent of dry mass (%)
A28: Carbon stock | B28: kg C/m² at plot and site level; kg C for totals
A30: WHERE THE NUMBERS COME FROM
A31: Tree biomass | B31: Lambert, Ung & Raulier (2005) and Ung, Bernier & Guo (2008) — Canadian national biomass equations. See 'R1. Tree Coefficients'.
A32: Tree roots | B32: Root:shoot relationships, 'Measuring Carbon in Trees' p.17. See the note on 'R1. Tree Coefficients'.
A33: Shrub biomass | B33: Flade et al. (2020). See 'R2. Understory Coefficients'.
A34: Soil carbon | B34: 'Measuring Carbon in Non-Peat Soils' pp.23–24, Eq 1–4.
A35: Carbon fraction | B35: 0.5 of dry biomass, and 0.5 of soil organic matter. Set on '8. Settings'.
A37: BEFORE YOU START | B37: Open '8. Settings' and confirm the reporting depth, the plot sizes your crew actually used, and your precision target from Part 2 of the workshop.

Sheet 1. Plot & Site Log
A1: PLOT & SITE LOG
A2: ONE ROW PER PLOT. This is the key every other sheet joins to. Fill this in first. Leave the plot-area columns at your standard sizes unless a plot was laid out differently. 'Slope allowance applied in field?' — answer Yes if you lengthened the tape on the slope (Trees guide, Appendix); answer No if you laid out the nominal distance along the ground, and the effective area will be corrected for you.
A4: Plot ID | B4: Site ID | C4: Study area | D4: Date | E4: Location | F4: Latitude | G4: Longitude | H4: GNSS accuracy (m) | I4: Datum | J4: Elevation (m) | K4: Plot shape | L4: Large plot area (m²) | M4: Medium plot area (m²) | N4: Small plot area (m²) | O4: Slope S–N (°) | P4: Slope E–W (°) | Q4: Slope allowance applied in field? | R4: Effective large plot area (m²) | S4: Notes
A5: MR-01 | B5: S1 | C5: MR | D5: 2026-07-14 | E5: Moose Ridge upland | F5: 51.4412 | G5: -84.2018 | H5: 0.4 | I5: WGS84 | J5: 214 | K5: circular | L5: 400 | M5: 100 | N5: 1 | O5: 3.2 | P5: -1.8 | Q5: Yes | R5: =IF($L5="","",IF($Q5="Yes",$L5,IF(OR($O5="",$P5=""),$L5,$L5*COS(RADIANS(ABS($O5)))*COS(RADIANS(ABS($P5)))))) -> 400
A6: MR-02 | B6: S1 | C6: MR | D6: 2026-07-14 | E6: Moose Ridge upland | F6: 51.4438 | G6: -84.1975 | H6: 0.5 | I6: WGS84 | J6: 219 | K6: circular | L6: 400 | M6: 100 | N6: 1 | O6: 6.1 | P6: 2.4 | Q6: Yes | R6: =IF($L6="","",IF($Q6="Yes",$L6,IF(OR($O6="",$P6=""),$L6,$L6*COS(RADIANS(ABS($O6)))*COS(RADIANS(ABS($P6)))))) -> 400
A7: MR-03 | B7: S1 | C7: MR | D7: 2026-07-15 | E7: Moose Ridge upland | F7: 51.4401 | G7: -84.1932 | H7: 0.4 | I7: WGS84 | J7: 208 | K7: circular | L7: 400 | M7: 100 | N7: 1 | O7: 11.5 | P7: 4 | Q7: No | R7: =IF($L7="","",IF($Q7="Yes",$L7,IF(OR($O7="",$P7=""),$L7,$L7*COS(RADIANS(ABS($O7)))*COS(RADIANS(ABS($P7)))))) -> 391.01506
A8: BC-01 | B8: S2 | C8: MR | D8: 2026-07-16 | E8: Beaver Creek lowland | F8: 51.4288 | G8: -84.2211 | H8: 0.6 | I8: WGS84 | J8: 186 | K8: square | L8: 400 | M8: 100 | N8: 1 | O8: 1.1 | P8: -0.7 | Q8: Yes | R8: =IF($L8="","",IF($Q8="Yes",$L8,IF(OR($O8="",$P8=""),$L8,$L8*COS(RADIANS(ABS($O8)))*COS(RADIANS(ABS($P8)))))) -> 400
A9: BC-02 | B9: S2 | C9: MR | D9: 2026-07-16 | E9: Beaver Creek lowland | F9: 51.4265 | G9: -84.2168 | H9: 0.5 | I9: WGS84 | J9: 184 | K9: square | L9: 400 | M9: 100 | N9: 1 | O9: 2 | P9: 1.2 | Q9: Yes | R9: =IF($L9="","",IF($Q9="Yes",$L9,IF(OR($O9="",$P9=""),$L9,$L9*COS(RADIANS(ABS($O9)))*COS(RADIANS(ABS($P9)))))) -> 400
A10: BC-03 | B10: S2 | C10: MR | D10: 2026-07-17 | E10: Beaver Creek lowland | F10: 51.4301 | G10: -84.2245 | H10: 0.7 | I10: WGS84 | J10: 188 | K10: square | L10: 400 | M10: 100 | N10: 1 | O10: 0.8 | P10: -0.4 | Q10: Yes | R10: =IF($L10="","",IF($Q10="Yes",$L10,IF(OR($O10="",$P10=""),$L10,$L10*COS(RADIANS(ABS($O10)))*COS(RADIANS(ABS($P10)))))) -> 400
R11: =IF($L11="","",IF($Q11="Yes",$L11,IF(OR($O11="",$P11=""),$L11,$L11*COS(RADIANS(ABS($O11)))*COS(RADIANS(ABS($P11))))))
R12: =IF($L12="","",IF($Q12="Yes",$L12,IF(OR($O12="",$P12=""),$L12,$L12*COS(RADIANS(ABS($O12)))*COS(RADIANS(ABS($P12))))))
R13: =IF($L13="","",IF($Q13="Yes",$L13,IF(OR($O13="",$P13=""),$L13,$L13*COS(RADIANS(ABS($O13)))*COS(RADIANS(ABS($P13))))))
R14: =IF($L14="","",IF($Q14="Yes",$L14,IF(OR($O14="",$P14=""),$L14,$L14*COS(RADIANS(ABS($O14)))*COS(RADIANS(ABS($P14))))))
R15: =IF($L15="","",IF($Q15="Yes",$L15,IF(OR($O15="",$P15=""),$L15,$L15*COS(RADIANS(ABS($O15)))*COS(RADIANS(ABS($P15))))))
R16: =IF($L16="","",IF($Q16="Yes",$L16,IF(OR($O16="",$P16=""),$L16,$L16*COS(RADIANS(ABS($O16)))*COS(RADIANS(ABS($P16))))))
R17: =IF($L17="","",IF($Q17="Yes",$L17,IF(OR($O17="",$P17=""),$L17,$L17*COS(RADIANS(ABS($O17)))*COS(RADIANS(ABS($P17))))))
R18: =IF($L18="","",IF($Q18="Yes",$L18,IF(OR($O18="",$P18=""),$L18,$L18*COS(RADIANS(ABS($O18)))*COS(RADIANS(ABS($P18))))))
R19: =IF($L19="","",IF($Q19="Yes",$L19,IF(OR($O19="",$P19=""),$L19,$L19*COS(RADIANS(ABS($O19)))*COS(RADIANS(ABS($P19))))))
R20: =IF($L20="","",IF($Q20="Yes",$L20,IF(OR($O20="",$P20=""),$L20,$L20*COS(RADIANS(ABS($O20)))*COS(RADIANS(ABS($P20))))))
R21: =IF($L21="","",IF($Q21="Yes",$L21,IF(OR($O21="",$P21=""),$L21,$L21*COS(RADIANS(ABS($O21)))*COS(RADIANS(ABS($P21))))))
R22: =IF($L22="","",IF($Q22="Yes",$L22,IF(OR($O22="",$P22=""),$L22,$L22*COS(RADIANS(ABS($O22)))*COS(RADIANS(ABS($P22))))))
... R64: =IF($L64="","",IF($Q64="Yes",$L64,IF(OR($O64="",$P64=""),$L64,$L64*COS(RADIANS(ABS($O64)))*COS(RADIANS(ABS($P64))))))

Sheet 2. Core Log
A1: CORE LOG
A2: ONE ROW PER CORE OR PIT. Matches the 'Core Notes' block on the paper Soil Carbon Data Sheet. Hole depth is the true depth of the ground you sampled; core length is what you recovered — the difference is compaction (Non-peat guide, Sampling).
A4: Core ID | B4: Plot ID | C4: Latitude | D4: Longitude | E4: Sampling method | F4: Hole depth (cm) | G4: Core length recovered (cm) | H4: Compaction factor | I4: Depth to substratum (cm) | J4: Photo series taken? | K4: Deepest slice logged (cm) | L4: Stock to reporting depth (kg C/m²) | M4: Stock, full core (kg C/m²) | N4: Reaches reporting depth? | O4: QC flags | P4: Notes
A5: MR-01-C1 | B5: MR-01 | C5: 51.4225 | D5: -84.20415 | E5: Soil core | F5: 50 | G5: 49 | H5: =IF(OR($F5="",$G5="",$G5=0),"",$F5/$G5) -> 1.0204082 | I5: 50 | J5: Yes | K5: =IF($A5="","",IF(SUMPRODUCT(MAX(('5. Soil Data'!$B$5:$B$504=$A5)*'5. Soil Data'!$E$5:$E$504))=0,"",SUMPRODUCT(MAX(('5. Soil Data'!$B$5:$B$504=$A5)*'5. Soil Data'!$E$5:$E$504)))) -> 50 | L5: =IF($A5="","",IFERROR(SUMIFS('5. Soil Data'!$O$5:$O$504,'5. Soil Data'!$B$5:$B$504,$A5),"")) -> 10.470085 | M5: =IF($A5="","",IFERROR(SUMIFS('5. Soil Data'!$P$5:$P$504,'5. Soil Data'!$B$5:$B$504,$A5),"")) -> 12.303385 | N5: =IF($K5="","",IF($K5>=REPORTING_DEPTH_CM,"Yes","No")) -> Yes | O5: =IF($A5="","",IF(AND($B5<>"",COUNTIF('1. Plot & Site Log'!$A$5:$A$64,$B5)=0),"Plot ID not in Plot & Site Log. ","")&IF($K5="","No soil slices logged for this core. ","")&IF($N5="No","Core stops short of the reporting depth — its depth-limited stock is an underestimate. ","")&IF(AND($H5<>"",$H5>1.05),"Core compacted by "&TEXT(($H5-1)*100,"0")&"%: slice depths in the tube sit shallower than in the ground, so the depth-limited stock is biased. Full-core stock is unaffected. ","")&IF(AND($H5<>"",$H5<0.98),"Core length exceeds hole depth — check the two measurements. ",""))
A6: MR-01-C2 | B6: MR-01 | C6: 51.43711 | D6: -84.20424 | E6: Soil core | F6: 30 | G6: 27.5 | H6: =IF(OR($F6="",$G6="",$G6=0),"",$F6/$G6) -> 1.0909091 | I6: 30 | J6: Yes | K6: =IF($A6="","",IF(SUMPRODUCT(MAX(('5. Soil Data'!$B$5:$B$504=$A6)*'5. Soil Data'!$E$5:$E$504))=0,"",SUMPRODUCT(MAX(('5. Soil Data'!$B$5:$B$504=$A6)*'5. Soil Data'!$E$5:$E$504)))) -> 30 | L6: =IF($A6="","",IFERROR(SUMIFS('5. Soil Data'!$O$5:$O$504,'5. Soil Data'!$B$5:$B$504,$A6),"")) -> 10.621455 | M6: =IF($A6="","",IFERROR(SUMIFS('5. Soil Data'!$P$5:$P$504,'5. Soil Data'!$B$5:$B$504,$A6),"")) -> 10.621455 | N6: =IF($K6="","",IF($K6>=REPORTING_DEPTH_CM,"Yes","No")) -> Yes | O6: =IF($A6="","",IF(AND($B6<>"",COUNTIF('1. Plot & Site Log'!$A$5:$A$64,$B6)=0),"Plot ID not in Plot & Site Log. ","")&IF($K6="","No soil slices logged for this core. ","")&IF($N6="No","Core stops short of the reporting depth — its depth-limited stock is an underestimate. ","")&IF(AND($H6<>"",$H6>1.05),"Core compacted by "&TEXT(($H6-1)*100,"0")&"%: slice depths in the tube sit shallower than in the ground, so the depth-limited stock is biased. Full-core stock is unaffected. ","")&IF(AND($H6<>"",$H6<0.98),"Core length exceeds hole depth — check the two measurements. ","")) -> Core compacted by 9%: slice depths in the tube sit shallower than in the ground, so the depth-limited stock is biased. Full-core stock is unaffected.
A7: MR-02-C1 | B7: MR-02 | C7: 51.4357 | D7: -84.20137 | E7: Soil core | F7: 40 | G7: 36.8 | H7: =IF(OR($F7="",$G7="",$G7=0),"",$F7/$G7) -> 1.0869565 | I7: 40 | J7: Yes | K7: =IF($A7="","",IF(SUMPRODUCT(MAX(('5. Soil Data'!$B$5:$B$504=$A7)*'5. Soil Data'!$E$5:$E$504))=0,"",SUMPRODUCT(MAX(('5. Soil Data'!$B$5:$B$504=$A7)*'5. Soil Data'!$E$5:$E$504)))) -> 40 | L7: =IF($A7="","",IFERROR(SUMIFS('5. Soil Data'!$O$5:$O$504,'5. Soil Data'!$B$5:$B$504,$A7),"")) -> 10.50648 | M7: =IF($A7="","",IFERROR(SUMIFS('5. Soil Data'!$P$5:$P$504,'5. Soil Data'!$B$5:$B$504,$A7),"")) -> 11.32278 | N7: =IF($K7="","",IF($K7>=REPORTING_DEPTH_CM,"Yes","No")) -> Yes | O7: =IF($A7="","",IF(AND($B7<>"",COUNTIF('1. Plot & Site Log'!$A$5:$A$64,$B7)=0),"Plot ID not in Plot & Site Log. ","")&IF($K7="","No soil slices logged for this core. ","")&IF($N7="No","Core stops short of the reporting depth — its depth-limited stock is an underestimate. ","")&IF(AND($H7<>"",$H7>1.05),"Core compacted by "&TEXT(($H7-1)*100,"0")&"%: slice depths in the tube sit shallower than in the ground, so the depth-limited stock is biased. Full-core stock is unaffected. ","")&IF(AND($H7<>"",$H7<0.98),"Core length exceeds hole depth — check the two measurements. ","")) -> Core compacted by 9%: slice depths in the tube sit shallower than in the ground, so the depth-limited stock is biased. Full-core stock is unaffected.
A8: MR-03-C1 | B8: MR-03 | C8: 51.42047 | D8: -84.20285 | E8: Soil core | F8: 22 | G8: 20.9 | H8: =IF(OR($F8="",$G8="",$G8=0),"",$F8/$G8) -> 1.0526316 | I8: 22 | J8: Yes | K8: =IF($A8="","",IF(SUMPRODUCT(MAX(('5. Soil Data'!$B$5:$B$504=$A8)*'5. Soil Data'!$E$5:$E$504))=0,"",SUMPRODUCT(MAX(('5. Soil Data'!$B$5:$B$504=$A8)*'5. Soil Data'!$E$5:$E$504)))) -> 22 | L8: =IF($A8="","",IFERROR(SUMIFS('5. Soil Data'!$O$5:$O$504,'5. Soil Data'!$B$5:$B$504,$A8),"")) -> 9.756524 | M8: =IF($A8="","",IFERROR(SUMIFS('5. Soil Data'!$P$5:$P$504,'5. Soil Data'!$B$5:$B$504,$A8),"")) -> 9.756524 | N8: =IF($K8="","",IF($K8>=REPORTING_DEPTH_CM,"Yes","No")) -> No | O8: =IF($A8="","",IF(AND($B8<>"",COUNTIF('1. Plot & Site Log'!$A$5:$A$64,$B8)=0),"Plot ID not in Plot & Site Log. ","")&IF($K8="","No soil slices logged for this core. ","")&IF($N8="No","Core stops short of the reporting depth — its depth-limited stock is an underestimate. ","")&IF(AND($H8<>"",$H8>1.05),"Core compacted by "&TEXT(($H8-1)*100,"0")&"%: slice depths in the tube sit shallower than in the ground, so the depth-limited stock is biased. Full-core stock is unaffected. ","")&IF(AND($H8<>"",$H8<0.98),"Core length exceeds hole depth — check the two measurements. ","")) -> Core stops short of the reporting depth — its depth-limited stock is an underestimate. Core compacted by 5%: slice depths in the tube sit shallower than in the ground, so the depth-limited stock is biased. Full-core stock is unaffected.
A9: BC-01-C1 | B9: BC-01 | C9: 51.4275 | D9: -84.21008 | E9: Soil core | F9: 50 | G9: 47.3 | H9: =IF(OR($F9="",$G9="",$G9=0),"",$F9/$G9) -> 1.0570825 | I9: 50 | J9: Yes | K9: =IF($A9="","",IF(SUMPRODUCT(MAX(('5. Soil Data'!$B$5:$B$504=$A9)*'5. Soil Data'!$E$5:$E$504))=0,"",SUMPRODUCT(MAX(('5. Soil Data'!$B$5:$B$504=$A9)*'5. Soil Data'!$E$5:$E$504)))) -> 50 | L9: =IF($A9="","",IFERROR(SUMIFS('5. Soil Data'!$O$5:$O$504,'5. Soil Data'!$B$5:$B$504,$A9),"")) -> 11.889705 | M9: =IF($A9="","",IFERROR(SUMIFS('5. Soil Data'!$P$5:$P$504,'5. Soil Data'!$B$5:$B$504,$A9),"")) -> 13.761845 | N9: =IF($K9="","",IF($K9>=REPORTING_DEPTH_CM,"Yes","No")) -> Yes | O9: =IF($A9="","",IF(AND($B9<>"",COUNTIF('1. Plot & Site Log'!$A$5:$A$64,$B9)=0),"Plot ID not in Plot & Site Log. ","")&IF($K9="","No soil slices logged for this core. ","")&IF($N9="No","Core stops short of the reporting depth — its depth-limited stock is an underestimate. ","")&IF(AND($H9<>"",$H9>1.05),"Core compacted by "&TEXT(($H9-1)*100,"0")&"%: slice depths in the tube sit shallower than in the ground, so the depth-limited stock is biased. Full-core stock is unaffected. ","")&IF(AND($H9<>"",$H9<0.98),"Core length exceeds hole depth — check the two measurements. ","")) -> Core compacted by 6%: slice depths in the tube sit shallower than in the ground, so the depth-limited stock is biased. Full-core stock is unaffected.
A10: BC-01-C2 | B10: BC-01 | C10: 51.42675 | D10: -84.20708 | E10: Soil core | F10: 50 | G10: 49.8 | H10: =IF(OR($F10="",$G10="",$G10=0),"",$F10/$G10) -> 1.0040161 | I10: 50 | J10: Yes | K10: =IF($A10="","",IF(SUMPRODUCT(MAX(('5. Soil Data'!$B$5:$B$504=$A10)*'5. Soil Data'!$E$5:$E$504))=0,"",SUMPRODUCT(MAX(('5. Soil Data'!$B$5:$B$504=$A10)*'5. Soil Data'!$E$5:$E$504)))) -> 50 | L10: =IF($A10="","",IFERROR(SUMIFS('5. Soil Data'!$O$5:$O$504,'5. Soil Data'!$B$5:$B$504,$A10),"")) -> 11.3162 | M10: =IF($A10="","",IFERROR(SUMIFS('5. Soil Data'!$P$5:$P$504,'5. Soil Data'!$B$5:$B$504,$A10),"")) -> 13.1242 | N10: =IF($K10="","",IF($K10>=REPORTING_DEPTH_CM,"Yes","No")) -> Yes | O10: =IF($A10="","",IF(AND($B10<>"",COUNTIF('1. Plot & Site Log'!$A$5:$A$64,$B10)=0),"Plot ID not in Plot & Site Log. ","")&IF($K10="","No soil slices logged for this core. ","")&IF($N10="No","Core stops short of the reporting depth — its depth-limited stock is an underestimate. ","")&IF(AND($H10<>"",$H10>1.05),"Core compacted by "&TEXT(($H10-1)*100,"0")&"%: slice depths in the tube sit shallower than in the ground, so the depth-limited stock is biased. Full-core stock is unaffected. ","")&IF(AND($H10<>"",$H10<0.98),"Core length exceeds hole depth — check the two measurements. ",""))
A11: BC-02-C1 | B11: BC-02 | C11: 51.44 | D11: -84.20575 | E11: Soil core | F11: 40 | G11: 35.8 | H11: =IF(OR($F11="",$G11="",$G11=0),"",$F11/$G11) -> 1.1173184 | I11: 40 | J11: Yes | K11: =IF($A11="","",IF(SUMPRODUCT(MAX(('5. Soil Data'!$B$5:$B$504=$A11)*'5. Soil Data'!$E$5:$E$504))=0,"",SUMPRODUCT(MAX(('5. Soil Data'!$B$5:$B$504=$A11)*'5. Soil Data'!$E$5:$E$504)))) -> 40 | L11: =IF($A11="","",IFERROR(SUMIFS('5. Soil Data'!$O$5:$O$504,'5. Soil Data'!$B$5:$B$504,$A11),"")) -> 10.794935 | M11: =IF($A11="","",IFERROR(SUMIFS('5. Soil Data'!$P$5:$P$504,'5. Soil Data'!$B$5:$B$504,$A11),"")) -> 11.600435 | N11: =IF($K11="","",IF($K11>=REPORTING_DEPTH_CM,"Yes","No")) -> Yes | O11: =IF($A11="","",IF(AND($B11<>"",COUNTIF('1. Plot & Site Log'!$A$5:$A$64,$B11)=0),"Plot ID not in Plot & Site Log. ","")&IF($K11="","No soil slices logged for this core. ","")&IF($N11="No","Core stops short of the reporting depth — its depth-limited stock is an underestimate. ","")&IF(AND($H11<>"",$H11>1.05),"Core compacted by "&TEXT(($H11-1)*100,"0")&"%: slice depths in the tube sit shallower than in the ground, so the depth-limited stock is biased. Full-core stock is unaffected. ","")&IF(AND($H11<>"",$H11<0.98),"Core length exceeds hole depth — check the two measurements. ","")) -> Core compacted by 12%: slice depths in the tube sit shallower than in the ground, so the depth-limited stock is biased. Full-core stock is unaffected.
A12: BC-03-C1 | B12: BC-03 | C12: 51.43526 | D12: -84.21274 | E12: Soil core | F12: 30 | G12: 26.4 | H12: =IF(OR($F12="",$G12="",$G12=0),"",$F12/$G12) -> 1.1363636 | I12: 30 | J12: Yes | K12: =IF($A12="","",IF(SUMPRODUCT(MAX(('5. Soil Data'!$B$5:$B$504=$A12)*'5. Soil Data'!$E$5:$E$504))=0,"",SUMPRODUCT(MAX(('5. Soil Data'!$B$5:$B$504=$A12)*'5. Soil Data'!$E$5:$E$504)))) -> 30 | L12: =IF($A12="","",IFERROR(SUMIFS('5. Soil Data'!$O$5:$O$504,'5. Soil Data'!$B$5:$B$504,$A12),"")) -> 10.58331 | M12: =IF($A12="","",IFERROR(SUMIFS('5. Soil Data'!$P$5:$P$504,'5. Soil Data'!$B$5:$B$504,$A12),"")) -> 10.58331 | N12: =IF($K12="","",IF($K12>=REPORTING_DEPTH_CM,"Yes","No")) -> Yes | O12: =IF($A12="","",IF(AND($B12<>"",COUNTIF('1. Plot & Site Log'!$A$5:$A$64,$B12)=0),"Plot ID not in Plot & Site Log. ","")&IF($K12="","No soil slices logged for this core. ","")&IF($N12="No","Core stops short of the reporting depth — its depth-limited stock is an underestimate. ","")&IF(AND($H12<>"",$H12>1.05),"Core compacted by "&TEXT(($H12-1)*100,"0")&"%: slice depths in the tube sit shallower than in the ground, so the depth-limited stock is biased. Full-core stock is unaffected. ","")&IF(AND($H12<>"",$H12<0.98),"Core length exceeds hole depth — check the two measurements. ","")) -> Core compacted by 14%: slice depths in the tube sit shallower than in the ground, so the depth-limited stock is biased. Full-core stock is unaffected.
H13: =IF(OR($F13="",$G13="",$G13=0),"",$F13/$G13) | K13: =IF($A13="","",IF(SUMPRODUCT(MAX(('5. Soil Data'!$B$5:$B$504=$A13)*'5. Soil Data'!$E$5:$E$504))=0,"",SUMPRODUCT(MAX(('5. Soil Data'!$B$5:$B$504=$A13)*'5. Soil Data'!$E$5:$E$504)))) | L13: =IF($A13="","",IFERROR(SUMIFS('5. Soil Data'!$O$5:$O$504,'5. Soil Data'!$B$5:$B$504,$A13),"")) | M13: =IF($A13="","",IFERROR(SUMIFS('5. Soil Data'!$P$5:$P$504,'5. Soil Data'!$B$5:$B$504,$A13),"")) | N13: =IF($K13="","",IF($K13>=REPORTING_DEPTH_CM,"Yes","No")) | O13: =IF($A13="","",IF(AND($B13<>"",COUNTIF('1. Plot & Site Log'!$A$5:$A$64,$B13)=0),"Plot ID not in Plot & Site Log. ","")&IF($K13="","No soil slices logged for this core. ","")&IF($N13="No","Core stops short of the reporting depth — its depth-limited stock is an underestimate. ","")&IF(AND($H13<>"",$H13>1.05),"Core compacted by "&TEXT(($H13-1)*100,"0")&"%: slice depths in the tube sit shallower than in the ground, so the depth-limited stock is biased. Full-core stock is unaffected. ","")&IF(AND($H13<>"",$H13<0.98),"Core length exceeds hole depth — check the two measurements. ",""))
H14: =IF(OR($F14="",$G14="",$G14=0),"",$F14/$G14) | K14: =IF($A14="","",IF(SUMPRODUCT(MAX(('5. Soil Data'!$B$5:$B$504=$A14)*'5. Soil Data'!$E$5:$E$504))=0,"",SUMPRODUCT(MAX(('5. Soil Data'!$B$5:$B$504=$A14)*'5. Soil Data'!$E$5:$E$504)))) | L14: =IF($A14="","",IFERROR(SUMIFS('5. Soil Data'!$O$5:$O$504,'5. Soil Data'!$B$5:$B$504,$A14),"")) | M14: =IF($A14="","",IFERROR(SUMIFS('5. Soil Data'!$P$5:$P$504,'5. Soil Data'!$B$5:$B$504,$A14),"")) | N14: =IF($K14="","",IF($K14>=REPORTING_DEPTH_CM,"Yes","No")) | O14: =IF($A14="","",IF(AND($B14<>"",COUNTIF('1. Plot & Site Log'!$A$5:$A$64,$B14)=0),"Plot ID not in Plot & Site Log. ","")&IF($K14="","No soil slices logged for this core. ","")&IF($N14="No","Core stops short of the reporting depth — its depth-limited stock is an underestimate. ","")&IF(AND($H14<>"",$H14>1.05),"Core compacted by "&TEXT(($H14-1)*100,"0")&"%: slice depths in the tube sit shallower than in the ground, so the depth-limited stock is biased. Full-core stock is unaffected. ","")&IF(AND($H14<>"",$H14<0.98),"Core length exceeds hole depth — check the two measurements. ",""))
H15: =IF(OR($F15="",$G15="",$G15=0),"",$F15/$G15) | K15: =IF($A15="","",IF(SUMPRODUCT(MAX(('5. Soil Data'!$B$5:$B$504=$A15)*'5. Soil Data'!$E$5:$E$504))=0,"",SUMPRODUCT(MAX(('5. Soil Data'!$B$5:$B$504=$A15)*'5. Soil Data'!$E$5:$E$504)))) | L15: =IF($A15="","",IFERROR(SUMIFS('5. Soil Data'!$O$5:$O$504,'5. Soil Data'!$B$5:$B$504,$A15),"")) | M15: =IF($A15="","",IFERROR(SUMIFS('5. Soil Data'!$P$5:$P$504,'5. Soil Data'!$B$5:$B$504,$A15),"")) | N15: =IF($K15="","",IF($K15>=REPORTING_DEPTH_CM,"Yes","No")) | O15: =IF($A15="","",IF(AND($B15<>"",COUNTIF('1. Plot & Site Log'!$A$5:$A$64,$B15)=0),"Plot ID not in Plot & Site Log. ","")&IF($K15="","No soil slices logged for this core. ","")&IF($N15="No","Core stops short of the reporting depth — its depth-limited stock is an underestimate. ","")&IF(AND($H15<>"",$H15>1.05),"Core compacted by "&TEXT(($H15-1)*100,"0")&"%: slice depths in the tube sit shallower than in the ground, so the depth-limited stock is biased. Full-core stock is unaffected. ","")&IF(AND($H15<>"",$H15<0.98),"Core length exceeds hole depth — check the two measurements. ",""))
H16: =IF(OR($F16="",$G16="",$G16=0),"",$F16/$G16) | K16: =IF($A16="","",IF(SUMPRODUCT(MAX(('5. Soil Data'!$B$5:$B$504=$A16)*'5. Soil Data'!$E$5:$E$504))=0,"",SUMPRODUCT(MAX(('5. Soil Data'!$B$5:$B$504=$A16)*'5. Soil Data'!$E$5:$E$504)))) | L16: =IF($A16="","",IFERROR(SUMIFS('5. Soil Data'!$O$5:$O$504,'5. Soil Data'!$B$5:$B$504,$A16),"")) | M16: =IF($A16="","",IFERROR(SUMIFS('5. Soil Data'!$P$5:$P$504,'5. Soil Data'!$B$5:$B$504,$A16),"")) | N16: =IF($K16="","",IF($K16>=REPORTING_DEPTH_CM,"Yes","No")) | O16: =IF($A16="","",IF(AND($B16<>"",COUNTIF('1. Plot & Site Log'!$A$5:$A$64,$B16)=0),"Plot ID not in Plot & Site Log. ","")&IF($K16="","No soil slices logged for this core. ","")&IF($N16="No","Core stops short of the reporting depth — its depth-limited stock is an underestimate. ","")&IF(AND($H16<>"",$H16>1.05),"Core compacted by "&TEXT(($H16-1)*100,"0")&"%: slice depths in the tube sit shallower than in the ground, so the depth-limited stock is biased. Full-core stock is unaffected. ","")&IF(AND($H16<>"",$H16<0.98),"Core length exceeds hole depth — check the two measurements. ",""))
H17: =IF(OR($F17="",$G17="",$G17=0),"",$F17/$G17) | K17: =IF($A17="","",IF(SUMPRODUCT(MAX(('5. Soil Data'!$B$5:$B$504=$A17)*'5. Soil Data'!$E$5:$E$504))=0,"",SUMPRODUCT(MAX(('5. Soil Data'!$B$5:$B$504=$A17)*'5. Soil Data'!$E$5:$E$504)))) | L17: =IF($A17="","",IFERROR(SUMIFS('5. Soil Data'!$O$5:$O$504,'5. Soil Data'!$B$5:$B$504,$A17),"")) | M17: =IF($A17="","",IFERROR(SUMIFS('5. Soil Data'!$P$5:$P$504,'5. Soil Data'!$B$5:$B$504,$A17),"")) | N17: =IF($K17="","",IF($K17>=REPORTING_DEPTH_CM,"Yes","No")) | O17: =IF($A17="","",IF(AND($B17<>"",COUNTIF('1. Plot & Site Log'!$A$5:$A$64,$B17)=0),"Plot ID not in Plot & Site Log. ","")&IF($K17="","No soil slices logged for this core. ","")&IF($N17="No","Core stops short of the reporting depth — its depth-limited stock is an underestimate. ","")&IF(AND($H17<>"",$H17>1.05),"Core compacted by "&TEXT(($H17-1)*100,"0")&"%: slice depths in the tube sit shallower than in the ground, so the depth-limited stock is biased. Full-core stock is unaffected. ","")&IF(AND($H17<>"",$H17<0.98),"Core length exceeds hole depth — check the two measurements. ",""))
H18: =IF(OR($F18="",$G18="",$G18=0),"",$F18/$G18) | K18: =IF($A18="","",IF(SUMPRODUCT(MAX(('5. Soil Data'!$B$5:$B$504=$A18)*'5. Soil Data'!$E$5:$E$504))=0,"",SUMPRODUCT(MAX(('5. Soil Data'!$B$5:$B$504=$A18)*'5. Soil Data'!$E$5:$E$504)))) | L18: =IF($A18="","",IFERROR(SUMIFS('5. Soil Data'!$O$5:$O$504,'5. Soil Data'!$B$5:$B$504,$A18),"")) | M18: =IF($A18="","",IFERROR(SUMIFS('5. Soil Data'!$P$5:$P$504,'5. Soil Data'!$B$5:$B$504,$A18),"")) | N18: =IF($K18="","",IF($K18>=REPORTING_DEPTH_CM,"Yes","No")) | O18: =IF($A18="","",IF(AND($B18<>"",COUNTIF('1. Plot & Site Log'!$A$5:$A$64,$B18)=0),"Plot ID not in Plot & Site Log. ","")&IF($K18="","No soil slices logged for this core. ","")&IF($N18="No","Core stops short of the reporting depth — its depth-limited stock is an underestimate. ","")&IF(AND($H18<>"",$H18>1.05),"Core compacted by "&TEXT(($H18-1)*100,"0")&"%: slice depths in the tube sit shallower than in the ground, so the depth-limited stock is biased. Full-core stock is unaffected. ","")&IF(AND($H18<>"",$H18<0.98),"Core length exceeds hole depth — check the two measurements. ",""))
H19: =IF(OR($F19="",$G19="",$G19=0),"",$F19/$G19) | K19: =IF($A19="","",IF(SUMPRODUCT(MAX(('5. Soil Data'!$B$5:$B$504=$A19)*'5. Soil Data'!$E$5:$E$504))=0,"",SUMPRODUCT(MAX(('5. Soil Data'!$B$5:$B$504=$A19)*'5. Soil Data'!$E$5:$E$504)))) | L19: =IF($A19="","",IFERROR(SUMIFS('5. Soil Data'!$O$5:$O$504,'5. Soil Data'!$B$5:$B$504,$A19),"")) | M19: =IF($A19="","",IFERROR(SUMIFS('5. Soil Data'!$P$5:$P$504,'5. Soil Data'!$B$5:$B$504,$A19),"")) | N19: =IF($K19="","",IF($K19>=REPORTING_DEPTH_CM,"Yes","No")) | O19: =IF($A19="","",IF(AND($B19<>"",COUNTIF('1. Plot & Site Log'!$A$5:$A$64,$B19)=0),"Plot ID not in Plot & Site Log. ","")&IF($K19="","No soil slices logged for this core. ","")&IF($N19="No","Core stops short of the reporting depth — its depth-limited stock is an underestimate. ","")&IF(AND($H19<>"",$H19>1.05),"Core compacted by "&TEXT(($H19-1)*100,"0")&"%: slice depths in the tube sit shallower than in the ground, so the depth-limited stock is biased. Full-core stock is unaffected. ","")&IF(AND($H19<>"",$H19<0.98),"Core length exceeds hole depth — check the two measurements. ",""))
H20: =IF(OR($F20="",$G20="",$G20=0),"",$F20/$G20) | K20: =IF($A20="","",IF(SUMPRODUCT(MAX(('5. Soil Data'!$B$5:$B$504=$A20)*'5. Soil Data'!$E$5:$E$504))=0,"",SUMPRODUCT(MAX(('5. Soil Data'!$B$5:$B$504=$A20)*'5. Soil Data'!$E$5:$E$504)))) | L20: =IF($A20="","",IFERROR(SUMIFS('5. Soil Data'!$O$5:$O$504,'5. Soil Data'!$B$5:$B$504,$A20),"")) | M20: =IF($A20="","",IFERROR(SUMIFS('5. Soil Data'!$P$5:$P$504,'5. Soil Data'!$B$5:$B$504,$A20),"")) | N20: =IF($K20="","",IF($K20>=REPORTING_DEPTH_CM,"Yes","No")) | O20: =IF($A20="","",IF(AND($B20<>"",COUNTIF('1. Plot & Site Log'!$A$5:$A$64,$B20)=0),"Plot ID not in Plot & Site Log. ","")&IF($K20="","No soil slices logged for this core. ","")&IF($N20="No","Core stops short of the reporting depth — its depth-limited stock is an underestimate. ","")&IF(AND($H20<>"",$H20>1.05),"Core compacted by "&TEXT(($H20-1)*100,"0")&"%: slice depths in the tube sit shallower than in the ground, so the depth-limited stock is biased. Full-core stock is unaffected. ","")&IF(AND($H20<>"",$H20<0.98),"Core length exceeds hole depth — check the two measurements. ",""))
H21: =IF(OR($F21="",$G21="",$G21=0),"",$F21/$G21) | K21: =IF($A21="","",IF(SUMPRODUCT(MAX(('5. Soil Data'!$B$5:$B$504=$A21)*'5. Soil Data'!$E$5:$E$504))=0,"",SUMPRODUCT(MAX(('5. Soil Data'!$B$5:$B$504=$A21)*'5. Soil Data'!$E$5:$E$504)))) | L21: =IF($A21="","",IFERROR(SUMIFS('5. Soil Data'!$O$5:$O$504,'5. Soil Data'!$B$5:$B$504,$A21),"")) | M21: =IF($A21="","",IFERROR(SUMIFS('5. Soil Data'!$P$5:$P$504,'5. Soil Data'!$B$5:$B$504,$A21),"")) | N21: =IF($K21="","",IF($K21>=REPORTING_DEPTH_CM,"Yes","No")) | O21: =IF($A21="","",IF(AND($B21<>"",COUNTIF('1. Plot & Site Log'!$A$5:$A$64,$B21)=0),"Plot ID not in Plot & Site Log. ","")&IF($K21="","No soil slices logged for this core. ","")&IF($N21="No","Core stops short of the reporting depth — its depth-limited stock is an underestimate. ","")&IF(AND($H21<>"",$H21>1.05),"Core compacted by "&TEXT(($H21-1)*100,"0")&"%: slice depths in the tube sit shallower than in the ground, so the depth-limited stock is biased. Full-core stock is unaffected. ","")&IF(AND($H21<>"",$H21<0.98),"Core length exceeds hole depth — check the two measurements. ",""))
H22: =IF(OR($F22="",$G22="",$G22=0),"",$F22/$G22) | K22: =IF($A22="","",IF(SUMPRODUCT(MAX(('5. Soil Data'!$B$5:$B$504=$A22)*'5. Soil Data'!$E$5:$E$504))=0,"",SUMPRODUCT(MAX(('5. Soil Data'!$B$5:$B$504=$A22)*'5. Soil Data'!$E$5:$E$504)))) | L22: =IF($A22="","",IFERROR(SUMIFS('5. Soil Data'!$O$5:$O$504,'5. Soil Data'!$B$5:$B$504,$A22),"")) | M22: =IF($A22="","",IFERROR(SUMIFS('5. Soil Data'!$P$5:$P$504,'5. Soil Data'!$B$5:$B$504,$A22),"")) | N22: =IF($K22="","",IF($K22>=REPORTING_DEPTH_CM,"Yes","No")) | O22: =IF($A22="","",IF(AND($B22<>"",COUNTIF('1. Plot & Site Log'!$A$5:$A$64,$B22)=0),"Plot ID not in Plot & Site Log. ","")&IF($K22="","No soil slices logged for this core. ","")&IF($N22="No","Core stops short of the reporting depth — its depth-limited stock is an underestimate. ","")&IF(AND($H22<>"",$H22>1.05),"Core compacted by "&TEXT(($H22-1)*100,"0")&"%: slice depths in the tube sit shallower than in the ground, so the depth-limited stock is biased. Full-core stock is unaffected. ","")&IF(AND($H22<>"",$H22<0.98),"Core length exceeds hole depth — check the two measurements. ",""))
H23: =IF(OR($F23="",$G23="",$G23=0),"",$F23/$G23) | K23: =IF($A23="","",IF(SUMPRODUCT(MAX(('5. Soil Data'!$B$5:$B$504=$A23)*'5. Soil Data'!$E$5:$E$504))=0,"",SUMPRODUCT(MAX(('5. Soil Data'!$B$5:$B$504=$A23)*'5. Soil Data'!$E$5:$E$504)))) | L23: =IF($A23="","",IFERROR(SUMIFS('5. Soil Data'!$O$5:$O$504,'5. Soil Data'!$B$5:$B$504,$A23),"")) | M23: =IF($A23="","",IFERROR(SUMIFS('5. Soil Data'!$P$5:$P$504,'5. Soil Data'!$B$5:$B$504,$A23),"")) | N23: =IF($K23="","",IF($K23>=REPORTING_DEPTH_CM,"Yes","No")) | O23: =IF($A23="","",IF(AND($B23<>"",COUNTIF('1. Plot & Site Log'!$A$5:$A$64,$B23)=0),"Plot ID not in Plot & Site Log. ","")&IF($K23="","No soil slices logged for this core. ","")&IF($N23="No","Core stops short of the reporting depth — its depth-limited stock is an underestimate. ","")&IF(AND($H23<>"",$H23>1.05),"Core compacted by "&TEXT(($H23-1)*100,"0")&"%: slice depths in the tube sit shallower than in the ground, so the depth-limited stock is biased. Full-core stock is unaffected. ","")&IF(AND($H23<>"",$H23<0.98),"Core length exceeds hole depth — check the two measurements. ",""))
H24: =IF(OR($F24="",$G24="",$G24=0),"",$F24/$G24) | K24: =IF($A24="","",IF(SUMPRODUCT(MAX(('5. Soil Data'!$B$5:$B$504=$A24)*'5. Soil Data'!$E$5:$E$504))=0,"",SUMPRODUCT(MAX(('5. Soil Data'!$B$5:$B$504=$A24)*'5. Soil Data'!$E$5:$E$504)))) | L24: =IF($A24="","",IFERROR(SUMIFS('5. Soil Data'!$O$5:$O$504,'5. Soil Data'!$B$5:$B$504,$A24),"")) | M24: =IF($A24="","",IFERROR(SUMIFS('5. Soil Data'!$P$5:$P$504,'5. Soil Data'!$B$5:$B$504,$A24),"")) | N24: =IF($K24="","",IF($K24>=REPORTING_DEPTH_CM,"Yes","No")) | O24: =IF($A24="","",IF(AND($B24<>"",COUNTIF('1. Plot & Site Log'!$A$5:$A$64,$B24)=0),"Plot ID not in Plot & Site Log. ","")&IF($K24="","No soil slices logged for this core. ","")&IF($N24="No","Core stops short of the reporting depth — its depth-limited stock is an underestimate. ","")&IF(AND($H24<>"",$H24>1.05),"Core compacted by "&TEXT(($H24-1)*100,"0")&"%: slice depths in the tube sit shallower than in the ground, so the depth-limited stock is biased. Full-core stock is unaffected. ","")&IF(AND($H24<>"",$H24<0.98),"Core length exceeds hole depth — check the two measurements. ",""))
... H124: =IF(OR($F124="",$G124="",$G124=0),"",$F124/$G124) | K124: =IF($A124="","",IF(SUMPRODUCT(MAX(('5. Soil Data'!$B$5:$B$504=$A124)*'5. Soil Data'!$E$5:$E$504))=0,"",SUMPRODUCT(MAX(('5. Soil Data'!$B$5:$B$504=$A124)*'5. Soil Data'!$E$5:$E$504)))) | L124: =IF($A124="","",IFERROR(SUMIFS('5. Soil Data'!$O$5:$O$504,'5. Soil Data'!$B$5:$B$504,$A124),"")) | M124: =IF($A124="","",IFERROR(SUMIFS('5. Soil Data'!$P$5:$P$504,'5. Soil Data'!$B$5:$B$504,$A124),"")) | N124: =IF($K124="","",IF($K124>=REPORTING_DEPTH_CM,"Yes","No")) | O124: =IF($A124="","",IF(AND($B124<>"",COUNTIF('1. Plot & Site Log'!$A$5:$A$64,$B124)=0),"Plot ID not in Plot & Site Log. ","")&IF($K124="","No soil slices logged for this core. ","")&IF($N124="No","Core stops short of the reporting depth — its depth-limited stock is an underestimate. ","")&IF(AND($H124<>"",$H124>1.05),"Core compacted by "&TEXT(($H124-1)*100,"0")&"%: slice depths in the tube sit shallower than in the ground, so the depth-limited stock is biased. Full-core stock is unaffected. ","")&IF(AND($H124<>"",$H124<0.98),"Core length exceeds hole depth — check the two measurements. ",""))

Sheet 3. Tree Data
A1: TREE DATA
A2: ONE ROW PER TREE over 2 m tall, inside the large plot. Type Plot ID, Tree ID, species and DBH. Height is optional — leave it blank and the DBH-only equation is used; fill it in and the more precise DBH+height equation is used instead. Column G tells you which one ran.
A4: Plot ID | B4: Tree ID | C4: Species | D4: DBH (cm) | E4: Height (m) | F4: Coefficient block | G4: Equation used | H4: Wood (kg) | I4: Bark (kg) | J4: Branches (kg) | K4: Foliage (kg) | L4: Above-ground biomass (kg) | M4: Tree type | N4: Below-ground biomass (kg) | O4: Total biomass (kg) | P4: Carbon (kg C) | Q4: QC flags
A5: MR-01 | B5: 1 | C5: White birch | D5: 18.3 | E5: 18.4 | F5: =IF($C5="","",IFERROR(12+(MATCH($C5,'R1. Tree Coefficients'!$L$12:$L$53,0)-1)*4,"")) -> 160 | G5: =IF($F5="","",IF(AND($E5<>"",$E5>0),"DBH + height","DBH only")) -> DBH + height | H5: =IF(OR($D5="",$F5=""),"",IF($E5>0,INDEX('R1. Tree Coefficients'!$F:$F,$F5+0)*($D5^INDEX('R1. Tree Coefficients'!$G:$G,$F5+0))*($E5^INDEX('R1. Tree Coefficients'!$H:$H,$F5+0)),INDEX('R1. Tree Coefficients'!$D:$D,$F5+0)*($D5^INDEX('R1. Tree Coefficients'!$E:$E,$F5+0)))) -> 102.10628 | I5: =IF(OR($D5="",$F5=""),"",IF($E5>0,INDEX('R1. Tree Coefficients'!$F:$F,$F5+1)*($D5^INDEX('R1. Tree Coefficients'!$G:$G,$F5+1))*($E5^INDEX('R1. Tree Coefficients'!$H:$H,$F5+1)),INDEX('R1. Tree Coefficients'!$D:$D,$F5+1)*($D5^INDEX('R1. Tree Coefficients'!$E:$E,$F5+1)))) -> 17.352862 | J5: =IF(OR($D5="",$F5=""),"",IF($E5>0,INDEX('R1. Tree Coefficients'!$F:$F,$F5+2)*($D5^INDEX('R1. Tree Coefficients'!$G:$G,$F5+2))*($E5^INDEX('R1. Tree Coefficients'!$H:$H,$F5+2)),INDEX('R1. Tree Coefficients'!$D:$D,$F5+2)*($D5^INDEX('R1. Tree Coefficients'!$E:$E,$F5+2)))) -> 17.111175 | K5: =IF(OR($D5="",$F5=""),"",IF($E5>0,INDEX('R1. Tree Coefficients'!$F:$F,$F5+3)*($D5^INDEX('R1. Tree Coefficients'!$G:$G,$F5+3))*($E5^INDEX('R1. Tree Coefficients'!$H:$H,$F5+3)),INDEX('R1. Tree Coefficients'!$D:$D,$F5+3)*($D5^INDEX('R1. Tree Coefficients'!$E:$E,$F5+3)))) -> 4.4850411 | L5: =IF($F5="","",IFERROR(SUM($H5:$K5),"")) -> 141.05536 | M5: =IF($F5="","",INDEX('R1. Tree Coefficients'!$J:$J,$F5)) -> Deciduous | N5: =IF($L5="","",IF($M5="Deciduous",BGB_RS_DECIDUOUS_a*($L5^BGB_RS_DECIDUOUS_b),IF($M5="Conifers",BGB_RS_CONIFER*$L5,AVERAGE(BGB_RS_DECIDUOUS_a*($L5^BGB_RS_DECIDUOUS_b),BGB_RS_CONIFER*$L5)))) -> 33.069742 | O5: =IF($L5="","",$L5+$N5) -> 174.1251 | P5: =IF($O5="","",$O5*CARBON_FRACTION_BIOMASS) -> 87.062549 | Q5: =IF(AND($A5="",$C5=""),"",IF(AND($A5<>"",COUNTIF('1. Plot & Site Log'!$A$5:$A$64,$A5)=0),"Plot ID not in Plot & Site Log — this tree will not reach the summary. ","")&IF($A5="","No Plot ID. ","")&IF(AND($C5<>"",$F5=""),"Species not in the coefficient list — check the spelling against R1. ","")&IF($D5="","No DBH — nothing can be calculated. ","")&IF(AND($D5<>"",$D5>QC_DBH_MAX_CM),"DBH above "&QC_DBH_MAX_CM&" cm — check for a transcription error. ","")&IF($M5="All","Generic species: no published root:shoot applies, so below-ground biomass is the mean of the deciduous and conifer relationships. Choose a species, or Deciduous/Conifers, if you can. ","")&IF(AND($O5<>"",$O5>0,OR($N5/$O5<BGB_FRACTION_MIN,$N5/$O5>BGB_FRACTION_MAX)),"Below-ground share is "&TEXT($N5/$O5,"0%")&", outside the 18–30% the Trees guide describes. ",""))
A6: MR-01 | B6: 2 | C6: Black spruce | D6: 19.2 | F6: =IF($C6="","",IFERROR(12+(MATCH($C6,'R1. Tree Coefficients'!$L$12:$L$53,0)-1)*4,"")) -> 48 | G6: =IF($F6="","",IF(AND($E6<>"",$E6>0),"DBH + height","DBH only")) -> DBH only | H6: =IF(OR($D6="",$F6=""),"",IF($E6>0,INDEX('R1. Tree Coefficients'!$F:$F,$F6+0)*($D6^INDEX('R1. Tree Coefficients'!$G:$G,$F6+0))*($E6^INDEX('R1. Tree Coefficients'!$H:$H,$F6+0)),INDEX('R1. Tree Coefficients'!$D:$D,$F6+0)*($D6^INDEX('R1. Tree Coefficients'!$E:$E,$F6+0)))) -> 80.387454 | I6: =IF(OR($D6="",$F6=""),"",IF($E6>0,INDEX('R1. Tree Coefficients'!$F:$F,$F6+1)*($D6^INDEX('R1. Tree Coefficients'!$G:$G,$F6+1))*($E6^INDEX('R1. Tree Coefficients'!$H:$H,$F6+1)),INDEX('R1. Tree Coefficients'!$D:$D,$F6+1)*($D6^INDEX('R1. Tree Coefficients'!$E:$E,$F6+1)))) -> 11.400385 | J6: =IF(OR($D6="",$F6=""),"",IF($E6>0,INDEX('R1. Tree Coefficients'!$F:$F,$F6+2)*($D6^INDEX('R1. Tree Coefficients'!$G:$G,$F6+2))*($E6^INDEX('R1. Tree Coefficients'!$H:$H,$F6+2)),INDEX('R1. Tree Coefficients'!$D:$D,$F6+2)*($D6^INDEX('R1. Tree Coefficients'!$E:$E,$F6+2)))) -> 13.3928 | K6: =IF(OR($D6="",$F6=""),"",IF($E6>0,INDEX('R1. Tree Coefficients'!$F:$F,$F6+3)*($D6^INDEX('R1. Tree Coefficients'!$G:$G,$F6+3))*($E6^INDEX('R1. Tree Coefficients'!$H:$H,$F6+3)),INDEX('R1. Tree Coefficients'!$D:$D,$F6+3)*($D6^INDEX('R1. Tree Coefficients'!$E:$E,$F6+3)))) -> 10.903476 | L6: =IF($F6="","",IFERROR(SUM($H6:$K6),"")) -> 116.08411 | M6: =IF($F6="","",INDEX('R1. Tree Coefficients'!$J:$J,$F6)) -> Conifers | N6: =IF($L6="","",IF($M6="Deciduous",BGB_RS_DECIDUOUS_a*($L6^BGB_RS_DECIDUOUS_b),IF($M6="Conifers",BGB_RS_CONIFER*$L6,AVERAGE(BGB_RS_DECIDUOUS_a*($L6^BGB_RS_DECIDUOUS_b),BGB_RS_CONIFER*$L6)))) -> 25.770673 | O6: =IF($L6="","",$L6+$N6) -> 141.85479 | P6: =IF($O6="","",$O6*CARBON_FRACTION_BIOMASS) -> 70.927394 | Q6: =IF(AND($A6="",$C6=""),"",IF(AND($A6<>"",COUNTIF('1. Plot & Site Log'!$A$5:$A$64,$A6)=0),"Plot ID not in Plot & Site Log — this tree will not reach the summary. ","")&IF($A6="","No Plot ID. ","")&IF(AND($C6<>"",$F6=""),"Species not in the coefficient list — check the spelling against R1. ","")&IF($D6="","No DBH — nothing can be calculated. ","")&IF(AND($D6<>"",$D6>QC_DBH_MAX_CM),"DBH above "&QC_DBH_MAX_CM&" cm — check for a transcription error. ","")&IF($M6="All","Generic species: no published root:shoot applies, so below-ground biomass is the mean of the deciduous and conifer relationships. Choose a species, or Deciduous/Conifers, if you can. ","")&IF(AND($O6<>"",$O6>0,OR($N6/$O6<BGB_FRACTION_MIN,$N6/$O6>BGB_FRACTION_MAX)),"Below-ground share is "&TEXT($N6/$O6,"0%")&", outside the 18–30% the Trees guide describes. ",""))
A7: MR-01 | B7: 3 | C7: Balsam fir | D7: 23.3 | F7: =IF($C7="","",IFERROR(12+(MATCH($C7,'R1. Tree Coefficients'!$L$12:$L$53,0)-1)*4,"")) -> 24 | G7: =IF($F7="","",IF(AND($E7<>"",$E7>0),"DBH + height","DBH only")) -> DBH only | H7: =IF(OR($D7="",$F7=""),"",IF($E7>0,INDEX('R1. Tree Coefficients'!$F:$F,$F7+0)*($D7^INDEX('R1. Tree Coefficients'!$G:$G,$F7+0))*($E7^INDEX('R1. Tree Coefficients'!$H:$H,$F7+0)),INDEX('R1. Tree Coefficients'!$D:$D,$F7+0)*($D7^INDEX('R1. Tree Coefficients'!$E:$E,$F7+0)))) -> 103.10923 | I7: =IF(OR($D7="",$F7=""),"",IF($E7>0,INDEX('R1. Tree Coefficients'!$F:$F,$F7+1)*($D7^INDEX('R1. Tree Coefficients'!$G:$G,$F7+1))*($E7^INDEX('R1. Tree Coefficients'!$H:$H,$F7+1)),INDEX('R1. Tree Coefficients'!$D:$D,$F7+1)*($D7^INDEX('R1. Tree Coefficients'!$E:$E,$F7+1)))) -> 18.698057 | J7: =IF(OR($D7="",$F7=""),"",IF($E7>0,INDEX('R1. Tree Coefficients'!$F:$F,$F7+2)*($D7^INDEX('R1. Tree Coefficients'!$G:$G,$F7+2))*($E7^INDEX('R1. Tree Coefficients'!$H:$H,$F7+2)),INDEX('R1. Tree Coefficients'!$D:$D,$F7+2)*($D7^INDEX('R1. Tree Coefficients'!$E:$E,$F7+2)))) -> 20.845028 | K7: =IF(OR($D7="",$F7=""),"",IF($E7>0,INDEX('R1. Tree Coefficients'!$F:$F,$F7+3)*($D7^INDEX('R1. Tree Coefficients'!$G:$G,$F7+3))*($E7^INDEX('R1. Tree Coefficients'!$H:$H,$F7+3)),INDEX('R1. Tree Coefficients'!$D:$D,$F7+3)*($D7^INDEX('R1. Tree Coefficients'!$E:$E,$F7+3)))) -> 16.109423 | L7: =IF($F7="","",IFERROR(SUM($H7:$K7),"")) -> 158.76174 | M7: =IF($F7="","",INDEX('R1. Tree Coefficients'!$J:$J,$F7)) -> Conifers | N7: =IF($L7="","",IF($M7="Deciduous",BGB_RS_DECIDUOUS_a*($L7^BGB_RS_DECIDUOUS_b),IF($M7="Conifers",BGB_RS_CONIFER*$L7,AVERAGE(BGB_RS_DECIDUOUS_a*($L7^BGB_RS_DECIDUOUS_b),BGB_RS_CONIFER*$L7)))) -> 35.245106 | O7: =IF($L7="","",$L7+$N7) -> 194.00684 | P7: =IF($O7="","",$O7*CARBON_FRACTION_BIOMASS) -> 97.003421 | Q7: =IF(AND($A7="",$C7=""),"",IF(AND($A7<>"",COUNTIF('1. Plot & Site Log'!$A$5:$A$64,$A7)=0),"Plot ID not in Plot & Site Log — this tree will not reach the summary. ","")&IF($A7="","No Plot ID. ","")&IF(AND($C7<>"",$F7=""),"Species not in the coefficient list — check the spelling against R1. ","")&IF($D7="","No DBH — nothing can be calculated. ","")&IF(AND($D7<>"",$D7>QC_DBH_MAX_CM),"DBH above "&QC_DBH_MAX_CM&" cm — check for a transcription error. ","")&IF($M7="All","Generic species: no published root:shoot applies, so below-ground biomass is the mean of the deciduous and conifer relationships. Choose a species, or Deciduous/Conifers, if you can. ","")&IF(AND($O7<>"",$O7>0,OR($N7/$O7<BGB_FRACTION_MIN,$N7/$O7>BGB_FRACTION_MAX)),"Below-ground share is "&TEXT($N7/$O7,"0%")&", outside the 18–30% the Trees guide describes. ",""))
A8: MR-01 | B8: 4 | C8: White birch | D8: 23.2 | E8: 19.7 | F8: =IF($C8="","",IFERROR(12+(MATCH($C8,'R1. Tree Coefficients'!$L$12:$L$53,0)-1)*4,"")) -> 160 | G8: =IF($F8="","",IF(AND($E8<>"",$E8>0),"DBH + height","DBH only")) -> DBH + height | H8: =IF(OR($D8="",$F8=""),"",IF($E8>0,INDEX('R1. Tree Coefficients'!$F:$F,$F8+0)*($D8^INDEX('R1. Tree Coefficients'!$G:$G,$F8+0))*($E8^INDEX('R1. Tree Coefficients'!$H:$H,$F8+0)),INDEX('R1. Tree Coefficients'!$D:$D,$F8+0)*($D8^INDEX('R1. Tree Coefficients'!$E:$E,$F8+0)))) -> 175.1866 | I8: =IF(OR($D8="",$F8=""),"",IF($E8>0,INDEX('R1. Tree Coefficients'!$F:$F,$F8+1)*($D8^INDEX('R1. Tree Coefficients'!$G:$G,$F8+1))*($E8^INDEX('R1. Tree Coefficients'!$H:$H,$F8+1)),INDEX('R1. Tree Coefficients'!$D:$D,$F8+1)*($D8^INDEX('R1. Tree Coefficients'!$E:$E,$F8+1)))) -> 29.100111 | J8: =IF(OR($D8="",$F8=""),"",IF($E8>0,INDEX('R1. Tree Coefficients'!$F:$F,$F8+2)*($D8^INDEX('R1. Tree Coefficients'!$G:$G,$F8+2))*($E8^INDEX('R1. Tree Coefficients'!$H:$H,$F8+2)),INDEX('R1. Tree Coefficients'!$D:$D,$F8+2)*($D8^INDEX('R1. Tree Coefficients'!$E:$E,$F8+2)))) -> 33.970495 | K8: =IF(OR($D8="",$F8=""),"",IF($E8>0,INDEX('R1. Tree Coefficients'!$F:$F,$F8+3)*($D8^INDEX('R1. Tree Coefficients'!$G:$G,$F8+3))*($E8^INDEX('R1. Tree Coefficients'!$H:$H,$F8+3)),INDEX('R1. Tree Coefficients'!$D:$D,$F8+3)*($D8^INDEX('R1. Tree Coefficients'!$E:$E,$F8+3)))) -> 7.1797124 | L8: =IF($F8="","",IFERROR(SUM($H8:$K8),"")) -> 245.43692 | M8: =IF($F8="","",INDEX('R1. Tree Coefficients'!$J:$J,$F8)) -> Deciduous | N8: =IF($L8="","",IF($M8="Deciduous",BGB_RS_DECIDUOUS_a*($L8^BGB_RS_DECIDUOUS_b),IF($M8="Conifers",BGB_RS_CONIFER*$L8,AVERAGE(BGB_RS_DECIDUOUS_a*($L8^BGB_RS_DECIDUOUS_b),BGB_RS_CONIFER*$L8)))) -> 46.491039 | O8: =IF($L8="","",$L8+$N8) -> 291.92796 | P8: =IF($O8="","",$O8*CARBON_FRACTION_BIOMASS) -> 145.96398 | Q8: =IF(AND($A8="",$C8=""),"",IF(AND($A8<>"",COUNTIF('1. Plot & Site Log'!$A$5:$A$64,$A8)=0),"Plot ID not in Plot & Site Log — this tree will not reach the summary. ","")&IF($A8="","No Plot ID. ","")&IF(AND($C8<>"",$F8=""),"Species not in the coefficient list — check the spelling against R1. ","")&IF($D8="","No DBH — nothing can be calculated. ","")&IF(AND($D8<>"",$D8>QC_DBH_MAX_CM),"DBH above "&QC_DBH_MAX_CM&" cm — check for a transcription error. ","")&IF($M8="All","Generic species: no published root:shoot applies, so below-ground biomass is the mean of the deciduous and conifer relationships. Choose a species, or Deciduous/Conifers, if you can. ","")&IF(AND($O8<>"",$O8>0,OR($N8/$O8<BGB_FRACTION_MIN,$N8/$O8>BGB_FRACTION_MAX)),"Below-ground share is "&TEXT($N8/$O8,"0%")&", outside the 18–30% the Trees guide describes. ",""))
A9: MR-01 | B9: 5 | C9: Black spruce | D9: 18.6 | F9: =IF($C9="","",IFERROR(12+(MATCH($C9,'R1. Tree Coefficients'!$L$12:$L$53,0)-1)*4,"")) -> 48 | G9: =IF($F9="","",IF(AND($E9<>"",$E9>0),"DBH + height","DBH only")) -> DBH only | H9: =IF(OR($D9="",$F9=""),"",IF($E9>0,INDEX('R1. Tree Coefficients'!$F:$F,$F9+0)*($D9^INDEX('R1. Tree Coefficients'!$G:$G,$F9+0))*($E9^INDEX('R1. Tree Coefficients'!$H:$H,$F9+0)),INDEX('R1. Tree Coefficients'!$D:$D,$F9+0)*($D9^INDEX('R1. Tree Coefficients'!$E:$E,$F9+0)))) -> 74.247715 | I9: =IF(OR($D9="",$F9=""),"",IF($E9>0,INDEX('R1. Tree Coefficients'!$F:$F,$F9+1)*($D9^INDEX('R1. Tree Coefficients'!$G:$G,$F9+1))*($E9^INDEX('R1. Tree Coefficients'!$H:$H,$F9+1)),INDEX('R1. Tree Coefficients'!$D:$D,$F9+1)*($D9^INDEX('R1. Tree Coefficients'!$E:$E,$F9+1)))) -> 10.614612 | J9: =IF(OR($D9="",$F9=""),"",IF($E9>0,INDEX('R1. Tree Coefficients'!$F:$F,$F9+2)*($D9^INDEX('R1. Tree Coefficients'!$G:$G,$F9+2))*($E9^INDEX('R1. Tree Coefficients'!$H:$H,$F9+2)),INDEX('R1. Tree Coefficients'!$D:$D,$F9+2)*($D9^INDEX('R1. Tree Coefficients'!$E:$E,$F9+2)))) -> 12.538896 | K9: =IF(OR($D9="",$F9=""),"",IF($E9>0,INDEX('R1. Tree Coefficients'!$F:$F,$F9+3)*($D9^INDEX('R1. Tree Coefficients'!$G:$G,$F9+3))*($E9^INDEX('R1. Tree Coefficients'!$H:$H,$F9+3)),INDEX('R1. Tree Coefficients'!$D:$D,$F9+3)*($D9^INDEX('R1. Tree Coefficients'!$E:$E,$F9+3)))) -> 10.422101 | L9: =IF($F9="","",IFERROR(SUM($H9:$K9),"")) -> 107.82332 | M9: =IF($F9="","",INDEX('R1. Tree Coefficients'!$J:$J,$F9)) -> Conifers | N9: =IF($L9="","",IF($M9="Deciduous",BGB_RS_DECIDUOUS_a*($L9^BGB_RS_DECIDUOUS_b),IF($M9="Conifers",BGB_RS_CONIFER*$L9,AVERAGE(BGB_RS_DECIDUOUS_a*($L9^BGB_RS_DECIDUOUS_b),BGB_RS_CONIFER*$L9)))) -> 23.936778 | O9: =IF($L9="","",$L9+$N9) -> 131.7601 | P9: =IF($O9="","",$O9*CARBON_FRACTION_BIOMASS) -> 65.880051 | Q9: =IF(AND($A9="",$C9=""),"",IF(AND($A9<>"",COUNTIF('1. Plot & Site Log'!$A$5:$A$64,$A9)=0),"Plot ID not in Plot & Site Log — this tree will not reach the summary. ","")&IF($A9="","No Plot ID. ","")&IF(AND($C9<>"",$F9=""),"Species not in the coefficient list — check the spelling against R1. ","")&IF($D9="","No DBH — nothing can be calculated. ","")&IF(AND($D9<>"",$D9>QC_DBH_MAX_CM),"DBH above "&QC_DBH_MAX_CM&" cm — check for a transcription error. ","")&IF($M9="All","Generic species: no published root:shoot applies, so below-ground biomass is the mean of the deciduous and conifer relationships. Choose a species, or Deciduous/Conifers, if you can. ","")&IF(AND($O9<>"",$O9>0,OR($N9/$O9<BGB_FRACTION_MIN,$N9/$O9>BGB_FRACTION_MAX)),"Below-ground share is "&TEXT($N9/$O9,"0%")&", outside the 18–30% the Trees guide describes. ",""))
A10: MR-01 | B10: 6 | C10: White spruce | D10: 22 | F10: =IF($C10="","",IFERROR(12+(MATCH($C10,'R1. Tree Coefficients'!$L$12:$L$53,0)-1)*4,"")) -> 172 | G10: =IF($F10="","",IF(AND($E10<>"",$E10>0),"DBH + height","DBH only")) -> DBH only | H10: =IF(OR($D10="",$F10=""),"",IF($E10>0,INDEX('R1. Tree Coefficients'!$F:$F,$F10+0)*($D10^INDEX('R1. Tree Coefficients'!$G:$G,$F10+0))*($E10^INDEX('R1. Tree Coefficients'!$H:$H,$F10+0)),INDEX('R1. Tree Coefficients'!$D:$D,$F10+0)*($D10^INDEX('R1. Tree Coefficients'!$E:$E,$F10+0)))) -> 102.65039 | I10: =IF(OR($D10="",$F10=""),"",IF($E10>0,INDEX('R1. Tree Coefficients'!$F:$F,$F10+1)*($D10^INDEX('R1. Tree Coefficients'!$G:$G,$F10+1))*($E10^INDEX('R1. Tree Coefficients'!$H:$H,$F10+1)),INDEX('R1. Tree Coefficients'!$D:$D,$F10+1)*($D10^INDEX('R1. Tree Coefficients'!$E:$E,$F10+1)))) -> 14.194785 | J10: =IF(OR($D10="",$F10=""),"",IF($E10>0,INDEX('R1. Tree Coefficients'!$F:$F,$F10+2)*($D10^INDEX('R1. Tree Coefficients'!$G:$G,$F10+2))*($E10^INDEX('R1. Tree Coefficients'!$H:$H,$F10+2)),INDEX('R1. Tree Coefficients'!$D:$D,$F10+2)*($D10^INDEX('R1. Tree Coefficients'!$E:$E,$F10+2)))) -> 19.466814 | K10: =IF(OR($D10="",$F10=""),"",IF($E10>0,INDEX('R1. Tree Coefficients'!$F:$F,$F10+3)*($D10^INDEX('R1. Tree Coefficients'!$G:$G,$F10+3))*($E10^INDEX('R1. Tree Coefficients'!$H:$H,$F10+3)),INDEX('R1. Tree Coefficients'!$D:$D,$F10+3)*($D10^INDEX('R1. Tree Coefficients'!$E:$E,$F10+3)))) -> 15.691251 | L10: =IF($F10="","",IFERROR(SUM($H10:$K10),"")) -> 152.00324 | M10: =IF($F10="","",INDEX('R1. Tree Coefficients'!$J:$J,$F10)) -> Conifers | N10: =IF($L10="","",IF($M10="Deciduous",BGB_RS_DECIDUOUS_a*($L10^BGB_RS_DECIDUOUS_b),IF($M10="Conifers",BGB_RS_CONIFER*$L10,AVERAGE(BGB_RS_DECIDUOUS_a*($L10^BGB_RS_DECIDUOUS_b),BGB_RS_CONIFER*$L10)))) -> 33.744719 | O10: =IF($L10="","",$L10+$N10) -> 185.74796 | P10: =IF($O10="","",$O10*CARBON_FRACTION_BIOMASS) -> 92.873978 | Q10: =IF(AND($A10="",$C10=""),"",IF(AND($A10<>"",COUNTIF('1. Plot & Site Log'!$A$5:$A$64,$A10)=0),"Plot ID not in Plot & Site Log — this tree will not reach the summary. ","")&IF($A10="","No Plot ID. ","")&IF(AND($C10<>"",$F10=""),"Species not in the coefficient list — check the spelling against R1. ","")&IF($D10="","No DBH — nothing can be calculated. ","")&IF(AND($D10<>"",$D10>QC_DBH_MAX_CM),"DBH above "&QC_DBH_MAX_CM&" cm — check for a transcription error. ","")&IF($M10="All","Generic species: no published root:shoot applies, so below-ground biomass is the mean of the deciduous and conifer relationships. Choose a species, or Deciduous/Conifers, if you can. ","")&IF(AND($O10<>"",$O10>0,OR($N10/$O10<BGB_FRACTION_MIN,$N10/$O10>BGB_FRACTION_MAX)),"Below-ground share is "&TEXT($N10/$O10,"0%")&", outside the 18–30% the Trees guide describes. ",""))
A11: MR-01 | B11: 7 | C11: Black spruce | D11: 48.3 | E11: 23 | F11: =IF($C11="","",IFERROR(12+(MATCH($C11,'R1. Tree Coefficients'!$L$12:$L$53,0)-1)*4,"")) -> 48 | G11: =IF($F11="","",IF(AND($E11<>"",$E11>0),"DBH + height","DBH only")) -> DBH + height | H11: =IF(OR($D11="",$F11=""),"",IF($E11>0,INDEX('R1. Tree Coefficients'!$F:$F,$F11+0)*($D11^INDEX('R1. Tree Coefficients'!$G:$G,$F11+0))*($E11^INDEX('R1. Tree Coefficients'!$H:$H,$F11+0)),INDEX('R1. Tree Coefficients'!$D:$D,$F11+0)*($D11^INDEX('R1. Tree Coefficients'!$E:$E,$F11+0)))) -> 620.18292 | I11: =IF(OR($D11="",$F11=""),"",IF($E11>0,INDEX('R1. Tree Coefficients'!$F:$F,$F11+1)*($D11^INDEX('R1. Tree Coefficients'!$G:$G,$F11+1))*($E11^INDEX('R1. Tree Coefficients'!$H:$H,$F11+1)),INDEX('R1. Tree Coefficients'!$D:$D,$F11+1)*($D11^INDEX('R1. Tree Coefficients'!$E:$E,$F11+1)))) -> 75.913184 | J11: =IF(OR($D11="",$F11=""),"",IF($E11>0,INDEX('R1. Tree Coefficients'!$F:$F,$F11+2)*($D11^INDEX('R1. Tree Coefficients'!$G:$G,$F11+2))*($E11^INDEX('R1. Tree Coefficients'!$H:$H,$F11+2)),INDEX('R1. Tree Coefficients'!$D:$D,$F11+2)*($D11^INDEX('R1. Tree Coefficients'!$E:$E,$F11+2)))) -> 131.8507 | K11: =IF(OR($D11="",$F11=""),"",IF($E11>0,INDEX('R1. Tree Coefficients'!$F:$F,$F11+3)*($D11^INDEX('R1. Tree Coefficients'!$G:$G,$F11+3))*($E11^INDEX('R1. Tree Coefficients'!$H:$H,$F11+3)),INDEX('R1. Tree Coefficients'!$D:$D,$F11+3)*($D11^INDEX('R1. Tree Coefficients'!$E:$E,$F11+3)))) -> 60.623496 | L11: =IF($F11="","",IFERROR(SUM($H11:$K11),"")) -> 888.5703 | M11: =IF($F11="","",INDEX('R1. Tree Coefficients'!$J:$J,$F11)) -> Conifers | N11: =IF($L11="","",IF($M11="Deciduous",BGB_RS_DECIDUOUS_a*($L11^BGB_RS_DECIDUOUS_b),IF($M11="Conifers",BGB_RS_CONIFER*$L11,AVERAGE(BGB_RS_DECIDUOUS_a*($L11^BGB_RS_DECIDUOUS_b),BGB_RS_CONIFER*$L11)))) -> 197.26261 | O11: =IF($L11="","",$L11+$N11) -> 1085.8329 | P11: =IF($O11="","",$O11*CARBON_FRACTION_BIOMASS) -> 542.91645 | Q11: =IF(AND($A11="",$C11=""),"",IF(AND($A11<>"",COUNTIF('1. Plot & Site Log'!$A$5:$A$64,$A11)=0),"Plot ID not in Plot & Site Log — this tree will not reach the summary. ","")&IF($A11="","No Plot ID. ","")&IF(AND($C11<>"",$F11=""),"Species not in the coefficient list — check the spelling against R1. ","")&IF($D11="","No DBH — nothing can be calculated. ","")&IF(AND($D11<>"",$D11>QC_DBH_MAX_CM),"DBH above "&QC_DBH_MAX_CM&" cm — check for a transcription error. ","")&IF($M11="All","Generic species: no published root:shoot applies, so below-ground biomass is the mean of the deciduous and conifer relationships. Choose a species, or Deciduous/Conifers, if you can. ","")&IF(AND($O11<>"",$O11>0,OR($N11/$O11<BGB_FRACTION_MIN,$N11/$O11>BGB_FRACTION_MAX)),"Below-ground share is "&TEXT($N11/$O11,"0%")&", outside the 18–30% the Trees guide describes. ",""))
A12: MR-01 | B12: 8 | C12: Trembling aspen | D12: 20.3 | F12: =IF($C12="","",IFERROR(12+(MATCH($C12,'R1. Tree Coefficients'!$L$12:$L$53,0)-1)*4,"")) -> 144 | G12: =IF($F12="","",IF(AND($E12<>"",$E12>0),"DBH + height","DBH only")) -> DBH only | H12: =IF(OR($D12="",$F12=""),"",IF($E12>0,INDEX('R1. Tree Coefficients'!$F:$F,$F12+0)*($D12^INDEX('R1. Tree Coefficients'!$G:$G,$F12+0))*($E12^INDEX('R1. Tree Coefficients'!$H:$H,$F12+0)),INDEX('R1. Tree Coefficients'!$D:$D,$F12+0)*($D12^INDEX('R1. Tree Coefficients'!$E:$E,$F12+0)))) -> 104.23055 | I12: =IF(OR($D12="",$F12=""),"",IF($E12>0,INDEX('R1. Tree Coefficients'!$F:$F,$F12+1)*($D12^INDEX('R1. Tree Coefficients'!$G:$G,$F12+1))*($E12^INDEX('R1. Tree Coefficients'!$H:$H,$F12+1)),INDEX('R1. Tree Coefficients'!$D:$D,$F12+1)*($D12^INDEX('R1. Tree Coefficients'!$E:$E,$F12+1)))) -> 22.670955 | J12: =IF(OR($D12="",$F12=""),"",IF($E12>0,INDEX('R1. Tree Coefficients'!$F:$F,$F12+2)*($D12^INDEX('R1. Tree Coefficients'!$G:$G,$F12+2))*($E12^INDEX('R1. Tree Coefficients'!$H:$H,$F12+2)),INDEX('R1. Tree Coefficients'!$D:$D,$F12+2)*($D12^INDEX('R1. Tree Coefficients'!$E:$E,$F12+2)))) -> 15.875527 | K12: =IF(OR($D12="",$F12=""),"",IF($E12>0,INDEX('R1. Tree Coefficients'!$F:$F,$F12+3)*($D12^INDEX('R1. Tree Coefficients'!$G:$G,$F12+3))*($E12^INDEX('R1. Tree Coefficients'!$H:$H,$F12+3)),INDEX('R1. Tree Coefficients'!$D:$D,$F12+3)*($D12^INDEX('R1. Tree Coefficients'!$E:$E,$F12+3)))) -> 3.5386146 | L12: =IF($F12="","",IFERROR(SUM($H12:$K12),"")) -> 146.31565 | M12: =IF($F12="","",INDEX('R1. Tree Coefficients'!$J:$J,$F12)) -> Deciduous | N12: =IF($L12="","",IF($M12="Deciduous",BGB_RS_DECIDUOUS_a*($L12^BGB_RS_DECIDUOUS_b),IF($M12="Conifers",BGB_RS_CONIFER*$L12,AVERAGE(BGB_RS_DECIDUOUS_a*($L12^BGB_RS_DECIDUOUS_b),BGB_RS_CONIFER*$L12)))) -> 33.822837 | O12: =IF($L12="","",$L12+$N12) -> 180.13848 | P12: =IF($O12="","",$O12*CARBON_FRACTION_BIOMASS) -> 90.069242 | Q12: =IF(AND($A12="",$C12=""),"",IF(AND($A12<>"",COUNTIF('1. Plot & Site Log'!$A$5:$A$64,$A12)=0),"Plot ID not in Plot & Site Log — this tree will not reach the summary. ","")&IF($A12="","No Plot ID. ","")&IF(AND($C12<>"",$F12=""),"Species not in the coefficient list — check the spelling against R1. ","")&IF($D12="","No DBH — nothing can be calculated. ","")&IF(AND($D12<>"",$D12>QC_DBH_MAX_CM),"DBH above "&QC_DBH_MAX_CM&" cm — check for a transcription error. ","")&IF($M12="All","Generic species: no published root:shoot applies, so below-ground biomass is the mean of the deciduous and conifer relationships. Choose a species, or Deciduous/Conifers, if you can. ","")&IF(AND($O12<>"",$O12>0,OR($N12/$O12<BGB_FRACTION_MIN,$N12/$O12>BGB_FRACTION_MAX)),"Below-ground share is "&TEXT($N12/$O12,"0%")&", outside the 18–30% the Trees guide describes. ",""))
A13: MR-01 | B13: 9 | C13: White spruce | D13: 12.3 | F13: =IF($C13="","",IFERROR(12+(MATCH($C13,'R1. Tree Coefficients'!$L$12:$L$53,0)-1)*4,"")) -> 172 | G13: =IF($F13="","",IF(AND($E13<>"",$E13>0),"DBH + height","DBH only")) -> DBH only | H13: =IF(OR($D13="",$F13=""),"",IF($E13>0,INDEX('R1. Tree Coefficients'!$F:$F,$F13+0)*($D13^INDEX('R1. Tree Coefficients'!$G:$G,$F13+0))*($E13^INDEX('R1. Tree Coefficients'!$H:$H,$F13+0)),INDEX('R1. Tree Coefficients'!$D:$D,$F13+0)*($D13^INDEX('R1. Tree Coefficients'!$E:$E,$F13+0)))) -> 22.663133 | I13: =IF(OR($D13="",$F13=""),"",IF($E13>0,INDEX('R1. Tree Coefficients'!$F:$F,$F13+1)*($D13^INDEX('R1. Tree Coefficients'!$G:$G,$F13+1))*($E13^INDEX('R1. Tree Coefficients'!$H:$H,$F13+1)),INDEX('R1. Tree Coefficients'!$D:$D,$F13+1)*($D13^INDEX('R1. Tree Coefficients'!$E:$E,$F13+1)))) -> 3.7144889 | J13: =IF(OR($D13="",$F13=""),"",IF($E13>0,INDEX('R1. Tree Coefficients'!$F:$F,$F13+2)*($D13^INDEX('R1. Tree Coefficients'!$G:$G,$F13+2))*($E13^INDEX('R1. Tree Coefficients'!$H:$H,$F13+2)),INDEX('R1. Tree Coefficients'!$D:$D,$F13+2)*($D13^INDEX('R1. Tree Coefficients'!$E:$E,$F13+2)))) -> 5.7656911 | K13: =IF(OR($D13="",$F13=""),"",IF($E13>0,INDEX('R1. Tree Coefficients'!$F:$F,$F13+3)*($D13^INDEX('R1. Tree Coefficients'!$G:$G,$F13+3))*($E13^INDEX('R1. Tree Coefficients'!$H:$H,$F13+3)),INDEX('R1. Tree Coefficients'!$D:$D,$F13+3)*($D13^INDEX('R1. Tree Coefficients'!$E:$E,$F13+3)))) -> 6.5550829 | L13: =IF($F13="","",IFERROR(SUM($H13:$K13),"")) -> 38.698396 | M13: =IF($F13="","",INDEX('R1. Tree Coefficients'!$J:$J,$F13)) -> Conifers | N13: =IF($L13="","",IF($M13="Deciduous",BGB_RS_DECIDUOUS_a*($L13^BGB_RS_DECIDUOUS_b),IF($M13="Conifers",BGB_RS_CONIFER*$L13,AVERAGE(BGB_RS_DECIDUOUS_a*($L13^BGB_RS_DECIDUOUS_b),BGB_RS_CONIFER*$L13)))) -> 8.5910439 | O13: =IF($L13="","",$L13+$N13) -> 47.28944 | P13: =IF($O13="","",$O13*CARBON_FRACTION_BIOMASS) -> 23.64472 | Q13: =IF(AND($A13="",$C13=""),"",IF(AND($A13<>"",COUNTIF('1. Plot & Site Log'!$A$5:$A$64,$A13)=0),"Plot ID not in Plot & Site Log — this tree will not reach the summary. ","")&IF($A13="","No Plot ID. ","")&IF(AND($C13<>"",$F13=""),"Species not in the coefficient list — check the spelling against R1. ","")&IF($D13="","No DBH — nothing can be calculated. ","")&IF(AND($D13<>"",$D13>QC_DBH_MAX_CM),"DBH above "&QC_DBH_MAX_CM&" cm — check for a transcription error. ","")&IF($M13="All","Generic species: no published root:shoot applies, so below-ground biomass is the mean of the deciduous and conifer relationships. Choose a species, or Deciduous/Conifers, if you can. ","")&IF(AND($O13<>"",$O13>0,OR($N13/$O13<BGB_FRACTION_MIN,$N13/$O13>BGB_FRACTION_MAX)),"Below-ground share is "&TEXT($N13/$O13,"0%")&", outside the 18–30% the Trees guide describes. ",""))
