Workbook

Sheet 0. Instructions
A1: GRASSLAND CARBON CALCULATOR
A2: WWF-Canada Carbon Measurement · Grassland Carbon Workshop
A4: What this workbook does | B4: Turns soil cores, separated roots and clipped vegetation into a carbon stock in kg C/m², scales plots to sites and to your study area, and checks the precision you achieved against the target you set in Part 2.
A6: COLOUR KEY
A7: Yellow | B7: TYPE HERE — field measurements you record.
A8: Blue | B8: TYPE HERE — lab results, once they come back.
A9: Orange | B9: NEEDS YOUR INPUT — a value this workshop cannot supply. Every one has a working default and a flag that stays lit until you replace it. They are all listed on '8. Fill Me In'.
A10: Grey | B10: Calculated for you. Do not type in grey cells.
A11: Green | B11: Summary — calculated.
A12: Red | B12: A QC flag. Read it; it is an instruction, not a decoration.
A14: FILL THE TABS IN THIS ORDER — each one joins to the ones above it
A15: 1. Plot & Site Log | B15: One row per plot. Everything keys to Plot ID, so fill this first.
A16: 2. Soil Data | B16: One row per depth increment per core. Joins on Plot ID and Core ID.
A17: 3. Root Biomass | B17: One row per increment per diameter class per live/dead state.
A18: 4. Vegetation Data | B18: One row per plot. Clip-and-weigh, shrubs, and tree carbon carried across from the Forests calculator.
A19: 5. Plot Summary | B19: Calculated. One row per plot.
A20: 6. Site Summary | B20: Calculated, except Site ID and site area. Soil and roots are checked against SEPARATE precision targets.
A21: 7. Settings | B21: Everything the workbook assumes. Orange rows need you.
A22: 8. Fill Me In | B22: Every orange cell in one list, with what happens if you leave it.
A23: R1. Reference | B23: Lookup tables — carbon fractions, grassland types, the bulk-density basis question.
A25: THREE THINGS THIS WORKBOOK WILL NOT LET YOU SKIP
A26: Roots and soil carbon can be double counted | B26: Soil carbon analysis conventionally removes visible roots, but fine roots stay in the sample. If root carbon is then added to a soil stock that already contains it, the same carbon is counted twice. ROOT_SOIL_REPORTING_BOUNDARY records which roots the soil sample no longer contains; until it is agreed with the lab, the Plot Summary refuses to add the two pools.
A27: 30 cm is a floor, not a total | B27: Native grassland roots reach metres. A root total whose deepest increment is simply the bottom of the core is a MINIMUM, and the Plot Summary flags it as one.
A28: A standing crop is not a stock | B28: Clipped vegetation grows from nothing each spring and is gone by autumn. It is reported in its own column and never merged into the soil figure.

Sheet 1. Plot & Site Log
A1: PLOT & SITE LOG
A2: ONE ROW PER PLOT. Fill this in first — everything joins to it on Plot ID. Management, grazing and fire are not optional context: they are the stratification variables, and they are what lets you post-stratify if your interval comes out wide.
A4: Plot ID | B4: Site ID | C4: Study area | D4: Date | E4: Location | F4: Latitude | G4: Longitude | H4: GNSS accuracy (m) | I4: Datum | J4: Elevation (m) | K4: Grassland type | L4: Management | M4: Grazing regime | N4: Years since fire | O4: Cultivation history | P4: Restoration year | Q4: Native or seeded | R4: Canopy cover (%) | S4: Slope position | T4: Notes
A5: GP-01 | B5: S1 | C5: RC | D5: 2026-08-05 | E5: Prairie unit | F5: 50.9 | G5: -104.62 | H5: 0.5 | I5: WGS84 | J5: 580 | K5: Prairie | L5: Never cultivated | M5: Season-long | N5: 12 | O5: Native sward | P5: 0 | Q5: Mid slope
A6: GP-02 | B6: S1 | C6: RC | D6: 2026-08-05 | E6: Prairie unit | F6: 50.904 | G6: -104.625 | H6: 0.5 | I6: WGS84 | J6: 577 | K6: Prairie | L6: Never cultivated | M6: Season-long | N6: 12 | O6: Native sward | P6: 0 | Q6: Mid slope
A7: GP-03 | B7: S1 | C7: RC | D7: 2026-08-05 | E7: Prairie unit | F7: 50.908 | G7: -104.63 | H7: 0.5 | I7: WGS84 | J7: 574 | K7: Prairie | L7: Never cultivated | M7: Season-long | N7: 12 | O7: Native sward | P7: 0 | Q7: Mid slope
A8: UP-01 | B8: S2 | C8: RC | D8: 2026-08-05 | E8: Prairie unit | F8: 50.912 | G8: -104.635 | H8: 0.5 | I8: WGS84 | J8: 571 | K8: Prairie | L8: Never cultivated | M8: None | N8: 12 | O8: Native sward | P8: 0 | Q8: Mid slope
A9: UP-02 | B9: S2 | C9: RC | D9: 2026-08-05 | E9: Prairie unit | F9: 50.916 | G9: -104.64 | H9: 0.5 | I9: WGS84 | J9: 568 | K9: Prairie | L9: Never cultivated | M9: None | N9: 12 | O9: Native sward | P9: 0 | Q9: Mid slope
A10: UP-03 | B10: S2 | C10: RC | D10: 2026-08-05 | E10: Prairie unit | F10: 50.92 | G10: -104.645 | H10: 0.5 | I10: WGS84 | J10: 565 | K10: Prairie | L10: Never cultivated | M10: None | N10: 12 | O10: Native sward | P10: 0 | Q10: Mid slope
A11: BOS-01 | B11: S3 | C11: RC | D11: 2026-08-05 | E11: Black Oak savannah unit | F11: 50.924 | G11: -104.65 | H11: 0.5 | I11: WGS84 | J11: 562 | K11: Black Oak savannah | L11: Never cultivated | M11: None | N11: 3 | O11: Native sward | P11: 28 | Q11: Mid slope
A12: BOS-02 | B12: S3 | C12: RC | D12: 2026-08-05 | E12: Black Oak savannah unit | F12: 50.928 | G12: -104.655 | H12: 0.5 | I12: WGS84 | J12: 559 | K12: Black Oak savannah | L12: Never cultivated | M12: None | N12: 3 | O12: Native sward | P12: 31 | Q12: Mid slope
A13: BOS-03 | B13: S3 | C13: RC | D13: 2026-08-05 | E13: Black Oak savannah unit | F13: 50.932 | G13: -104.66 | H13: 0.5 | I13: WGS84 | J13: 556 | K13: Black Oak savannah | L13: Never cultivated | M13: None | N13: 9 | O13: Native sward | P13: 22 | Q13: Mid slope

Sheet 2. Soil Data
A1: SOIL DATA
A2: ONE ROW PER DEPTH INCREMENT PER CORE. Record the ACTUAL top and bottom depths, not the ones you planned — a truncated increment scaled as a full one is a silent error. Bulk density and carbon come back from the lab.
A4: Plot ID | B4: Core ID | C4: Increment # | D4: Top depth (cm) | E4: Bottom depth (cm) | F4: Thickness (cm) | G4: Corer internal diameter (cm) | H4: Depth driven (cm) | I4: Length recovered (cm) | J4: Recovery ratio | K4: Coarse fragments (% vol) | L4: Bulk density basis | M4: Bulk density (g/cm³) | N4: Organic carbon (%) | O4: BD used (g/cm³) | P4: Stock, increment (kg C/m²) | Q4: Thickness within reporting depth (cm) | R4: Stock to reporting depth (kg C/m²) | S4: QC flags | T4: Notes | U4: _first_of_core
A5: GP-01 | B5: GP-01-C1 | C5: 1 | D5: 0 | E5: 10 | F5: =IF(OR($D5="",$E5=""),"",$E5-$D5) -> 10 | G5: 5 | H5: 10 | I5: 10 | J5: =IF(OR(NOT(ISNUMBER($H5)),NOT(ISNUMBER($I5)),$H5=0),"",$I5/$H5) -> 1 | K5: 2 | L5: Fine earth / total volume | M5: 1.019 | N5: 4.816 | O5: =IF(NOT(ISNUMBER($M5)),"",IF($L5="Fine earth / fine-earth volume",$M5*(1-IF(ISNUMBER($K5),$K5,0)/100),$M5)) -> 1.019 | P5: =IF(OR(NOT(ISNUMBER($O5)),NOT(ISNUMBER($N5)),NOT(ISNUMBER($F5))),"",$O5*($N5/100)*$F5*10) -> 4.907504 | Q5: =IF(OR(NOT(ISNUMBER($D5)),NOT(ISNUMBER($E5))),"",MAX(0,MIN($E5,SOIL_REPORTING_DEPTH_CM)-MIN($D5,SOIL_REPORTING_DEPTH_CM))) -> 10 | R5: =IF(OR(NOT(ISNUMBER($O5)),NOT(ISNUMBER($N5)),NOT(ISNUMBER($Q5))),"",$O5*($N5/100)*$Q5*10) -> 4.907504 | S5: =IF(AND($A5="",$B5="",$D5=""),"",IF(AND($A5<>"",COUNTIF('1. Plot & Site Log'!$A$5:$A$64,$A5)=0),"Plot ID not in the Plot & Site Log. ","")&IF(AND(ISNUMBER($D5),ISNUMBER($E5),$E5<=$D5),"Bottom depth is not below top depth. ","")&IF($L5="Not confirmed","Bulk-density basis not confirmed with the lab — the coarse-fragment correction may be wrong or doubled. ","")&IF(LAB_BULK_DENSITY_BASIS="Not confirmed","No lab bulk-density basis is on file in Settings (LAB_BULK_DENSITY_BASIS), so nothing checks this row. ","")&IF(AND($L5<>"",LAB_BULK_DENSITY_BASIS<>"Not confirmed",$L5<>LAB_BULK_DENSITY_BASIS),"This row's bulk-density basis disagrees with the lab method on file. One of "&"the two is wrong, and the coarse-fragment correction follows the row. ","")&IF(AND(ISNUMBER($M5),OR($M5<QC_BD_MIN,$M5>QC_BD_MAX)),"Bulk density outside the plausible range for a mineral grassland soil. ","")&IF(AND(ISNUMBER($N5),$N5>QC_CARBON_PCT_MAX),"Organic carbon above the QC ceiling — check units, and whether this is an organic horizon. ","")&IF(AND(ISNUMBER($J5),$J5<QC_RECOVERY_MIN),"Recovered less than the QC minimum of the depth driven — the increments may not sit where you think. Do NOT stretch them back out. ","")&IF(AND(ISNUMBER($K5),$K5>0,$L5="Fine earth / total volume"),"Coarse fragments recorded and the lab basis already accounts for them — no further correction applied, which is correct. ","")) -> Coarse fragments recorded and the lab basis already accounts for them — no further correction applied, which is correct. | U5: =IF($B5="",0,IF(COUNTIFS($B$5:$B5,$B5)=1,1,0)) -> 1
A6: GP-01 | B6: GP-01-C1 | C6: 2 | D6: 10 | E6: 20 | F6: =IF(OR($D6="",$E6=""),"",$E6-$D6) -> 10 | G6: 5 | H6: 20 | I6: 20 | J6: =IF(OR(NOT(ISNUMBER($H6)),NOT(ISNUMBER($I6)),$H6=0),"",$I6/$H6) -> 1 | K6: 2 | L6: Fine earth / total volume | M6: 1.182 | N6: 3.003 | O6: =IF(NOT(ISNUMBER($M6)),"",IF($L6="Fine earth / fine-earth volume",$M6*(1-IF(ISNUMBER($K6),$K6,0)/100),$M6)) -> 1.182 | P6: =IF(OR(NOT(ISNUMBER($O6)),NOT(ISNUMBER($N6)),NOT(ISNUMBER($F6))),"",$O6*($N6/100)*$F6*10) -> 3.549546 | Q6: =IF(OR(NOT(ISNUMBER($D6)),NOT(ISNUMBER($E6))),"",MAX(0,MIN($E6,SOIL_REPORTING_DEPTH_CM)-MIN($D6,SOIL_REPORTING_DEPTH_CM))) -> 10 | R6: =IF(OR(NOT(ISNUMBER($O6)),NOT(ISNUMBER($N6)),NOT(ISNUMBER($Q6))),"",$O6*($N6/100)*$Q6*10) -> 3.549546 | S6: =IF(AND($A6="",$B6="",$D6=""),"",IF(AND($A6<>"",COUNTIF('1. Plot & Site Log'!$A$5:$A$64,$A6)=0),"Plot ID not in the Plot & Site Log. ","")&IF(AND(ISNUMBER($D6),ISNUMBER($E6),$E6<=$D6),"Bottom depth is not below top depth. ","")&IF($L6="Not confirmed","Bulk-density basis not confirmed with the lab — the coarse-fragment correction may be wrong or doubled. ","")&IF(LAB_BULK_DENSITY_BASIS="Not confirmed","No lab bulk-density basis is on file in Settings (LAB_BULK_DENSITY_BASIS), so nothing checks this row. ","")&IF(AND($L6<>"",LAB_BULK_DENSITY_BASIS<>"Not confirmed",$L6<>LAB_BULK_DENSITY_BASIS),"This row's bulk-density basis disagrees with the lab method on file. One of "&"the two is wrong, and the coarse-fragment correction follows the row. ","")&IF(AND(ISNUMBER($M6),OR($M6<QC_BD_MIN,$M6>QC_BD_MAX)),"Bulk density outside the plausible range for a mineral grassland soil. ","")&IF(AND(ISNUMBER($N6),$N6>QC_CARBON_PCT_MAX),"Organic carbon above the QC ceiling — check units, and whether this is an organic horizon. ","")&IF(AND(ISNUMBER($J6),$J6<QC_RECOVERY_MIN),"Recovered less than the QC minimum of the depth driven — the increments may not sit where you think. Do NOT stretch them back out. ","")&IF(AND(ISNUMBER($K6),$K6>0,$L6="Fine earth / total volume"),"Coarse fragments recorded and the lab basis already accounts for them — no further correction applied, which is correct. ","")) -> Coarse fragments recorded and the lab basis already accounts for them — no further correction applied, which is correct. | U6: =IF($B6="",0,IF(COUNTIFS($B$5:$B6,$B6)=1,1,0)) -> 0
A7: GP-01 | B7: GP-01-C1 | C7: 3 | D7: 20 | E7: 30 | F7: =IF(OR($D7="",$E7=""),"",$E7-$D7) -> 10 | G7: 5 | H7: 30 | I7: 30 | J7: =IF(OR(NOT(ISNUMBER($H7)),NOT(ISNUMBER($I7)),$H7=0),"",$I7/$H7) -> 1 | K7: 2 | L7: Fine earth / total volume | M7: 1.283 | N7: 2.1 | O7: =IF(NOT(ISNUMBER($M7)),"",IF($L7="Fine earth / fine-earth volume",$M7*(1-IF(ISNUMBER($K7),$K7,0)/100),$M7)) -> 1.283 | P7: =IF(OR(NOT(ISNUMBER($O7)),NOT(ISNUMBER($N7)),NOT(ISNUMBER($F7))),"",$O7*($N7/100)*$F7*10) -> 2.6943 | Q7: =IF(OR(NOT(ISNUMBER($D7)),NOT(ISNUMBER($E7))),"",MAX(0,MIN($E7,SOIL_REPORTING_DEPTH_CM)-MIN($D7,SOIL_REPORTING_DEPTH_CM))) -> 10 | R7: =IF(OR(NOT(ISNUMBER($O7)),NOT(ISNUMBER($N7)),NOT(ISNUMBER($Q7))),"",$O7*($N7/100)*$Q7*10) -> 2.6943 | S7: =IF(AND($A7="",$B7="",$D7=""),"",IF(AND($A7<>"",COUNTIF('1. Plot & Site Log'!$A$5:$A$64,$A7)=0),"Plot ID not in the Plot & Site Log. ","")&IF(AND(ISNUMBER($D7),ISNUMBER($E7),$E7<=$D7),"Bottom depth is not below top depth. ","")&IF($L7="Not confirmed","Bulk-density basis not confirmed with the lab — the coarse-fragment correction may be wrong or doubled. ","")&IF(LAB_BULK_DENSITY_BASIS="Not confirmed","No lab bulk-density basis is on file in Settings (LAB_BULK_DENSITY_BASIS), so nothing checks this row. ","")&IF(AND($L7<>"",LAB_BULK_DENSITY_BASIS<>"Not confirmed",$L7<>LAB_BULK_DENSITY_BASIS),"This row's bulk-density basis disagrees with the lab method on file. One of "&"the two is wrong, and the coarse-fragment correction follows the row. ","")&IF(AND(ISNUMBER($M7),OR($M7<QC_BD_MIN,$M7>QC_BD_MAX)),"Bulk density outside the plausible range for a mineral grassland soil. ","")&IF(AND(ISNUMBER($N7),$N7>QC_CARBON_PCT_MAX),"Organic carbon above the QC ceiling — check units, and whether this is an organic horizon. ","")&IF(AND(ISNUMBER($J7),$J7<QC_RECOVERY_MIN),"Recovered less than the QC minimum of the depth driven — the increments may not sit where you think. Do NOT stretch them back out. ","")&IF(AND(ISNUMBER($K7),$K7>0,$L7="Fine earth / total volume"),"Coarse fragments recorded and the lab basis already accounts for them — no further correction applied, which is correct. ","")) -> Coarse fragments recorded and the lab basis already accounts for them — no further correction applied, which is correct. | U7: =IF($B7="",0,IF(COUNTIFS($B$5:$B7,$B7)=1,1,0)) -> 0
A8: GP-01 | B8: GP-01-C1 | C8: 4 | D8: 30 | E8: 60 | F8: =IF(OR($D8="",$E8=""),"",$E8-$D8) -> 30 | G8: 5 | H8: 60 | I8: 60 | J8: =IF(OR(NOT(ISNUMBER($H8)),NOT(ISNUMBER($I8)),$H8=0),"",$I8/$H8) -> 1 | K8: 2 | L8: Fine earth / total volume | M8: 1.359 | N8: 1.205 | O8: =IF(NOT(ISNUMBER($M8)),"",IF($L8="Fine earth / fine-earth volume",$M8*(1-IF(ISNUMBER($K8),$K8,0)/100),$M8)) -> 1.359 | P8: =IF(OR(NOT(ISNUMBER($O8)),NOT(ISNUMBER($N8)),NOT(ISNUMBER($F8))),"",$O8*($N8/100)*$F8*10) -> 4.912785 | Q8: =IF(OR(NOT(ISNUMBER($D8)),NOT(ISNUMBER($E8))),"",MAX(0,MIN($E8,SOIL_REPORTING_DEPTH_CM)-MIN($D8,SOIL_REPORTING_DEPTH_CM))) -> 0 | R8: =IF(OR(NOT(ISNUMBER($O8)),NOT(ISNUMBER($N8)),NOT(ISNUMBER($Q8))),"",$O8*($N8/100)*$Q8*10) -> 0 | S8: =IF(AND($A8="",$B8="",$D8=""),"",IF(AND($A8<>"",COUNTIF('1. Plot & Site Log'!$A$5:$A$64,$A8)=0),"Plot ID not in the Plot & Site Log. ","")&IF(AND(ISNUMBER($D8),ISNUMBER($E8),$E8<=$D8),"Bottom depth is not below top depth. ","")&IF($L8="Not confirmed","Bulk-density basis not confirmed with the lab — the coarse-fragment correction may be wrong or doubled. ","")&IF(LAB_BULK_DENSITY_BASIS="Not confirmed","No lab bulk-density basis is on file in Settings (LAB_BULK_DENSITY_BASIS), so nothing checks this row. ","")&IF(AND($L8<>"",LAB_BULK_DENSITY_BASIS<>"Not confirmed",$L8<>LAB_BULK_DENSITY_BASIS),"This row's bulk-density basis disagrees with the lab method on file. One of "&"the two is wrong, and the coarse-fragment correction follows the row. ","")&IF(AND(ISNUMBER($M8),OR($M8<QC_BD_MIN,$M8>QC_BD_MAX)),"Bulk density outside the plausible range for a mineral grassland soil. ","")&IF(AND(ISNUMBER($N8),$N8>QC_CARBON_PCT_MAX),"Organic carbon above the QC ceiling — check units, and whether this is an organic horizon. ","")&IF(AND(ISNUMBER($J8),$J8<QC_RECOVERY_MIN),"Recovered less than the QC minimum of the depth driven — the increments may not sit where you think. Do NOT stretch them back out. ","")&IF(AND(ISNUMBER($K8),$K8>0,$L8="Fine earth / total volume"),"Coarse fragments recorded and the lab basis already accounts for them — no further correction applied, which is correct. ","")) -> Coarse fragments recorded and the lab basis already accounts for them — no further correction applied, which is correct. | U8: =IF($B8="",0,IF(COUNTIFS($B$5:$B8,$B8)=1,1,0)) -> 0
A9: GP-02 | B9: GP-02-C1 | C9: 1 | D9: 0 | E9: 10 | F9: =IF(OR($D9="",$E9=""),"",$E9-$D9) -> 10 | G9: 5 | H9: 10 | I9: 10 | J9: =IF(OR(NOT(ISNUMBER($H9)),NOT(ISNUMBER($I9)),$H9=0),"",$I9/$H9) -> 1 | K9: 2 | L9: Not confirmed | M9: 1.02 | N9: 4.418 | O9: =IF(NOT(ISNUMBER($M9)),"",IF($L9="Fine earth / fine-earth volume",$M9*(1-IF(ISNUMBER($K9),$K9,0)/100),$M9)) -> 1.02 | P9: =IF(OR(NOT(ISNUMBER($O9)),NOT(ISNUMBER($N9)),NOT(ISNUMBER($F9))),"",$O9*($N9/100)*$F9*10) -> 4.50636 | Q9: =IF(OR(NOT(ISNUMBER($D9)),NOT(ISNUMBER($E9))),"",MAX(0,MIN($E9,SOIL_REPORTING_DEPTH_CM)-MIN($D9,SOIL_REPORTING_DEPTH_CM))) -> 10 | R9: =IF(OR(NOT(ISNUMBER($O9)),NOT(ISNUMBER($N9)),NOT(ISNUMBER($Q9))),"",$O9*($N9/100)*$Q9*10) -> 4.50636 | S9: =IF(AND($A9="",$B9="",$D9=""),"",IF(AND($A9<>"",COUNTIF('1. Plot & Site Log'!$A$5:$A$64,$A9)=0),"Plot ID not in the Plot & Site Log. ","")&IF(AND(ISNUMBER($D9),ISNUMBER($E9),$E9<=$D9),"Bottom depth is not below top depth. ","")&IF($L9="Not confirmed","Bulk-density basis not confirmed with the lab — the coarse-fragment correction may be wrong or doubled. ","")&IF(LAB_BULK_DENSITY_BASIS="Not confirmed","No lab bulk-density basis is on file in Settings (LAB_BULK_DENSITY_BASIS), so nothing checks this row. ","")&IF(AND($L9<>"",LAB_BULK_DENSITY_BASIS<>"Not confirmed",$L9<>LAB_BULK_DENSITY_BASIS),"This row's bulk-density basis disagrees with the lab method on file. One of "&"the two is wrong, and the coarse-fragment correction follows the row. ","")&IF(AND(ISNUMBER($M9),OR($M9<QC_BD_MIN,$M9>QC_BD_MAX)),"Bulk density outside the plausible range for a mineral grassland soil. ","")&IF(AND(ISNUMBER($N9),$N9>QC_CARBON_PCT_MAX),"Organic carbon above the QC ceiling — check units, and whether this is an organic horizon. ","")&IF(AND(ISNUMBER($J9),$J9<QC_RECOVERY_MIN),"Recovered less than the QC minimum of the depth driven — the increments may not sit where you think. Do NOT stretch them back out. ","")&IF(AND(ISNUMBER($K9),$K9>0,$L9="Fine earth / total volume"),"Coarse fragments recorded and the lab basis already accounts for them — no further correction applied, which is correct. ","")) -> Bulk-density basis not confirmed with the lab — the coarse-fragment correction may be wrong or doubled. This row's bulk-density basis disagrees with the lab method on file. One of the two is wrong, and the coarse-fragment correction follows the row. | U9: =IF($B9="",0,IF(COUNTIFS($B$5:$B9,$B9)=1,1,0)) -> 1
A10: GP-02 | B10: GP-02-C1 | C10: 2 | D10: 10 | E10: 20 | F10: =IF(OR($D10="",$E10=""),"",$E10-$D10) -> 10 | G10: 5 | H10: 20 | I10: 20 | J10: =IF(OR(NOT(ISNUMBER($H10)),NOT(ISNUMBER($I10)),$H10=0),"",$I10/$H10) -> 1 | K10: 2 | L10: Not confirmed | M10: 1.182 | N10: 2.75 | O10: =IF(NOT(ISNUMBER($M10)),"",IF($L10="Fine earth / fine-earth volume",$M10*(1-IF(ISNUMBER($K10),$K10,0)/100),$M10)) -> 1.182 | P10: =IF(OR(NOT(ISNUMBER($O10)),NOT(ISNUMBER($N10)),NOT(ISNUMBER($F10))),"",$O10*($N10/100)*$F10*10) -> 3.2505 | Q10: =IF(OR(NOT(ISNUMBER($D10)),NOT(ISNUMBER($E10))),"",MAX(0,MIN($E10,SOIL_REPORTING_DEPTH_CM)-MIN($D10,SOIL_REPORTING_DEPTH_CM))) -> 10 | R10: =IF(OR(NOT(ISNUMBER($O10)),NOT(ISNUMBER($N10)),NOT(ISNUMBER($Q10))),"",$O10*($N10/100)*$Q10*10) -> 3.2505 | S10: =IF(AND($A10="",$B10="",$D10=""),"",IF(AND($A10<>"",COUNTIF('1. Plot & Site Log'!$A$5:$A$64,$A10)=0),"Plot ID not in the Plot & Site Log. ","")&IF(AND(ISNUMBER($D10),ISNUMBER($E10),$E10<=$D10),"Bottom depth is not below top depth. ","")&IF($L10="Not confirmed","Bulk-density basis not confirmed with the lab — the coarse-fragment correction may be wrong or doubled. ","")&IF(LAB_BULK_DENSITY_BASIS="Not confirmed","No lab bulk-density basis is on file in Settings (LAB_BULK_DENSITY_BASIS), so nothing checks this row. ","")&IF(AND($L10<>"",LAB_BULK_DENSITY_BASIS<>"Not confirmed",$L10<>LAB_BULK_DENSITY_BASIS),"This row's bulk-density basis disagrees with the lab method on file. One of "&"the two is wrong, and the coarse-fragment correction follows the row. ","")&IF(AND(ISNUMBER($M10),OR($M10<QC_BD_MIN,$M10>QC_BD_MAX)),"Bulk density outside the plausible range for a mineral grassland soil. ","")&IF(AND(ISNUMBER($N10),$N10>QC_CARBON_PCT_MAX),"Organic carbon above the QC ceiling — check units, and whether this is an organic horizon. ","")&IF(AND(ISNUMBER($J10),$J10<QC_RECOVERY_MIN),"Recovered less than the QC minimum of the depth driven — the increments may not sit where you think. Do NOT stretch them back out. ","")&IF(AND(ISNUMBER($K10),$K10>0,$L10="Fine earth / total volume"),"Coarse fragments recorded and the lab basis already accounts for them — no further correction applied, which is correct. ","")) -> Bulk-density basis not confirmed with the lab — the coarse-fragment correction may be wrong or doubled. This row's bulk-density basis disagrees with the lab method on file. One of the two is wrong, and the coarse-fragment correction follows the row. | U10: =IF($B10="",0,IF(COUNTIFS($B$5:$B10,$B10)=1,1,0)) -> 0
A11: GP-02 | B11: GP-02-C1 | C11: 3 | D11: 20 | E11: 30 | F11: =IF(OR($D11="",$E11=""),"",$E11-$D11) -> 10 | G11: 5 | H11: 30 | I11: 30 | J11: =IF(OR(NOT(ISNUMBER($H11)),NOT(ISNUMBER($I11)),$H11=0),"",$I11/$H11) -> 1 | K11: 2 | L11: Not confirmed | M11: 1.26 | N11: 1.837 | O11: =IF(NOT(ISNUMBER($M11)),"",IF($L11="Fine earth / fine-earth volume",$M11*(1-IF(ISNUMBER($K11),$K11,0)/100),$M11)) -> 1.26 | P11: =IF(OR(NOT(ISNUMBER($O11)),NOT(ISNUMBER($N11)),NOT(ISNUMBER($F11))),"",$O11*($N11/100)*$F11*10) -> 2.31462 | Q11: =IF(OR(NOT(ISNUMBER($D11)),NOT(ISNUMBER($E11))),"",MAX(0,MIN($E11,SOIL_REPORTING_DEPTH_CM)-MIN($D11,SOIL_REPORTING_DEPTH_CM))) -> 10 | R11: =IF(OR(NOT(ISNUMBER($O11)),NOT(ISNUMBER($N11)),NOT(ISNUMBER($Q11))),"",$O11*($N11/100)*$Q11*10) -> 2.31462 | S11: =IF(AND($A11="",$B11="",$D11=""),"",IF(AND($A11<>"",COUNTIF('1. Plot & Site Log'!$A$5:$A$64,$A11)=0),"Plot ID not in the Plot & Site Log. ","")&IF(AND(ISNUMBER($D11),ISNUMBER($E11),$E11<=$D11),"Bottom depth is not below top depth. ","")&IF($L11="Not confirmed","Bulk-density basis not confirmed with the lab — the coarse-fragment correction may be wrong or doubled. ","")&IF(LAB_BULK_DENSITY_BASIS="Not confirmed","No lab bulk-density basis is on file in Settings (LAB_BULK_DENSITY_BASIS), so nothing checks this row. ","")&IF(AND($L11<>"",LAB_BULK_DENSITY_BASIS<>"Not confirmed",$L11<>LAB_BULK_DENSITY_BASIS),"This row's bulk-density basis disagrees with the lab method on file. One of "&"the two is wrong, and the coarse-fragment correction follows the row. ","")&IF(AND(ISNUMBER($M11),OR($M11<QC_BD_MIN,$M11>QC_BD_MAX)),"Bulk density outside the plausible range for a mineral grassland soil. ","")&IF(AND(ISNUMBER($N11),$N11>QC_CARBON_PCT_MAX),"Organic carbon above the QC ceiling — check units, and whether this is an organic horizon. ","")&IF(AND(ISNUMBER($J11),$J11<QC_RECOVERY_MIN),"Recovered less than the QC minimum of the depth driven — the increments may not sit where you think. Do NOT stretch them back out. ","")&IF(AND(ISNUMBER($K11),$K11>0,$L11="Fine earth / total volume"),"Coarse fragments recorded and the lab basis already accounts for them — no further correction applied, which is correct. ","")) -> Bulk-density basis not confirmed with the lab — the coarse-fragment correction may be wrong or doubled. This row's bulk-density basis disagrees with the lab method on file. One of the two is wrong, and the coarse-fragment correction follows the row. | U11: =IF($B11="",0,IF(COUNTIFS($B$5:$B11,$B11)=1,1,0)) -> 0
A12: GP-02 | B12: GP-02-C1 | C12: 4 | D12: 30 | E12: 60 | F12: =IF(OR($D12="",$E12=""),"",$E12-$D12) -> 30 | G12: 5 | H12: 60 | I12: 60 | J12: =IF(OR(NOT(ISNUMBER($H12)),NOT(ISNUMBER($I12)),$H12=0),"",$I12/$H12) -> 1 | K12: 2 | L12: Not confirmed | M12: 1.36 | N12: 1.105 | O12: =IF(NOT(ISNUMBER($M12)),"",IF($L12="Fine earth / fine-earth volume",$M12*(1-IF(ISNUMBER($K12),$K12,0)/100),$M12)) -> 1.36 | P12: =IF(OR(NOT(ISNUMBER($O12)),NOT(ISNUMBER($N12)),NOT(ISNUMBER($F12))),"",$O12*($N12/100)*$F12*10) -> 4.5084 | Q12: =IF(OR(NOT(ISNUMBER($D12)),NOT(ISNUMBER($E12))),"",MAX(0,MIN($E12,SOIL_REPORTING_DEPTH_CM)-MIN($D12,SOIL_REPORTING_DEPTH_CM))) -> 0 | R12: =IF(OR(NOT(ISNUMBER($O12)),NOT(ISNUMBER($N12)),NOT(ISNUMBER($Q12))),"",$O12*($N12/100)*$Q12*10) -> 0 | S12: =IF(AND($A12="",$B12="",$D12=""),"",IF(AND($A12<>"",COUNTIF('1. Plot & Site Log'!$A$5:$A$64,$A12)=0),"Plot ID not in the Plot & Site Log. ","")&IF(AND(ISNUMBER($D12),ISNUMBER($E12),$E12<=$D12),"Bottom depth is not below top depth. ","")&IF($L12="Not confirmed","Bulk-density basis not confirmed with the lab — the coarse-fragment correction may be wrong or doubled. ","")&IF(LAB_BULK_DENSITY_BASIS="Not confirmed","No lab bulk-density basis is on file in Settings (LAB_BULK_DENSITY_BASIS), so nothing checks this row. ","")&IF(AND($L12<>"",LAB_BULK_DENSITY_BASIS<>"Not confirmed",$L12<>LAB_BULK_DENSITY_BASIS),"This row's bulk-density basis disagrees with the lab method on file. One of "&"the two is wrong, and the coarse-fragment correction follows the row. ","")&IF(AND(ISNUMBER($M12),OR($M12<QC_BD_MIN,$M12>QC_BD_MAX)),"Bulk density outside the plausible range for a mineral grassland soil. ","")&IF(AND(ISNUMBER($N12),$N12>QC_CARBON_PCT_MAX),"Organic carbon above the QC ceiling — check units, and whether this is an organic horizon. ","")&IF(AND(ISNUMBER($J12),$J12<QC_RECOVERY_MIN),"Recovered less than the QC minimum of the depth driven — the increments may not sit where you think. Do NOT stretch them back out. ","")&IF(AND(ISNUMBER($K12),$K12>0,$L12="Fine earth / total volume"),"Coarse fragments recorded and the lab basis already accounts for them — no further correction applied, which is correct. ","")) -> Bulk-density basis not confirmed with the lab — the coarse-fragment correction may be wrong or doubled. This row's bulk-density basis disagrees with the lab method on file. One of the two is wrong, and the coarse-fragment correction follows the row. | U12: =IF($B12="",0,IF(COUNTIFS($B$5:$B12,$B12)=1,1,0)) -> 0
A13: GP-03 | B13: GP-03-C1 | C13: 1 | D13: 0 | E13: 10 | F13: =IF(OR($D13="",$E13=""),"",$E13-$D13) -> 10 | G13: 5 | H13: 10 | I13: 9.4 | J13: =IF(OR(NOT(ISNUMBER($H13)),NOT(ISNUMBER($I13)),$H13=0),"",$I13/$H13) -> 0.94 | K13: 2 | L13: Fine earth / total volume | M13: 1.023 | N13: 4.589 | O13: =IF(NOT(ISNUMBER($M13)),"",IF($L13="Fine earth / fine-earth volume",$M13*(1-IF(ISNUMBER($K13),$K13,0)/100),$M13)) -> 1.023 | P13: =IF(OR(NOT(ISNUMBER($O13)),NOT(ISNUMBER($N13)),NOT(ISNUMBER($F13))),"",$O13*($N13/100)*$F13*10) -> 4.694547 | Q13: =IF(OR(NOT(ISNUMBER($D13)),NOT(ISNUMBER($E13))),"",MAX(0,MIN($E13,SOIL_REPORTING_DEPTH_CM)-MIN($D13,SOIL_REPORTING_DEPTH_CM))) -> 10 | R13: =IF(OR(NOT(ISNUMBER($O13)),NOT(ISNUMBER($N13)),NOT(ISNUMBER($Q13))),"",$O13*($N13/100)*$Q13*10) -> 4.694547 | S13: =IF(AND($A13="",$B13="",$D13=""),"",IF(AND($A13<>"",COUNTIF('1. Plot & Site Log'!$A$5:$A$64,$A13)=0),"Plot ID not in the Plot & Site Log. ","")&IF(AND(ISNUMBER($D13),ISNUMBER($E13),$E13<=$D13),"Bottom depth is not below top depth. ","")&IF($L13="Not confirmed","Bulk-density basis not confirmed with the lab — the coarse-fragment correction may be wrong or doubled. ","")&IF(LAB_BULK_DENSITY_BASIS="Not confirmed","No lab bulk-density basis is on file in Settings (LAB_BULK_DENSITY_BASIS), so nothing checks this row. ","")&IF(AND($L13<>"",LAB_BULK_DENSITY_BASIS<>"Not confirmed",$L13<>LAB_BULK_DENSITY_BASIS),"This row's bulk-density basis disagrees with the lab method on file. One of "&"the two is wrong, and the coarse-fragment correction follows the row. ","")&IF(AND(ISNUMBER($M13),OR($M13<QC_BD_MIN,$M13>QC_BD_MAX)),"Bulk density outside the plausible range for a mineral grassland soil. ","")&IF(AND(ISNUMBER($N13),$N13>QC_CARBON_PCT_MAX),"Organic carbon above the QC ceiling — check units, and whether this is an organic horizon. ","")&IF(AND(ISNUMBER($J13),$J13<QC_RECOVERY_MIN),"Recovered less than the QC minimum of the depth driven — the increments may not sit where you think. Do NOT stretch them back out. ","")&IF(AND(ISNUMBER($K13),$K13>0,$L13="Fine earth / total volume"),"Coarse fragments recorded and the lab basis already accounts for them — no further correction applied, which is correct. ","")) -> Coarse fragments recorded and the lab basis already accounts for them — no further correction applied, which is correct. | U13: =IF($B13="",0,IF(COUNTIFS($B$5:$B13,$B13)=1,1,0)) -> 1
A14: GP-03 | B14: GP-03-C1 | C14: 2 | D14: 10 | E14: 20 | F14: =IF(OR($D14="",$E14=""),"",$E14-$D14) -> 10 | G14: 5 | H14: 20 | I14: 18.8 | J14: =IF(OR(NOT(ISNUMBER($H14)),NOT(ISNUMBER($I14)),$H14=0),"",$I14/$H14) -> 0.94 | K14: 2 | L14: Fine earth / total volume | M14: 1.188 | N14: 2.871 | O14: =IF(NOT(ISNUMBER($M14)),"",IF($L14="Fine earth / fine-earth volume",$M14*(1-IF(ISNUMBER($K14),$K14,0)/100),$M14)) -> 1.188 | P14: =IF(OR(NOT(ISNUMBER($O14)),NOT(ISNUMBER($N14)),NOT(ISNUMBER($F14))),"",$O14*($N14/100)*$F14*10) -> 3.410748 | Q14: =IF(OR(NOT(ISNUMBER($D14)),NOT(ISNUMBER($E14))),"",MAX(0,MIN($E14,SOIL_REPORTING_DEPTH_CM)-MIN($D14,SOIL_REPORTING_DEPTH_CM))) -> 10 | R14: =IF(OR(NOT(ISNUMBER($O14)),NOT(ISNUMBER($N14)),NOT(ISNUMBER($Q14))),"",$O14*($N14/100)*$Q14*10) -> 3.410748 | S14: =IF(AND($A14="",$B14="",$D14=""),"",IF(AND($A14<>"",COUNTIF('1. Plot & Site Log'!$A$5:$A$64,$A14)=0),"Plot ID not in the Plot & Site Log. ","")&IF(AND(ISNUMBER($D14),ISNUMBER($E14),$E14<=$D14),"Bottom depth is not below top depth. ","")&IF($L14="Not confirmed","Bulk-density basis not confirmed with the lab — the coarse-fragment correction may be wrong or doubled. ","")&IF(LAB_BULK_DENSITY_BASIS="Not confirmed","No lab bulk-density basis is on file in Settings (LAB_BULK_DENSITY_BASIS), so nothing checks this row. ","")&IF(AND($L14<>"",LAB_BULK_DENSITY_BASIS<>"Not confirmed",$L14<>LAB_BULK_DENSITY_BASIS),"This row's bulk-density basis disagrees with the lab method on file. One of "&"the two is wrong, and the coarse-fragment correction follows the row. ","")&IF(AND(ISNUMBER($M14),OR($M14<QC_BD_MIN,$M14>QC_BD_MAX)),"Bulk density outside the plausible range for a mineral grassland soil. ","")&IF(AND(ISNUMBER($N14),$N14>QC_CARBON_PCT_MAX),"Organic carbon above the QC ceiling — check units, and whether this is an organic horizon. ","")&IF(AND(ISNUMBER($J14),$J14<QC_RECOVERY_MIN),"Recovered less than the QC minimum of the depth driven — the increments may not sit where you think. Do NOT stretch them back out. ","")&IF(AND(ISNUMBER($K14),$K14>0,$L14="Fine earth / total volume"),"Coarse fragments recorded and the lab basis already accounts for them — no further correction applied, which is correct. ","")) -> Coarse fragments recorded and the lab basis already accounts for them — no further correction applied, which is correct. | U14: =IF($B14="",0,IF(COUNTIFS($B$5:$B14,$B14)=1,1,0)) -> 0
A15: GP-03 | B15: GP-03-C1 | C15: 3 | D15: 20 | E15: 30 | F15: =IF(OR($D15="",$E15=""),"",$E15-$D15) -> 10 | G15: 5 | H15: 30 | I15: 28.2 | J15: =IF(OR(NOT(ISNUMBER($H15)),NOT(ISNUMBER($I15)),$H15=0),"",$I15/$H15) -> 0.94 | K15: 2 | L15: Fine earth / total volume | M15: 1.258 | N15: 1.883 | O15: =IF(NOT(ISNUMBER($M15)),"",IF($L15="Fine earth / fine-earth volume",$M15*(1-IF(ISNUMBER($K15),$K15,0)/100),$M15)) -> 1.258 | P15: =IF(OR(NOT(ISNUMBER($O15)),NOT(ISNUMBER($N15)),NOT(ISNUMBER($F15))),"",$O15*($N15/100)*$F15*10) -> 2.368814 | Q15: =IF(OR(NOT(ISNUMBER($D15)),NOT(ISNUMBER($E15))),"",MAX(0,MIN($E15,SOIL_REPORTING_DEPTH_CM)-MIN($D15,SOIL_REPORTING_DEPTH_CM))) -> 10 | R15: =IF(OR(NOT(ISNUMBER($O15)),NOT(ISNUMBER($N15)),NOT(ISNUMBER($Q15))),"",$O15*($N15/100)*$Q15*10) -> 2.368814 | S15: =IF(AND($A15="",$B15="",$D15=""),"",IF(AND($A15<>"",COUNTIF('1. Plot & Site Log'!$A$5:$A$64,$A15)=0),"Plot ID not in the Plot & Site Log. ","")&IF(AND(ISNUMBER($D15),ISNUMBER($E15),$E15<=$D15),"Bottom depth is not below top depth. ","")&IF($L15="Not confirmed","Bulk-density basis not confirmed with the lab — the coarse-fragment correction may be wrong or doubled. ","")&IF(LAB_BULK_DENSITY_BASIS="Not confirmed","No lab bulk-density basis is on file in Settings (LAB_BULK_DENSITY_BASIS), so nothing checks this row. ","")&IF(AND($L15<>"",LAB_BULK_DENSITY_BASIS<>"Not confirmed",$L15<>LAB_BULK_DENSITY_BASIS),"This row's bulk-density basis disagrees with the lab method on file. One of "&"the two is wrong, and the coarse-fragment correction follows the row. ","")&IF(AND(ISNUMBER($M15),OR($M15<QC_BD_MIN,$M15>QC_BD_MAX)),"Bulk density outside the plausible range for a mineral grassland soil. ","")&IF(AND(ISNUMBER($N15),$N15>QC_CARBON_PCT_MAX),"Organic carbon above the QC ceiling — check units, and whether this is an organic horizon. ","")&IF(AND(ISNUMBER($J15),$J15<QC_RECOVERY_MIN),"Recovered less than the QC minimum of the depth driven — the increments may not sit where you think. Do NOT stretch them back out. ","")&IF(AND(ISNUMBER($K15),$K15>0,$L15="Fine earth / total volume"),"Coarse fragments recorded and the lab basis already accounts for them — no further correction applied, which is correct. ","")) -> Coarse fragments recorded and the lab basis already accounts for them — no further correction applied, which is correct. | U15: =IF($B15="",0,IF(COUNTIFS($B$5:$B15,$B15)=1,1,0)) -> 0
A16: GP-03 | B16: GP-03-C1 | C16: 4 | D16: 30 | E16: 60 | F16: =IF(OR($D16="",$E16=""),"",$E16-$D16) -> 30 | G16: 5 | H16: 60 | I16: 56.4 | J16: =IF(OR(NOT(ISNUMBER($H16)),NOT(ISNUMBER($I16)),$H16=0),"",$I16/$H16) -> 0.94 | K16: 2 | L16: Fine earth / total volume | M16: 1.354 | N16: 1.125 | O16: =IF(NOT(ISNUMBER($M16)),"",IF($L16="Fine earth / fine-earth volume",$M16*(1-IF(ISNUMBER($K16),$K16,0)/100),$M16)) -> 1.354 | P16: =IF(OR(NOT(ISNUMBER($O16)),NOT(ISNUMBER($N16)),NOT(ISNUMBER($F16))),"",$O16*($N16/100)*$F16*10) -> 4.56975 | Q16: =IF(OR(NOT(ISNUMBER($D16)),NOT(ISNUMBER($E16))),"",MAX(0,MIN($E16,SOIL_REPORTING_DEPTH_CM)-MIN($D16,SOIL_REPORTING_DEPTH_CM))) -> 0 | R16: =IF(OR(NOT(ISNUMBER($O16)),NOT(ISNUMBER($N16)),NOT(ISNUMBER($Q16))),"",$O16*($N16/100)*$Q16*10) -> 0 | S16: =IF(AND($A16="",$B16="",$D16=""),"",IF(AND($A16<>"",COUNTIF('1. Plot & Site Log'!$A$5:$A$64,$A16)=0),"Plot ID not in the Plot & Site Log. ","")&IF(AND(ISNUMBER($D16),ISNUMBER($E16),$E16<=$D16),"Bottom depth is not below top depth. ","")&IF($L16="Not confirmed","Bulk-density basis not confirmed with the lab — the coarse-fragment correction may be wrong or doubled. ","")&IF(LAB_BULK_DENSITY_BASIS="Not confirmed","No lab bulk-density basis is on file in Settings (LAB_BULK_DENSITY_BASIS), so nothing checks this row. ","")&IF(AND($L16<>"",LAB_BULK_DENSITY_BASIS<>"Not confirmed",$L16<>LAB_BULK_DENSITY_BASIS),"This row's bulk-density basis disagrees with the lab method on file. One of "&"the two is wrong, and the coarse-fragment correction follows the row. ","")&IF(AND(ISNUMBER($M16),OR($M16<QC_BD_MIN,$M16>QC_BD_MAX)),"Bulk density outside the plausible range for a mineral grassland soil. ","")&IF(AND(ISNUMBER($N16),$N16>QC_CARBON_PCT_MAX),"Organic carbon above the QC ceiling — check units, and whether this is an organic horizon. ","")&IF(AND(ISNUMBER($J16),$J16<QC_RECOVERY_MIN),"Recovered less than the QC minimum of the depth driven — the increments may not sit where you think. Do NOT stretch them back out. ","")&IF(AND(ISNUMBER($K16),$K16>0,$L16="Fine earth / total volume"),"Coarse fragments recorded and the lab basis already accounts for them — no further correction applied, which is correct. ","")) -> Coarse fragments recorded and the lab basis already accounts for them — no further correction applied, which is correct. | U16: =IF($B16="",0,IF(COUNTIFS($B$5:$B16,$B16)=1,1,0)) -> 0
... A37: BOS-03 | B37: BOS-03-C1 | C37: 2 | D37: 10 | E37: 20 | F37: =IF(OR($D37="",$E37=""),"",$E37-$D37) -> 10 | G37: 5 | H37: 20 | I37: 20 | J37: =IF(OR(NOT(ISNUMBER($H37)),NOT(ISNUMBER($I37)),$H37=0),"",$I37/$H37) -> 1 | K37: 11 | L37: Fine earth / total volume | M37: 1.43 | N37: 1.362 | O37: =IF(NOT(ISNUMBER($M37)),"",IF($L37="Fine earth / fine-earth volume",$M37*(1-IF(ISNUMBER($K37),$K37,0)/100),$M37)) -> 1.43 | P37: =IF(OR(NOT(ISNUMBER($O37)),NOT(ISNUMBER($N37)),NOT(ISNUMBER($F37))),"",$O37*($N37/100)*$F37*10) -> 1.94766 | Q37: =IF(OR(NOT(ISNUMBER($D37)),NOT(ISNUMBER($E37))),"",MAX(0,MIN($E37,SOIL_REPORTING_DEPTH_CM)-MIN($D37,SOIL_REPORTING_DEPTH_CM))) -> 10 | R37: =IF(OR(NOT(ISNUMBER($O37)),NOT(ISNUMBER($N37)),NOT(ISNUMBER($Q37))),"",$O37*($N37/100)*$Q37*10) -> 1.94766 | S37: =IF(AND($A37="",$B37="",$D37=""),"",IF(AND($A37<>"",COUNTIF('1. Plot & Site Log'!$A$5:$A$64,$A37)=0),"Plot ID not in the Plot & Site Log. ","")&IF(AND(ISNUMBER($D37),ISNUMBER($E37),$E37<=$D37),"Bottom depth is not below top depth. ","")&IF($L37="Not confirmed","Bulk-density basis not confirmed with the lab — the coarse-fragment correction may be wrong or doubled. ","")&IF(LAB_BULK_DENSITY_BASIS="Not confirmed","No lab bulk-density basis is on file in Settings (LAB_BULK_DENSITY_BASIS), so nothing checks this row. ","")&IF(AND($L37<>"",LAB_BULK_DENSITY_BASIS<>"Not confirmed",$L37<>LAB_BULK_DENSITY_BASIS),"This row's bulk-density basis disagrees with the lab method on file. One of "&"the two is wrong, and the coarse-fragment correction follows the row. ","")&IF(AND(ISNUMBER($M37),OR($M37<QC_BD_MIN,$M37>QC_BD_MAX)),"Bulk density outside the plausible range for a mineral grassland soil. ","")&IF(AND(ISNUMBER($N37),$N37>QC_CARBON_PCT_MAX),"Organic carbon above the QC ceiling — check units, and whether this is an organic horizon. ","")&IF(AND(ISNUMBER($J37),$J37<QC_RECOVERY_MIN),"Recovered less than the QC minimum of the depth driven — the increments may not sit where you think. Do NOT stretch them back out. ","")&IF(AND(ISNUMBER($K37),$K37>0,$L37="Fine earth / total volume"),"Coarse fragments recorded and the lab basis already accounts for them — no further correction applied, which is correct. ","")) -> Coarse fragments recorded and the lab basis already accounts for them — no further correction applied, which is correct. | U37: =IF($B37="",0,IF(COUNTIFS($B$5:$B37,$B37)=1,1,0)) -> 0
A38: BOS-03 | B38: BOS-03-C1 | C38: 3 | D38: 20 | E38: 22 | F38: =IF(OR($D38="",$E38=""),"",$E38-$D38) -> 2 | G38: 5 | H38: 22 | I38: 22 | J38: =IF(OR(NOT(ISNUMBER($H38)),NOT(ISNUMBER($I38)),$H38=0),"",$I38/$H38) -> 1 | K38: 11 | L38: Fine earth / total volume | M38: 1.516 | N38: 0.792 | O38: =IF(NOT(ISNUMBER($M38)),"",IF($L38="Fine earth / fine-earth volume",$M38*(1-IF(ISNUMBER($K38),$K38,0)/100),$M38)) -> 1.516 | P38: =IF(OR(NOT(ISNUMBER($O38)),NOT(ISNUMBER($N38)),NOT(ISNUMBER($F38))),"",$O38*($N38/100)*$F38*10) -> 0.2401344 | Q38: =IF(OR(NOT(ISNUMBER($D38)),NOT(ISNUMBER($E38))),"",MAX(0,MIN($E38,SOIL_REPORTING_DEPTH_CM)-MIN($D38,SOIL_REPORTING_DEPTH_CM))) -> 2 | R38: =IF(OR(NOT(ISNUMBER($O38)),NOT(ISNUMBER($N38)),NOT(ISNUMBER($Q38))),"",$O38*($N38/100)*$Q38*10) -> 0.2401344 | S38: =IF(AND($A38="",$B38="",$D38=""),"",IF(AND($A38<>"",COUNTIF('1. Plot & Site Log'!$A$5:$A$64,$A38)=0),"Plot ID not in the Plot & Site Log. ","")&IF(AND(ISNUMBER($D38),ISNUMBER($E38),$E38<=$D38),"Bottom depth is not below top depth. ","")&IF($L38="Not confirmed","Bulk-density basis not confirmed with the lab — the coarse-fragment correction may be wrong or doubled. ","")&IF(LAB_BULK_DENSITY_BASIS="Not confirmed","No lab bulk-density basis is on file in Settings (LAB_BULK_DENSITY_BASIS), so nothing checks this row. ","")&IF(AND($L38<>"",LAB_BULK_DENSITY_BASIS<>"Not confirmed",$L38<>LAB_BULK_DENSITY_BASIS),"This row's bulk-density basis disagrees with the lab method on file. One of "&"the two is wrong, and the coarse-fragment correction follows the row. ","")&IF(AND(ISNUMBER($M38),OR($M38<QC_BD_MIN,$M38>QC_BD_MAX)),"Bulk density outside the plausible range for a mineral grassland soil. ","")&IF(AND(ISNUMBER($N38),$N38>QC_CARBON_PCT_MAX),"Organic carbon above the QC ceiling — check units, and whether this is an organic horizon. ","")&IF(AND(ISNUMBER($J38),$J38<QC_RECOVERY_MIN),"Recovered less than the QC minimum of the depth driven — the increments may not sit where you think. Do NOT stretch them back out. ","")&IF(AND(ISNUMBER($K38),$K38>0,$L38="Fine earth / total volume"),"Coarse fragments recorded and the lab basis already accounts for them — no further correction applied, which is correct. ","")) -> Coarse fragments recorded and the lab basis already accounts for them — no further correction applied, which is correct. | T38: Refusal on bedrock at 22 cm. | U38: =IF($B38="",0,IF(COUNTIFS($B$5:$B38,$B38)=1,1,0)) -> 0
F39: =IF(OR($D39="",$E39=""),"",$E39-$D39) | J39: =IF(OR(NOT(ISNUMBER($H39)),NOT(ISNUMBER($I39)),$H39=0),"",$I39/$H39) | O39: =IF(NOT(ISNUMBER($M39)),"",IF($L39="Fine earth / fine-earth volume",$M39*(1-IF(ISNUMBER($K39),$K39,0)/100),$M39)) | P39: =IF(OR(NOT(ISNUMBER($O39)),NOT(ISNUMBER($N39)),NOT(ISNUMBER($F39))),"",$O39*($N39/100)*$F39*10) | Q39: =IF(OR(NOT(ISNUMBER($D39)),NOT(ISNUMBER($E39))),"",MAX(0,MIN($E39,SOIL_REPORTING_DEPTH_CM)-MIN($D39,SOIL_REPORTING_DEPTH_CM))) | R39: =IF(OR(NOT(ISNUMBER($O39)),NOT(ISNUMBER($N39)),NOT(ISNUMBER($Q39))),"",$O39*($N39/100)*$Q39*10) | S39: =IF(AND($A39="",$B39="",$D39=""),"",IF(AND($A39<>"",COUNTIF('1. Plot & Site Log'!$A$5:$A$64,$A39)=0),"Plot ID not in the Plot & Site Log. ","")&IF(AND(ISNUMBER($D39),ISNUMBER($E39),$E39<=$D39),"Bottom depth is not below top depth. ","")&IF($L39="Not confirmed","Bulk-density basis not confirmed with the lab — the coarse-fragment correction may be wrong or doubled. ","")&IF(LAB_BULK_DENSITY_BASIS="Not confirmed","No lab bulk-density basis is on file in Settings (LAB_BULK_DENSITY_BASIS), so nothing checks this row. ","")&IF(AND($L39<>"",LAB_BULK_DENSITY_BASIS<>"Not confirmed",$L39<>LAB_BULK_DENSITY_BASIS),"This row's bulk-density basis disagrees with the lab method on file. One of "&"the two is wrong, and the coarse-fragment correction follows the row. ","")&IF(AND(ISNUMBER($M39),OR($M39<QC_BD_MIN,$M39>QC_BD_MAX)),"Bulk density outside the plausible range for a mineral grassland soil. ","")&IF(AND(ISNUMBER($N39),$N39>QC_CARBON_PCT_MAX),"Organic carbon above the QC ceiling — check units, and whether this is an organic horizon. ","")&IF(AND(ISNUMBER($J39),$J39<QC_RECOVERY_MIN),"Recovered less than the QC minimum of the depth driven — the increments may not sit where you think. Do NOT stretch them back out. ","")&IF(AND(ISNUMBER($K39),$K39>0,$L39="Fine earth / total volume"),"Coarse fragments recorded and the lab basis already accounts for them — no further correction applied, which is correct. ","")) | U39: =IF($B39="",0,IF(COUNTIFS($B$5:$B39,$B39)=1,1,0)) -> 0
F40: =IF(OR($D40="",$E40=""),"",$E40-$D40) | J40: =IF(OR(NOT(ISNUMBER($H40)),NOT(ISNUMBER($I40)),$H40=0),"",$I40/$H40) | O40: =IF(NOT(ISNUMBER($M40)),"",IF($L40="Fine earth / fine-earth volume",$M40*(1-IF(ISNUMBER($K40),$K40,0)/100),$M40)) | P40: =IF(OR(NOT(ISNUMBER($O40)),NOT(ISNUMBER($N40)),NOT(ISNUMBER($F40))),"",$O40*($N40/100)*$F40*10) | Q40: =IF(OR(NOT(ISNUMBER($D40)),NOT(ISNUMBER($E40))),"",MAX(0,MIN($E40,SOIL_REPORTING_DEPTH_CM)-MIN($D40,SOIL_REPORTING_DEPTH_CM))) | R40: =IF(OR(NOT(ISNUMBER($O40)),NOT(ISNUMBER($N40)),NOT(ISNUMBER($Q40))),"",$O40*($N40/100)*$Q40*10) | S40: =IF(AND($A40="",$B40="",$D40=""),"",IF(AND($A40<>"",COUNTIF('1. Plot & Site Log'!$A$5:$A$64,$A40)=0),"Plot ID not in the Plot & Site Log. ","")&IF(AND(ISNUMBER($D40),ISNUMBER($E40),$E40<=$D40),"Bottom depth is not below top depth. ","")&IF($L40="Not confirmed","Bulk-density basis not confirmed with the lab — the coarse-fragment correction may be wrong or doubled. ","")&IF(LAB_BULK_DENSITY_BASIS="Not confirmed","No lab bulk-density basis is on file in Settings (LAB_BULK_DENSITY_BASIS), so nothing checks this row. ","")&IF(AND($L40<>"",LAB_BULK_DENSITY_BASIS<>"Not confirmed",$L40<>LAB_BULK_DENSITY_BASIS),"This row's bulk-density basis disagrees with the lab method on file. One of "&"the two is wrong, and the coarse-fragment correction follows the row. ","")&IF(AND(ISNUMBER($M40),OR($M40<QC_BD_MIN,$M40>QC_BD_MAX)),"Bulk density outside the plausible range for a mineral grassland soil. ","")&IF(AND(ISNUMBER($N40),$N40>QC_CARBON_PCT_MAX),"Organic carbon above the QC ceiling — check units, and whether this is an organic horizon. ","")&IF(AND(ISNUMBER($J40),$J40<QC_RECOVERY_MIN),"Recovered less than the QC minimum of the depth driven — the increments may not sit where you think. Do NOT stretch them back out. ","")&IF(AND(ISNUMBER($K40),$K40>0,$L40="Fine earth / total volume"),"Coarse fragments recorded and the lab basis already accounts for them — no further correction applied, which is correct. ","")) | U40: =IF($B40="",0,IF(COUNTIFS($B$5:$B40,$B40)=1,1,0)) -> 0
F41: =IF(OR($D41="",$E41=""),"",$E41-$D41) | J41: =IF(OR(NOT(ISNUMBER($H41)),NOT(ISNUMBER($I41)),$H41=0),"",$I41/$H41) | O41: =IF(NOT(ISNUMBER($M41)),"",IF($L41="Fine earth / fine-earth volume",$M41*(1-IF(ISNUMBER($K41),$K41,0)/100),$M41)) | P41: =IF(OR(NOT(ISNUMBER($O41)),NOT(ISNUMBER($N41)),NOT(ISNUMBER($F41))),"",$O41*($N41/100)*$F41*10) | Q41: =IF(OR(NOT(ISNUMBER($D41)),NOT(ISNUMBER($E41))),"",MAX(0,MIN($E41,SOIL_REPORTING_DEPTH_CM)-MIN($D41,SOIL_REPORTING_DEPTH_CM))) | R41: =IF(OR(NOT(ISNUMBER($O41)),NOT(ISNUMBER($N41)),NOT(ISNUMBER($Q41))),"",$O41*($N41/100)*$Q41*10) | S41: =IF(AND($A41="",$B41="",$D41=""),"",IF(AND($A41<>"",COUNTIF('1. Plot & Site Log'!$A$5:$A$64,$A41)=0),"Plot ID not in the Plot & Site Log. ","")&IF(AND(ISNUMBER($D41),ISNUMBER($E41),$E41<=$D41),"Bottom depth is not below top depth. ","")&IF($L41="Not confirmed","Bulk-density basis not confirmed with the lab — the coarse-fragment correction may be wrong or doubled. ","")&IF(LAB_BULK_DENSITY_BASIS="Not confirmed","No lab bulk-density basis is on file in Settings (LAB_BULK_DENSITY_BASIS), so nothing checks this row. ","")&IF(AND($L41<>"",LAB_BULK_DENSITY_BASIS<>"Not confirmed",$L41<>LAB_BULK_DENSITY_BASIS),"This row's bulk-density basis disagrees with the lab method on file. One of "&"the two is wrong, and the coarse-fragment correction follows the row. ","")&IF(AND(ISNUMBER($M41),OR($M41<QC_BD_MIN,$M41>QC_BD_MAX)),"Bulk density outside the plausible range for a mineral grassland soil. ","")&IF(AND(ISNUMBER($N41),$N41>QC_CARBON_PCT_MAX),"Organic carbon above the QC ceiling — check units, and whether this is an organic horizon. ","")&IF(AND(ISNUMBER($J41),$J41<QC_RECOVERY_MIN),"Recovered less than the QC minimum of the depth driven — the increments may not sit where you think. Do NOT stretch them back out. ","")&IF(AND(ISNUMBER($K41),$K41>0,$L41="Fine earth / total volume"),"Coarse fragments recorded and the lab basis already accounts for them — no further correction applied, which is correct. ","")) | U41: =IF($B41="",0,IF(COUNTIFS($B$5:$B41,$B41)=1,1,0)) -> 0
F42: =IF(OR($D42="",$E42=""),"",$E42-$D42) | J42: =IF(OR(NOT(ISNUMBER($H42)),NOT(ISNUMBER($I42)),$H42=0),"",$I42/$H42) | O42: =IF(NOT(ISNUMBER($M42)),"",IF($L42="Fine earth / fine-earth volume",$M42*(1-IF(ISNUMBER($K42),$K42,0)/100),$M42)) | P42: =IF(OR(NOT(ISNUMBER($O42)),NOT(ISNUMBER($N42)),NOT(ISNUMBER($F42))),"",$O42*($N42/100)*$F42*10) | Q42: =IF(OR(NOT(ISNUMBER($D42)),NOT(ISNUMBER($E42))),"",MAX(0,MIN($E42,SOIL_REPORTING_DEPTH_CM)-MIN($D42,SOIL_REPORTING_DEPTH_CM))) | R42: =IF(OR(NOT(ISNUMBER($O42)),NOT(ISNUMBER($N42)),NOT(ISNUMBER($Q42))),"",$O42*($N42/100)*$Q42*10) | S42: =IF(AND($A42="",$B42="",$D42=""),"",IF(AND($A42<>"",COUNTIF('1. Plot & Site Log'!$A$5:$A$64,$A42)=0),"Plot ID not in the Plot & Site Log. ","")&IF(AND(ISNUMBER($D42),ISNUMBER($E42),$E42<=$D42),"Bottom depth is not below top depth. ","")&IF($L42="Not confirmed","Bulk-density basis not confirmed with the lab — the coarse-fragment correction may be wrong or doubled. ","")&IF(LAB_BULK_DENSITY_BASIS="Not confirmed","No lab bulk-density basis is on file in Settings (LAB_BULK_DENSITY_BASIS), so nothing checks this row. ","")&IF(AND($L42<>"",LAB_BULK_DENSITY_BASIS<>"Not confirmed",$L42<>LAB_BULK_DENSITY_BASIS),"This row's bulk-density basis disagrees with the lab method on file. One of "&"the two is wrong, and the coarse-fragment correction follows the row. ","")&IF(AND(ISNUMBER($M42),OR($M42<QC_BD_MIN,$M42>QC_BD_MAX)),"Bulk density outside the plausible range for a mineral grassland soil. ","")&IF(AND(ISNUMBER($N42),$N42>QC_CARBON_PCT_MAX),"Organic carbon above the QC ceiling — check units, and whether this is an organic horizon. ","")&IF(AND(ISNUMBER($J42),$J42<QC_RECOVERY_MIN),"Recovered less than the QC minimum of the depth driven — the increments may not sit where you think. Do NOT stretch them back out. ","")&IF(AND(ISNUMBER($K42),$K42>0,$L42="Fine earth / total volume"),"Coarse fragments recorded and the lab basis already accounts for them — no further correction applied, which is correct. ","")) | U42: =IF($B42="",0,IF(COUNTIFS($B$5:$B42,$B42)=1,1,0)) -> 0
F43: =IF(OR($D43="",$E43=""),"",$E43-$D43) | J43: =IF(OR(NOT(ISNUMBER($H43)),NOT(ISNUMBER($I43)),$H43=0),"",$I43/$H43) | O43: =IF(NOT(ISNUMBER($M43)),"",IF($L43="Fine earth / fine-earth volume",$M43*(1-IF(ISNUMBER($K43),$K43,0)/100),$M43)) | P43: =IF(OR(NOT(ISNUMBER($O43)),NOT(ISNUMBER($N43)),NOT(ISNUMBER($F43))),"",$O43*($N43/100)*$F43*10) | Q43: =IF(OR(NOT(ISNUMBER($D43)),NOT(ISNUMBER($E43))),"",MAX(0,MIN($E43,SOIL_REPORTING_DEPTH_CM)-MIN($D43,SOIL_REPORTING_DEPTH_CM))) | R43: =IF(OR(NOT(ISNUMBER($O43)),NOT(ISNUMBER($N43)),NOT(ISNUMBER($Q43))),"",$O43*($N43/100)*$Q43*10) | S43: =IF(AND($A43="",$B43="",$D43=""),"",IF(AND($A43<>"",COUNTIF('1. Plot & Site Log'!$A$5:$A$64,$A43)=0),"Plot ID not in the Plot & Site Log. ","")&IF(AND(ISNUMBER($D43),ISNUMBER($E43),$E43<=$D43),"Bottom depth is not below top depth. ","")&IF($L43="Not confirmed","Bulk-density basis not confirmed with the lab — the coarse-fragment correction may be wrong or doubled. ","")&IF(LAB_BULK_DENSITY_BASIS="Not confirmed","No lab bulk-density basis is on file in Settings (LAB_BULK_DENSITY_BASIS), so nothing checks this row. ","")&IF(AND($L43<>"",LAB_BULK_DENSITY_BASIS<>"Not confirmed",$L43<>LAB_BULK_DENSITY_BASIS),"This row's bulk-density basis disagrees with the lab method on file. One of "&"the two is wrong, and the coarse-fragment correction follows the row. ","")&IF(AND(ISNUMBER($M43),OR($M43<QC_BD_MIN,$M43>QC_BD_MAX)),"Bulk density outside the plausible range for a mineral grassland soil. ","")&IF(AND(ISNUMBER($N43),$N43>QC_CARBON_PCT_MAX),"Organic carbon above the QC ceiling — check units, and whether this is an organic horizon. ","")&IF(AND(ISNUMBER($J43),$J43<QC_RECOVERY_MIN),"Recovered less than the QC minimum of the depth driven — the increments may not sit where you think. Do NOT stretch them back out. ","")&IF(AND(ISNUMBER($K43),$K43>0,$L43="Fine earth / total volume"),"Coarse fragments recorded and the lab basis already accounts for them — no further correction applied, which is correct. ","")) | U43: =IF($B43="",0,IF(COUNTIFS($B$5:$B43,$B43)=1,1,0)) -> 0
F44: =IF(OR($D44="",$E44=""),"",$E44-$D44) | J44: =IF(OR(NOT(ISNUMBER($H44)),NOT(ISNUMBER($I44)),$H44=0),"",$I44/$H44) | O44: =IF(NOT(ISNUMBER($M44)),"",IF($L44="Fine earth / fine-earth volume",$M44*(1-IF(ISNUMBER($K44),$K44,0)/100),$M44)) | P44: =IF(OR(NOT(ISNUMBER($O44)),NOT(ISNUMBER($N44)),NOT(ISNUMBER($F44))),"",$O44*($N44/100)*$F44*10) | Q44: =IF(OR(NOT(ISNUMBER($D44)),NOT(ISNUMBER($E44))),"",MAX(0,MIN($E44,SOIL_REPORTING_DEPTH_CM)-MIN($D44,SOIL_REPORTING_DEPTH_CM))) | R44: =IF(OR(NOT(ISNUMBER($O44)),NOT(ISNUMBER($N44)),NOT(ISNUMBER($Q44))),"",$O44*($N44/100)*$Q44*10) | S44: =IF(AND($A44="",$B44="",$D44=""),"",IF(AND($A44<>"",COUNTIF('1. Plot & Site Log'!$A$5:$A$64,$A44)=0),"Plot ID not in the Plot & Site Log. ","")&IF(AND(ISNUMBER($D44),ISNUMBER($E44),$E44<=$D44),"Bottom depth is not below top depth. ","")&IF($L44="Not confirmed","Bulk-density basis not confirmed with the lab — the coarse-fragment correction may be wrong or doubled. ","")&IF(LAB_BULK_DENSITY_BASIS="Not confirmed","No lab bulk-density basis is on file in Settings (LAB_BULK_DENSITY_BASIS), so nothing checks this row. ","")&IF(AND($L44<>"",LAB_BULK_DENSITY_BASIS<>"Not confirmed",$L44<>LAB_BULK_DENSITY_BASIS),"This row's bulk-density basis disagrees with the lab method on file. One of "&"the two is wrong, and the coarse-fragment correction follows the row. ","")&IF(AND(ISNUMBER($M44),OR($M44<QC_BD_MIN,$M44>QC_BD_MAX)),"Bulk density outside the plausible range for a mineral grassland soil. ","")&IF(AND(ISNUMBER($N44),$N44>QC_CARBON_PCT_MAX),"Organic carbon above the QC ceiling — check units, and whether this is an organic horizon. ","")&IF(AND(ISNUMBER($J44),$J44<QC_RECOVERY_MIN),"Recovered less than the QC minimum of the depth driven — the increments may not sit where you think. Do NOT stretch them back out. ","")&IF(AND(ISNUMBER($K44),$K44>0,$L44="Fine earth / total volume"),"Coarse fragments recorded and the lab basis already accounts for them — no further correction applied, which is correct. ","")) | U44: =IF($B44="",0,IF(COUNTIFS($B$5:$B44,$B44)=1,1,0)) -> 0
F45: =IF(OR($D45="",$E45=""),"",$E45-$D45) | J45: =IF(OR(NOT(ISNUMBER($H45)),NOT(ISNUMBER($I45)),$H45=0),"",$I45/$H45) | O45: =IF(NOT(ISNUMBER($M45)),"",IF($L45="Fine earth / fine-earth volume",$M45*(1-IF(ISNUMBER($K45),$K45,0)/100),$M45)) | P45: =IF(OR(NOT(ISNUMBER($O45)),NOT(ISNUMBER($N45)),NOT(ISNUMBER($F45))),"",$O45*($N45/100)*$F45*10) | Q45: =IF(OR(NOT(ISNUMBER($D45)),NOT(ISNUMBER($E45))),"",MAX(0,MIN($E45,SOIL_REPORTING_DEPTH_CM)-MIN($D45,SOIL_REPORTING_DEPTH_CM))) | R45: =IF(OR(NOT(ISNUMBER($O45)),NOT(ISNUMBER($N45)),NOT(ISNUMBER($Q45))),"",$O45*($N45/100)*$Q45*10) | S45: =IF(AND($A45="",$B45="",$D45=""),"",IF(AND($A45<>"",COUNTIF('1. Plot & Site Log'!$A$5:$A$64,$A45)=0),"Plot ID not in the Plot & Site Log. ","")&IF(AND(ISNUMBER($D45),ISNUMBER($E45),$E45<=$D45),"Bottom depth is not below top depth. ","")&IF($L45="Not confirmed","Bulk-density basis not confirmed with the lab — the coarse-fragment correction may be wrong or doubled. ","")&IF(LAB_BULK_DENSITY_BASIS="Not confirmed","No lab bulk-density basis is on file in Settings (LAB_BULK_DENSITY_BASIS), so nothing checks this row. ","")&IF(AND($L45<>"",LAB_BULK_DENSITY_BASIS<>"Not confirmed",$L45<>LAB_BULK_DENSITY_BASIS),"This row's bulk-density basis disagrees with the lab method on file. One of "&"the two is wrong, and the coarse-fragment correction follows the row. ","")&IF(AND(ISNUMBER($M45),OR($M45<QC_BD_MIN,$M45>QC_BD_MAX)),"Bulk density outside the plausible range for a mineral grassland soil. ","")&IF(AND(ISNUMBER($N45),$N45>QC_CARBON_PCT_MAX),"Organic carbon above the QC ceiling — check units, and whether this is an organic horizon. ","")&IF(AND(ISNUMBER($J45),$J45<QC_RECOVERY_MIN),"Recovered less than the QC minimum of the depth driven — the increments may not sit where you think. Do NOT stretch them back out. ","")&IF(AND(ISNUMBER($K45),$K45>0,$L45="Fine earth / total volume"),"Coarse fragments recorded and the lab basis already accounts for them — no further correction applied, which is correct. ","")) | U45: =IF($B45="",0,IF(COUNTIFS($B$5:$B45,$B45)=1,1,0)) -> 0
F46: =IF(OR($D46="",$E46=""),"",$E46-$D46) | J46: =IF(OR(NOT(ISNUMBER($H46)),NOT(ISNUMBER($I46)),$H46=0),"",$I46/$H46) | O46: =IF(NOT(ISNUMBER($M46)),"",IF($L46="Fine earth / fine-earth volume",$M46*(1-IF(ISNUMBER($K46),$K46,0)/100),$M46)) | P46: =IF(OR(NOT(ISNUMBER($O46)),NOT(ISNUMBER($N46)),NOT(ISNUMBER($F46))),"",$O46*($N46/100)*$F46*10) | Q46: =IF(OR(NOT(ISNUMBER($D46)),NOT(ISNUMBER($E46))),"",MAX(0,MIN($E46,SOIL_REPORTING_DEPTH_CM)-MIN($D46,SOIL_REPORTING_DEPTH_CM))) | R46: =IF(OR(NOT(ISNUMBER($O46)),NOT(ISNUMBER($N46)),NOT(ISNUMBER($Q46))),"",$O46*($N46/100)*$Q46*10) | S46: =IF(AND($A46="",$B46="",$D46=""),"",IF(AND($A46<>"",COUNTIF('1. Plot & Site Log'!$A$5:$A$64,$A46)=0),"Plot ID not in the Plot & Site Log. ","")&IF(AND(ISNUMBER($D46),ISNUMBER($E46),$E46<=$D46),"Bottom depth is not below top depth. ","")&IF($L46="Not confirmed","Bulk-density basis not confirmed with the lab — the coarse-fragment correction may be wrong or doubled. ","")&IF(LAB_BULK_DENSITY_BASIS="Not confirmed","No lab bulk-density basis is on file in Settings (LAB_BULK_DENSITY_BASIS), so nothing checks this row. ","")&IF(AND($L46<>"",LAB_BULK_DENSITY_BASIS<>"Not confirmed",$L46<>LAB_BULK_DENSITY_BASIS),"This row's bulk-density basis disagrees with the lab method on file. One of "&"the two is wrong, and the coarse-fragment correction follows the row. ","")&IF(AND(ISNUMBER($M46),OR($M46<QC_BD_MIN,$M46>QC_BD_MAX)),"Bulk density outside the plausible range for a mineral grassland soil. ","")&IF(AND(ISNUMBER($N46),$N46>QC_CARBON_PCT_MAX),"Organic carbon above the QC ceiling — check units, and whether this is an organic horizon. ","")&IF(AND(ISNUMBER($J46),$J46<QC_RECOVERY_MIN),"Recovered less than the QC minimum of the depth driven — the increments may not sit where you think. Do NOT stretch them back out. ","")&IF(AND(ISNUMBER($K46),$K46>0,$L46="Fine earth / total volume"),"Coarse fragments recorded and the lab basis already accounts for them — no further correction applied, which is correct. ","")) | U46: =IF($B46="",0,IF(COUNTIFS($B$5:$B46,$B46)=1,1,0)) -> 0
F47: =IF(OR($D47="",$E47=""),"",$E47-$D47) | J47: =IF(OR(NOT(ISNUMBER($H47)),NOT(ISNUMBER($I47)),$H47=0),"",$I47/$H47) | O47: =IF(NOT(ISNUMBER($M47)),"",IF($L47="Fine earth / fine-earth volume",$M47*(1-IF(ISNUMBER($K47),$K47,0)/100),$M47)) | P47: =IF(OR(NOT(ISNUMBER($O47)),NOT(ISNUMBER($N47)),NOT(ISNUMBER($F47))),"",$O47*($N47/100)*$F47*10) | Q47: =IF(OR(NOT(ISNUMBER($D47)),NOT(ISNUMBER($E47))),"",MAX(0,MIN($E47,SOIL_REPORTING_DEPTH_CM)-MIN($D47,SOIL_REPORTING_DEPTH_CM))) | R47: =IF(OR(NOT(ISNUMBER($O47)),NOT(ISNUMBER($N47)),NOT(ISNUMBER($Q47))),"",$O47*($N47/100)*$Q47*10) | S47: =IF(AND($A47="",$B47="",$D47=""),"",IF(AND($A47<>"",COUNTIF('1. Plot & Site Log'!$A$5:$A$64,$A47)=0),"Plot ID not in the Plot & Site Log. ","")&IF(AND(ISNUMBER($D47),ISNUMBER($E47),$E47<=$D47),"Bottom depth is not below top depth. ","")&IF($L47="Not confirmed","Bulk-density basis not confirmed with the lab — the coarse-fragment correction may be wrong or doubled. ","")&IF(LAB_BULK_DENSITY_BASIS="Not confirmed","No lab bulk-density basis is on file in Settings (LAB_BULK_DENSITY_BASIS), so nothing checks this row. ","")&IF(AND($L47<>"",LAB_BULK_DENSITY_BASIS<>"Not confirmed",$L47<>LAB_BULK_DENSITY_BASIS),"This row's bulk-density basis disagrees with the lab method on file. One of "&"the two is wrong, and the coarse-fragment correction follows the row. ","")&IF(AND(ISNUMBER($M47),OR($M47<QC_BD_MIN,$M47>QC_BD_MAX)),"Bulk density outside the plausible range for a mineral grassland soil. ","")&IF(AND(ISNUMBER($N47),$N47>QC_CARBON_PCT_MAX),"Organic carbon above the QC ceiling — check units, and whether this is an organic horizon. ","")&IF(AND(ISNUMBER($J47),$J47<QC_RECOVERY_MIN),"Recovered less than the QC minimum of the depth driven — the increments may not sit where you think. Do NOT stretch them back out. ","")&IF(AND(ISNUMBER($K47),$K47>0,$L47="Fine earth / total volume"),"Coarse fragments recorded and the lab basis already accounts for them — no further correction applied, which is correct. ","")) | U47: =IF($B47="",0,IF(COUNTIFS($B$5:$B47,$B47)=1,1,0)) -> 0
