Workbook
Name CARBON_FRACTION_OM: '7. Settings'!$B$5
Name OM_FACTOR_IS_LOCAL: '7. Settings'!$B$6
Name CO2E_FACTOR: '7. Settings'!$B$7
Name REFERENCE_DEPTH_CM: '7. Settings'!$B$8
Name PEATLAND_MIN_DEPTH_CM: '7. Settings'!$B$9
Name PLOT_AREA_M2: '7. Settings'!$B$10
Name TARGET_MARGIN: '7. Settings'!$B$11
Name TARGET_CONFIDENCE: '7. Settings'!$B$12
Name QC_BD_MIN: '7. Settings'!$B$13
Name QC_BD_MAX: '7. Settings'!$B$14
Name QC_CARBON_PCT_MAX: '7. Settings'!$B$15
Name QC_RECOVERY_MIN: '7. Settings'!$B$16
Name LORCA_MIN: '7. Settings'!$B$17
Name LORCA_MAX: '7. Settings'!$B$18

Sheet 0. Instructions
A1: WETLAND CARBON CALCULATOR
B2: WWF-Canada Carbon Measurement · Wetland Carbon Workshop
A4: What this workbook does | B4: Turns peat core measurements into a carbon stock in kg C/m², scales cores to plots, sites and your whole study area, and — if you have dated the core — converts the same carbon into accumulation rates. It follows 'Measuring Carbon in Peat Soils' (WWF-Canada, 2024), with the additions noted at the bottom of this sheet.
A6: COLOUR KEY
A7: Yellow | B7: TYPE HERE — field measurements you record.
A8: Blue | B8: TYPE HERE — lab results, once they come back.
A9: Grey | B9: Calculated for you. Do not type in grey cells.
A10: Green | B10: Summary output.
A11: Red | B11: A quality-control flag. Read it before trusting the row.
A13: ORDER OF WORK
A14: 1 | B14: Fill '1. Plot & Site Log' FIRST — one row per plot. Everything joins to it on Plot ID.
A15: 2 | B15: Fill '2. Core Log' — one row per core. Everything in the peat sheet joins to it on Core ID.
A16: 3 | B16: Fill '3. Peat Data' — one row per section, as the core is sectioned.
A17: 4 | B17: Add lab results (blue columns) to '3. Peat Data' when they return.
A18: 5 | B18: OPTIONAL: if the core has been dated, fill '4. Chronology' to get accumulation rates.
A19: 6 | B19: Read '5. Plot Summary' and '6. Site Summary'. Both calculate themselves.
A21: ⚠ IDs MUST MATCH | B21: Plot ID joins the Core Log to the Plot & Site Log; Core ID joins the Peat Data and the Chronology to the Core Log. A mismatch means that row's carbon never reaches the summary. Every sheet has a QC flags column that tells you when this happens.
A23: UNITS
A24: Depths | B24: centimetres (cm), measured down from the peat surface
A25: Bulk density | B25: g/cm³ — oven-dry mass ÷ sample volume (see the basis note on '3. Peat Data')
A26: Carbon content | B26: per cent of dry mass (%)
A27: Carbon stock | B27: kg C/m² at core, plot and site level; kg C for totals
A28: Accumulation rate | B28: g C/m²/yr — note the unit change: 1 kg C/m² per 1,000 yr = 1 g C/m²/yr
A29: Age | B29: years before the year the core was taken
A31: TWO STOCK NUMBERS, AND WHY
A32: Full profile | B32: Stock over the whole peat profile, to the mineral contact. THIS IS THE HEADLINE NUMBER — it is what the peatland actually holds, and what the peatland literature reports.
A33: To reference depth | B33: Stock integrated to a fixed depth (100 cm by default, set on '7. Settings'). Reported alongside so your numbers stay comparable with projects that sampled to a standard depth. Cores that stop short of it are flagged.
A34: Why both | B34: Bansal et al. (2023) found 65% of wetland organic carbon sat between 30 and 120 cm. Report only a shallow fixed depth and you miss most of the store; report only full profiles and cores of different depths cannot be compared. So the workbook gives you both.
A36: WHAT'S BEYOND THE PRINTED GUIDE
A37: Uncertainty | B37: Site means carry a standard deviation, standard error and confidence interval, checked against the precision target you set in Part 2. The guide's Eq 1–8 give point estimates only.
A38: Eq 5 correction | B38: The guide's printed Eq 5 has its right-hand side in g/cm² and its left-hand side in kg/m². This workbook uses the correct form — summing the kg/m² core values — which is also what the guide's own example spreadsheet does.
A39: Carbon fraction | B39: Settable on '7. Settings', defaulting to the guide's 0.5. See 'R1. Reference' for why that is a convention rather than a constant.
A40: Accumulation rates | B40: The guide raises them in its introduction and its glossary but gives no method. '4. Chronology' supplies one — see Part 5 of the workshop.

Sheet 1. Plot & Site Log
A1: PLOT & SITE LOG
A2: ONE ROW PER PLOT. Fill this in first — everything joins to it on Plot ID. Water table depth is measured DOWN from the peat surface, so a positive number means the water table sits below the surface and a negative number means standing water above it. Microform matters: hollows accumulate more organic matter than hummocks, so recording it lets you stratify later.
A4: Plot ID | B4: Site ID | C4: Study area | D4: Date | E4: Location | F4: Latitude | G4: Longitude | H4: GNSS accuracy (m) | I4: Datum | J4: Elevation (m) | K4: Wetland type | L4: Microform | M4: Vegetation zone | N4: Water table depth (cm) | O4: Plot area (m²) | P4: Notes

Sheet 2. Core Log
A1: CORE LOG
A2: ONE ROW PER CORE. A Russian (Macaulay) corer takes 50 cm at a time, so a 2 m core is four drives — log the core once here and its sections on the next sheet. BORE DEPTH is how deep the corer went; CORE LENGTH RECOVERED is what came back. For a side-filling corer these should be nearly equal: a shortfall means the chamber did not fill, NOT that the peat compressed.
A4: Core ID | B4: Plot ID | C4: Latitude | D4: Longitude | E4: Coring date | F4: Drives taken | G4: Bore depth (cm) | H4: Core length recovered (cm) | I4: Surface compaction (cm) | J4: Recovery ratio | K4: Depth to mineral contact (cm) | L4: Reached mineral contact? | M4: von Post at base | N4: Chamber length (cm) | O4: Chamber diameter (cm) | P4: Photo series? | Q4: Deepest section logged (cm) | R4: Stock, full profile (kg C/m²) | S4: Stock to reference depth (kg C/m²) | T4: Reaches reference depth? | U4: QC flags | V4: Notes
J5: =IF(OR($G5="",$H5="",$G5=0),"",$H5/$G5) | Q5: =IF($A5="","",IF(SUMPRODUCT(MAX(('3. Peat Data'!$B$5:$B$604=$A5)*'3. Peat Data'!$F$5:$F$604))=0,"",SUMPRODUCT(MAX(('3. Peat Data'!$B$5:$B$604=$A5)*'3. Peat Data'!$F$5:$F$604)))) | R5: =IF($A5="","",IFERROR(SUMIFS('3. Peat Data'!$P$5:$P$604,'3. Peat Data'!$B$5:$B$604,$A5),"")) | S5: =IF($A5="","",IFERROR(SUMIFS('3. Peat Data'!$Q$5:$Q$604,'3. Peat Data'!$B$5:$B$604,$A5),"")) | T5: =IF(NOT(ISNUMBER($Q5)),"",IF($Q5>=REFERENCE_DEPTH_CM,"Yes","No")) | U5: =IF($A5="","",IF(AND($B5<>"",COUNTIF('1. Plot & Site Log'!$A$5:$A$64,$B5)=0),"Plot ID not in Plot & Site Log. ","")&IF(NOT(ISNUMBER($Q5)),"No peat sections logged for this core. ","")&IF($T5="No","Core stops short of the reference depth, so its reference-depth stock is an underestimate. Its full-profile stock is still valid. ","")&IF($L5="No","Core did not reach the mineral contact — the full-profile stock is a MINIMUM, not the whole store. ","")&IF(AND(ISNUMBER($K5),$K5<PEATLAND_MIN_DEPTH_CM),"Organic depth under "&PEATLAND_MIN_DEPTH_CM&" cm: by the guide's definition this is not peatland. Report it, but say so. ","")&IF(AND(ISNUMBER($J5),$J5<QC_RECOVERY_MIN),"Recovered only "&TEXT($J5,"0%")&" of the bore depth — the chamber probably did not fill completely. Material is missing, which is not the same as compaction. ","")&IF(AND(ISNUMBER($J5),$J5>1.05),"Recovered more than the bore depth — check the two measurements. ","")&IF(AND(ISNUMBER($I5),$I5>2),"Surface compaction of "&$I5&" cm: depths in this core sit shallower than in the ground, so depth-limited stock is biased. Full-profile stock is unaffected. ",""))
J6: =IF(OR($G6="",$H6="",$G6=0),"",$H6/$G6) | Q6: =IF($A6="","",IF(SUMPRODUCT(MAX(('3. Peat Data'!$B$5:$B$604=$A6)*'3. Peat Data'!$F$5:$F$604))=0,"",SUMPRODUCT(MAX(('3. Peat Data'!$B$5:$B$604=$A6)*'3. Peat Data'!$F$5:$F$604)))) | R6: =IF($A6="","",IFERROR(SUMIFS('3. Peat Data'!$P$5:$P$604,'3. Peat Data'!$B$5:$B$604,$A6),"")) | S6: =IF($A6="","",IFERROR(SUMIFS('3. Peat Data'!$Q$5:$Q$604,'3. Peat Data'!$B$5:$B$604,$A6),"")) | T6: =IF(NOT(ISNUMBER($Q6)),"",IF($Q6>=REFERENCE_DEPTH_CM,"Yes","No")) | U6: =IF($A6="","",IF(AND($B6<>"",COUNTIF('1. Plot & Site Log'!$A$5:$A$64,$B6)=0),"Plot ID not in Plot & Site Log. ","")&IF(NOT(ISNUMBER($Q6)),"No peat sections logged for this core. ","")&IF($T6="No","Core stops short of the reference depth, so its reference-depth stock is an underestimate. Its full-profile stock is still valid. ","")&IF($L6="No","Core did not reach the mineral contact — the full-profile stock is a MINIMUM, not the whole store. ","")&IF(AND(ISNUMBER($K6),$K6<PEATLAND_MIN_DEPTH_CM),"Organic depth under "&PEATLAND_MIN_DEPTH_CM&" cm: by the guide's definition this is not peatland. Report it, but say so. ","")&IF(AND(ISNUMBER($J6),$J6<QC_RECOVERY_MIN),"Recovered only "&TEXT($J6,"0%")&" of the bore depth — the chamber probably did not fill completely. Material is missing, which is not the same as compaction. ","")&IF(AND(ISNUMBER($J6),$J6>1.05),"Recovered more than the bore depth — check the two measurements. ","")&IF(AND(ISNUMBER($I6),$I6>2),"Surface compaction of "&$I6&" cm: depths in this core sit shallower than in the ground, so depth-limited stock is biased. Full-profile stock is unaffected. ",""))
J7: =IF(OR($G7="",$H7="",$G7=0),"",$H7/$G7) | Q7: =IF($A7="","",IF(SUMPRODUCT(MAX(('3. Peat Data'!$B$5:$B$604=$A7)*'3. Peat Data'!$F$5:$F$604))=0,"",SUMPRODUCT(MAX(('3. Peat Data'!$B$5:$B$604=$A7)*'3. Peat Data'!$F$5:$F$604)))) | R7: =IF($A7="","",IFERROR(SUMIFS('3. Peat Data'!$P$5:$P$604,'3. Peat Data'!$B$5:$B$604,$A7),"")) | S7: =IF($A7="","",IFERROR(SUMIFS('3. Peat Data'!$Q$5:$Q$604,'3. Peat Data'!$B$5:$B$604,$A7),"")) | T7: =IF(NOT(ISNUMBER($Q7)),"",IF($Q7>=REFERENCE_DEPTH_CM,"Yes","No")) | U7: =IF($A7="","",IF(AND($B7<>"",COUNTIF('1. Plot & Site Log'!$A$5:$A$64,$B7)=0),"Plot ID not in Plot & Site Log. ","")&IF(NOT(ISNUMBER($Q7)),"No peat sections logged for this core. ","")&IF($T7="No","Core stops short of the reference depth, so its reference-depth stock is an underestimate. Its full-profile stock is still valid. ","")&IF($L7="No","Core did not reach the mineral contact — the full-profile stock is a MINIMUM, not the whole store. ","")&IF(AND(ISNUMBER($K7),$K7<PEATLAND_MIN_DEPTH_CM),"Organic depth under "&PEATLAND_MIN_DEPTH_CM&" cm: by the guide's definition this is not peatland. Report it, but say so. ","")&IF(AND(ISNUMBER($J7),$J7<QC_RECOVERY_MIN),"Recovered only "&TEXT($J7,"0%")&" of the bore depth — the chamber probably did not fill completely. Material is missing, which is not the same as compaction. ","")&IF(AND(ISNUMBER($J7),$J7>1.05),"Recovered more than the bore depth — check the two measurements. ","")&IF(AND(ISNUMBER($I7),$I7>2),"Surface compaction of "&$I7&" cm: depths in this core sit shallower than in the ground, so depth-limited stock is biased. Full-profile stock is unaffected. ",""))
J8: =IF(OR($G8="",$H8="",$G8=0),"",$H8/$G8) | Q8: =IF($A8="","",IF(SUMPRODUCT(MAX(('3. Peat Data'!$B$5:$B$604=$A8)*'3. Peat Data'!$F$5:$F$604))=0,"",SUMPRODUCT(MAX(('3. Peat Data'!$B$5:$B$604=$A8)*'3. Peat Data'!$F$5:$F$604)))) | R8: =IF($A8="","",IFERROR(SUMIFS('3. Peat Data'!$P$5:$P$604,'3. Peat Data'!$B$5:$B$604,$A8),"")) | S8: =IF($A8="","",IFERROR(SUMIFS('3. Peat Data'!$Q$5:$Q$604,'3. Peat Data'!$B$5:$B$604,$A8),"")) | T8: =IF(NOT(ISNUMBER($Q8)),"",IF($Q8>=REFERENCE_DEPTH_CM,"Yes","No")) | U8: =IF($A8="","",IF(AND($B8<>"",COUNTIF('1. Plot & Site Log'!$A$5:$A$64,$B8)=0),"Plot ID not in Plot & Site Log. ","")&IF(NOT(ISNUMBER($Q8)),"No peat sections logged for this core. ","")&IF($T8="No","Core stops short of the reference depth, so its reference-depth stock is an underestimate. Its full-profile stock is still valid. ","")&IF($L8="No","Core did not reach the mineral contact — the full-profile stock is a MINIMUM, not the whole store. ","")&IF(AND(ISNUMBER($K8),$K8<PEATLAND_MIN_DEPTH_CM),"Organic depth under "&PEATLAND_MIN_DEPTH_CM&" cm: by the guide's definition this is not peatland. Report it, but say so. ","")&IF(AND(ISNUMBER($J8),$J8<QC_RECOVERY_MIN),"Recovered only "&TEXT($J8,"0%")&" of the bore depth — the chamber probably did not fill completely. Material is missing, which is not the same as compaction. ","")&IF(AND(ISNUMBER($J8),$J8>1.05),"Recovered more than the bore depth — check the two measurements. ","")&IF(AND(ISNUMBER($I8),$I8>2),"Surface compaction of "&$I8&" cm: depths in this core sit shallower than in the ground, so depth-limited stock is biased. Full-profile stock is unaffected. ",""))
J9: =IF(OR($G9="",$H9="",$G9=0),"",$H9/$G9) | Q9: =IF($A9="","",IF(SUMPRODUCT(MAX(('3. Peat Data'!$B$5:$B$604=$A9)*'3. Peat Data'!$F$5:$F$604))=0,"",SUMPRODUCT(MAX(('3. Peat Data'!$B$5:$B$604=$A9)*'3. Peat Data'!$F$5:$F$604)))) | R9: =IF($A9="","",IFERROR(SUMIFS('3. Peat Data'!$P$5:$P$604,'3. Peat Data'!$B$5:$B$604,$A9),"")) | S9: =IF($A9="","",IFERROR(SUMIFS('3. Peat Data'!$Q$5:$Q$604,'3. Peat Data'!$B$5:$B$604,$A9),"")) | T9: =IF(NOT(ISNUMBER($Q9)),"",IF($Q9>=REFERENCE_DEPTH_CM,"Yes","No")) | U9: =IF($A9="","",IF(AND($B9<>"",COUNTIF('1. Plot & Site Log'!$A$5:$A$64,$B9)=0),"Plot ID not in Plot & Site Log. ","")&IF(NOT(ISNUMBER($Q9)),"No peat sections logged for this core. ","")&IF($T9="No","Core stops short of the reference depth, so its reference-depth stock is an underestimate. Its full-profile stock is still valid. ","")&IF($L9="No","Core did not reach the mineral contact — the full-profile stock is a MINIMUM, not the whole store. ","")&IF(AND(ISNUMBER($K9),$K9<PEATLAND_MIN_DEPTH_CM),"Organic depth under "&PEATLAND_MIN_DEPTH_CM&" cm: by the guide's definition this is not peatland. Report it, but say so. ","")&IF(AND(ISNUMBER($J9),$J9<QC_RECOVERY_MIN),"Recovered only "&TEXT($J9,"0%")&" of the bore depth — the chamber probably did not fill completely. Material is missing, which is not the same as compaction. ","")&IF(AND(ISNUMBER($J9),$J9>1.05),"Recovered more than the bore depth — check the two measurements. ","")&IF(AND(ISNUMBER($I9),$I9>2),"Surface compaction of "&$I9&" cm: depths in this core sit shallower than in the ground, so depth-limited stock is biased. Full-profile stock is unaffected. ",""))
J10: =IF(OR($G10="",$H10="",$G10=0),"",$H10/$G10) | Q10: =IF($A10="","",IF(SUMPRODUCT(MAX(('3. Peat Data'!$B$5:$B$604=$A10)*'3. Peat Data'!$F$5:$F$604))=0,"",SUMPRODUCT(MAX(('3. Peat Data'!$B$5:$B$604=$A10)*'3. Peat Data'!$F$5:$F$604)))) | R10: =IF($A10="","",IFERROR(SUMIFS('3. Peat Data'!$P$5:$P$604,'3. Peat Data'!$B$5:$B$604,$A10),"")) | S10: =IF($A10="","",IFERROR(SUMIFS('3. Peat Data'!$Q$5:$Q$604,'3. Peat Data'!$B$5:$B$604,$A10),"")) | T10: =IF(NOT(ISNUMBER($Q10)),"",IF($Q10>=REFERENCE_DEPTH_CM,"Yes","No")) | U10: =IF($A10="","",IF(AND($B10<>"",COUNTIF('1. Plot & Site Log'!$A$5:$A$64,$B10)=0),"Plot ID not in Plot & Site Log. ","")&IF(NOT(ISNUMBER($Q10)),"No peat sections logged for this core. ","")&IF($T10="No","Core stops short of the reference depth, so its reference-depth stock is an underestimate. Its full-profile stock is still valid. ","")&IF($L10="No","Core did not reach the mineral contact — the full-profile stock is a MINIMUM, not the whole store. ","")&IF(AND(ISNUMBER($K10),$K10<PEATLAND_MIN_DEPTH_CM),"Organic depth under "&PEATLAND_MIN_DEPTH_CM&" cm: by the guide's definition this is not peatland. Report it, but say so. ","")&IF(AND(ISNUMBER($J10),$J10<QC_RECOVERY_MIN),"Recovered only "&TEXT($J10,"0%")&" of the bore depth — the chamber probably did not fill completely. Material is missing, which is not the same as compaction. ","")&IF(AND(ISNUMBER($J10),$J10>1.05),"Recovered more than the bore depth — check the two measurements. ","")&IF(AND(ISNUMBER($I10),$I10>2),"Surface compaction of "&$I10&" cm: depths in this core sit shallower than in the ground, so depth-limited stock is biased. Full-profile stock is unaffected. ",""))
J11: =IF(OR($G11="",$H11="",$G11=0),"",$H11/$G11) | Q11: =IF($A11="","",IF(SUMPRODUCT(MAX(('3. Peat Data'!$B$5:$B$604=$A11)*'3. Peat Data'!$F$5:$F$604))=0,"",SUMPRODUCT(MAX(('3. Peat Data'!$B$5:$B$604=$A11)*'3. Peat Data'!$F$5:$F$604)))) | R11: =IF($A11="","",IFERROR(SUMIFS('3. Peat Data'!$P$5:$P$604,'3. Peat Data'!$B$5:$B$604,$A11),"")) | S11: =IF($A11="","",IFERROR(SUMIFS('3. Peat Data'!$Q$5:$Q$604,'3. Peat Data'!$B$5:$B$604,$A11),"")) | T11: =IF(NOT(ISNUMBER($Q11)),"",IF($Q11>=REFERENCE_DEPTH_CM,"Yes","No")) | U11: =IF($A11="","",IF(AND($B11<>"",COUNTIF('1. Plot & Site Log'!$A$5:$A$64,$B11)=0),"Plot ID not in Plot & Site Log. ","")&IF(NOT(ISNUMBER($Q11)),"No peat sections logged for this core. ","")&IF($T11="No","Core stops short of the reference depth, so its reference-depth stock is an underestimate. Its full-profile stock is still valid. ","")&IF($L11="No","Core did not reach the mineral contact — the full-profile stock is a MINIMUM, not the whole store. ","")&IF(AND(ISNUMBER($K11),$K11<PEATLAND_MIN_DEPTH_CM),"Organic depth under "&PEATLAND_MIN_DEPTH_CM&" cm: by the guide's definition this is not peatland. Report it, but say so. ","")&IF(AND(ISNUMBER($J11),$J11<QC_RECOVERY_MIN),"Recovered only "&TEXT($J11,"0%")&" of the bore depth — the chamber probably did not fill completely. Material is missing, which is not the same as compaction. ","")&IF(AND(ISNUMBER($J11),$J11>1.05),"Recovered more than the bore depth — check the two measurements. ","")&IF(AND(ISNUMBER($I11),$I11>2),"Surface compaction of "&$I11&" cm: depths in this core sit shallower than in the ground, so depth-limited stock is biased. Full-profile stock is unaffected. ",""))
J12: =IF(OR($G12="",$H12="",$G12=0),"",$H12/$G12) | Q12: =IF($A12="","",IF(SUMPRODUCT(MAX(('3. Peat Data'!$B$5:$B$604=$A12)*'3. Peat Data'!$F$5:$F$604))=0,"",SUMPRODUCT(MAX(('3. Peat Data'!$B$5:$B$604=$A12)*'3. Peat Data'!$F$5:$F$604)))) | R12: =IF($A12="","",IFERROR(SUMIFS('3. Peat Data'!$P$5:$P$604,'3. Peat Data'!$B$5:$B$604,$A12),"")) | S12: =IF($A12="","",IFERROR(SUMIFS('3. Peat Data'!$Q$5:$Q$604,'3. Peat Data'!$B$5:$B$604,$A12),"")) | T12: =IF(NOT(ISNUMBER($Q12)),"",IF($Q12>=REFERENCE_DEPTH_CM,"Yes","No")) | U12: =IF($A12="","",IF(AND($B12<>"",COUNTIF('1. Plot & Site Log'!$A$5:$A$64,$B12)=0),"Plot ID not in Plot & Site Log. ","")&IF(NOT(ISNUMBER($Q12)),"No peat sections logged for this core. ","")&IF($T12="No","Core stops short of the reference depth, so its reference-depth stock is an underestimate. Its full-profile stock is still valid. ","")&IF($L12="No","Core did not reach the mineral contact — the full-profile stock is a MINIMUM, not the whole store. ","")&IF(AND(ISNUMBER($K12),$K12<PEATLAND_MIN_DEPTH_CM),"Organic depth under "&PEATLAND_MIN_DEPTH_CM&" cm: by the guide's definition this is not peatland. Report it, but say so. ","")&IF(AND(ISNUMBER($J12),$J12<QC_RECOVERY_MIN),"Recovered only "&TEXT($J12,"0%")&" of the bore depth — the chamber probably did not fill completely. Material is missing, which is not the same as compaction. ","")&IF(AND(ISNUMBER($J12),$J12>1.05),"Recovered more than the bore depth — check the two measurements. ","")&IF(AND(ISNUMBER($I12),$I12>2),"Surface compaction of "&$I12&" cm: depths in this core sit shallower than in the ground, so depth-limited stock is biased. Full-profile stock is unaffected. ",""))
J13: =IF(OR($G13="",$H13="",$G13=0),"",$H13/$G13) | Q13: =IF($A13="","",IF(SUMPRODUCT(MAX(('3. Peat Data'!$B$5:$B$604=$A13)*'3. Peat Data'!$F$5:$F$604))=0,"",SUMPRODUCT(MAX(('3. Peat Data'!$B$5:$B$604=$A13)*'3. Peat Data'!$F$5:$F$604)))) | R13: =IF($A13="","",IFERROR(SUMIFS('3. Peat Data'!$P$5:$P$604,'3. Peat Data'!$B$5:$B$604,$A13),"")) | S13: =IF($A13="","",IFERROR(SUMIFS('3. Peat Data'!$Q$5:$Q$604,'3. Peat Data'!$B$5:$B$604,$A13),"")) | T13: =IF(NOT(ISNUMBER($Q13)),"",IF($Q13>=REFERENCE_DEPTH_CM,"Yes","No")) | U13: =IF($A13="","",IF(AND($B13<>"",COUNTIF('1. Plot & Site Log'!$A$5:$A$64,$B13)=0),"Plot ID not in Plot & Site Log. ","")&IF(NOT(ISNUMBER($Q13)),"No peat sections logged for this core. ","")&IF($T13="No","Core stops short of the reference depth, so its reference-depth stock is an underestimate. Its full-profile stock is still valid. ","")&IF($L13="No","Core did not reach the mineral contact — the full-profile stock is a MINIMUM, not the whole store. ","")&IF(AND(ISNUMBER($K13),$K13<PEATLAND_MIN_DEPTH_CM),"Organic depth under "&PEATLAND_MIN_DEPTH_CM&" cm: by the guide's definition this is not peatland. Report it, but say so. ","")&IF(AND(ISNUMBER($J13),$J13<QC_RECOVERY_MIN),"Recovered only "&TEXT($J13,"0%")&" of the bore depth — the chamber probably did not fill completely. Material is missing, which is not the same as compaction. ","")&IF(AND(ISNUMBER($J13),$J13>1.05),"Recovered more than the bore depth — check the two measurements. ","")&IF(AND(ISNUMBER($I13),$I13>2),"Surface compaction of "&$I13&" cm: depths in this core sit shallower than in the ground, so depth-limited stock is biased. Full-profile stock is unaffected. ",""))
J14: =IF(OR($G14="",$H14="",$G14=0),"",$H14/$G14) | Q14: =IF($A14="","",IF(SUMPRODUCT(MAX(('3. Peat Data'!$B$5:$B$604=$A14)*'3. Peat Data'!$F$5:$F$604))=0,"",SUMPRODUCT(MAX(('3. Peat Data'!$B$5:$B$604=$A14)*'3. Peat Data'!$F$5:$F$604)))) | R14: =IF($A14="","",IFERROR(SUMIFS('3. Peat Data'!$P$5:$P$604,'3. Peat Data'!$B$5:$B$604,$A14),"")) | S14: =IF($A14="","",IFERROR(SUMIFS('3. Peat Data'!$Q$5:$Q$604,'3. Peat Data'!$B$5:$B$604,$A14),"")) | T14: =IF(NOT(ISNUMBER($Q14)),"",IF($Q14>=REFERENCE_DEPTH_CM,"Yes","No")) | U14: =IF($A14="","",IF(AND($B14<>"",COUNTIF('1. Plot & Site Log'!$A$5:$A$64,$B14)=0),"Plot ID not in Plot & Site Log. ","")&IF(NOT(ISNUMBER($Q14)),"No peat sections logged for this core. ","")&IF($T14="No","Core stops short of the reference depth, so its reference-depth stock is an underestimate. Its full-profile stock is still valid. ","")&IF($L14="No","Core did not reach the mineral contact — the full-profile stock is a MINIMUM, not the whole store. ","")&IF(AND(ISNUMBER($K14),$K14<PEATLAND_MIN_DEPTH_CM),"Organic depth under "&PEATLAND_MIN_DEPTH_CM&" cm: by the guide's definition this is not peatland. Report it, but say so. ","")&IF(AND(ISNUMBER($J14),$J14<QC_RECOVERY_MIN),"Recovered only "&TEXT($J14,"0%")&" of the bore depth — the chamber probably did not fill completely. Material is missing, which is not the same as compaction. ","")&IF(AND(ISNUMBER($J14),$J14>1.05),"Recovered more than the bore depth — check the two measurements. ","")&IF(AND(ISNUMBER($I14),$I14>2),"Surface compaction of "&$I14&" cm: depths in this core sit shallower than in the ground, so depth-limited stock is biased. Full-profile stock is unaffected. ",""))
J15: =IF(OR($G15="",$H15="",$G15=0),"",$H15/$G15) | Q15: =IF($A15="","",IF(SUMPRODUCT(MAX(('3. Peat Data'!$B$5:$B$604=$A15)*'3. Peat Data'!$F$5:$F$604))=0,"",SUMPRODUCT(MAX(('3. Peat Data'!$B$5:$B$604=$A15)*'3. Peat Data'!$F$5:$F$604)))) | R15: =IF($A15="","",IFERROR(SUMIFS('3. Peat Data'!$P$5:$P$604,'3. Peat Data'!$B$5:$B$604,$A15),"")) | S15: =IF($A15="","",IFERROR(SUMIFS('3. Peat Data'!$Q$5:$Q$604,'3. Peat Data'!$B$5:$B$604,$A15),"")) | T15: =IF(NOT(ISNUMBER($Q15)),"",IF($Q15>=REFERENCE_DEPTH_CM,"Yes","No")) | U15: =IF($A15="","",IF(AND($B15<>"",COUNTIF('1. Plot & Site Log'!$A$5:$A$64,$B15)=0),"Plot ID not in Plot & Site Log. ","")&IF(NOT(ISNUMBER($Q15)),"No peat sections logged for this core. ","")&IF($T15="No","Core stops short of the reference depth, so its reference-depth stock is an underestimate. Its full-profile stock is still valid. ","")&IF($L15="No","Core did not reach the mineral contact — the full-profile stock is a MINIMUM, not the whole store. ","")&IF(AND(ISNUMBER($K15),$K15<PEATLAND_MIN_DEPTH_CM),"Organic depth under "&PEATLAND_MIN_DEPTH_CM&" cm: by the guide's definition this is not peatland. Report it, but say so. ","")&IF(AND(ISNUMBER($J15),$J15<QC_RECOVERY_MIN),"Recovered only "&TEXT($J15,"0%")&" of the bore depth — the chamber probably did not fill completely. Material is missing, which is not the same as compaction. ","")&IF(AND(ISNUMBER($J15),$J15>1.05),"Recovered more than the bore depth — check the two measurements. ","")&IF(AND(ISNUMBER($I15),$I15>2),"Surface compaction of "&$I15&" cm: depths in this core sit shallower than in the ground, so depth-limited stock is biased. Full-profile stock is unaffected. ",""))
J16: =IF(OR($G16="",$H16="",$G16=0),"",$H16/$G16) | Q16: =IF($A16="","",IF(SUMPRODUCT(MAX(('3. Peat Data'!$B$5:$B$604=$A16)*'3. Peat Data'!$F$5:$F$604))=0,"",SUMPRODUCT(MAX(('3. Peat Data'!$B$5:$B$604=$A16)*'3. Peat Data'!$F$5:$F$604)))) | R16: =IF($A16="","",IFERROR(SUMIFS('3. Peat Data'!$P$5:$P$604,'3. Peat Data'!$B$5:$B$604,$A16),"")) | S16: =IF($A16="","",IFERROR(SUMIFS('3. Peat Data'!$Q$5:$Q$604,'3. Peat Data'!$B$5:$B$604,$A16),"")) | T16: =IF(NOT(ISNUMBER($Q16)),"",IF($Q16>=REFERENCE_DEPTH_CM,"Yes","No")) | U16: =IF($A16="","",IF(AND($B16<>"",COUNTIF('1. Plot & Site Log'!$A$5:$A$64,$B16)=0),"Plot ID not in Plot & Site Log. ","")&IF(NOT(ISNUMBER($Q16)),"No peat sections logged for this core. ","")&IF($T16="No","Core stops short of the reference depth, so its reference-depth stock is an underestimate. Its full-profile stock is still valid. ","")&IF($L16="No","Core did not reach the mineral contact — the full-profile stock is a MINIMUM, not the whole store. ","")&IF(AND(ISNUMBER($K16),$K16<PEATLAND_MIN_DEPTH_CM),"Organic depth under "&PEATLAND_MIN_DEPTH_CM&" cm: by the guide's definition this is not peatland. Report it, but say so. ","")&IF(AND(ISNUMBER($J16),$J16<QC_RECOVERY_MIN),"Recovered only "&TEXT($J16,"0%")&" of the bore depth — the chamber probably did not fill completely. Material is missing, which is not the same as compaction. ","")&IF(AND(ISNUMBER($J16),$J16>1.05),"Recovered more than the bore depth — check the two measurements. ","")&IF(AND(ISNUMBER($I16),$I16>2),"Surface compaction of "&$I16&" cm: depths in this core sit shallower than in the ground, so depth-limited stock is biased. Full-profile stock is unaffected. ",""))
... J124: =IF(OR($G124="",$H124="",$G124=0),"",$H124/$G124) | Q124: =IF($A124="","",IF(SUMPRODUCT(MAX(('3. Peat Data'!$B$5:$B$604=$A124)*'3. Peat Data'!$F$5:$F$604))=0,"",SUMPRODUCT(MAX(('3. Peat Data'!$B$5:$B$604=$A124)*'3. Peat Data'!$F$5:$F$604)))) | R124: =IF($A124="","",IFERROR(SUMIFS('3. Peat Data'!$P$5:$P$604,'3. Peat Data'!$B$5:$B$604,$A124),"")) | S124: =IF($A124="","",IFERROR(SUMIFS('3. Peat Data'!$Q$5:$Q$604,'3. Peat Data'!$B$5:$B$604,$A124),"")) | T124: =IF(NOT(ISNUMBER($Q124)),"",IF($Q124>=REFERENCE_DEPTH_CM,"Yes","No")) | U124: =IF($A124="","",IF(AND($B124<>"",COUNTIF('1. Plot & Site Log'!$A$5:$A$64,$B124)=0),"Plot ID not in Plot & Site Log. ","")&IF(NOT(ISNUMBER($Q124)),"No peat sections logged for this core. ","")&IF($T124="No","Core stops short of the reference depth, so its reference-depth stock is an underestimate. Its full-profile stock is still valid. ","")&IF($L124="No","Core did not reach the mineral contact — the full-profile stock is a MINIMUM, not the whole store. ","")&IF(AND(ISNUMBER($K124),$K124<PEATLAND_MIN_DEPTH_CM),"Organic depth under "&PEATLAND_MIN_DEPTH_CM&" cm: by the guide's definition this is not peatland. Report it, but say so. ","")&IF(AND(ISNUMBER($J124),$J124<QC_RECOVERY_MIN),"Recovered only "&TEXT($J124,"0%")&" of the bore depth — the chamber probably did not fill completely. Material is missing, which is not the same as compaction. ","")&IF(AND(ISNUMBER($J124),$J124>1.05),"Recovered more than the bore depth — check the two measurements. ","")&IF(AND(ISNUMBER($I124),$I124>2),"Surface compaction of "&$I124&" cm: depths in this core sit shallower than in the ground, so depth-limited stock is biased. Full-profile stock is unaffected. ",""))

Sheet 3. Peat Data
A1: PEAT DATA
A2: ONE ROW PER SECTION. Depths run continuously down the core, so the bottom of one section is the top of the next — and they continue across drive boundaries (drive 2 starts where drive 1 ended). Enter either LOI₅₅₀ or a measured organic carbon %; if you have both, the measured value wins.
A4: Plot ID | B4: Core ID | C4: Drive # | D4: Section ID | E4: Top depth (cm) | F4: Bottom depth (cm) | G4: Thickness (cm) | H4: von Post | I4: Bulk density basis | J4: Bulk density (g/cm³) | K4: Water content (%) | L4: LOI₅₅₀ (%) | M4: Organic carbon (%) | N4: Carbon % used | O4: Thickness within reference depth (cm) | P4: Stock, full thickness (kg C/m²) | Q4: Stock to reference depth (kg C/m²) | R4: _stock per cm | S4: Cumulative carbon to base (kg C/m²) | T4: QC flags | U4: Notes
G5: =IF(OR($E5="",$F5=""),"",$F5-$E5) | N5: =IF($M5<>"",$M5,IF($L5<>"",$L5*CARBON_FRACTION_OM,"")) | O5: =IF(OR($E5="",$F5=""),"",MAX(0,MIN($F5,REFERENCE_DEPTH_CM)-MIN($E5,REFERENCE_DEPTH_CM))) | P5: =IF(OR($J5="",$N5="",$G5=""),"",$J5*($N5/100)*$G5*10) | Q5: =IF(OR($J5="",$N5="",$O5=""),"",$J5*($N5/100)*$O5*10) | R5: =IF(OR(NOT(ISNUMBER($P5)),NOT(ISNUMBER($G5)),$G5=0),0,$P5/$G5) | S5: =IF(OR($B5="",NOT(ISNUMBER($F5))),"",SUMIFS('3. Peat Data'!$P$5:$P$604,'3. Peat Data'!$B$5:$B$604,$B5,'3. Peat Data'!$F$5:$F$604,"<="&$F5)) | T5: =IF(AND($A5="",$B5="",$E5=""),"",IF(AND($B5<>"",COUNTIF('2. Core Log'!$A$5:$A$124,$B5)=0),"Core ID not in Core Log. ","")&IF(AND($A5<>"",COUNTIF('1. Plot & Site Log'!$A$5:$A$64,$A5)=0),"Plot ID not in Plot & Site Log. ","")&IF(AND(ISNUMBER($E5),ISNUMBER($F5),$F5<=$E5),"Bottom depth is not below top depth. ","")&IF($I5="","Say which bulk-density basis the lab reported. ","")&IF(AND(ISNUMBER($J5),OR($J5<QC_BD_MIN,$J5>QC_BD_MAX)),"Bulk density outside "&QC_BD_MIN&"–"&QC_BD_MAX&" g/cm³ for peat. Above the top of that range usually means the mineral contact has been passed. ","")&IF(AND(ISNUMBER($N5),$N5>QC_CARBON_PCT_MAX),"Carbon above "&QC_CARBON_PCT_MAX&"% — check units; this may be organic matter rather than carbon. ","")&IF(AND($L5<>"",$M5<>""),"Both LOI and measured carbon given — the measured value is used. ","")&IF(AND($M5="",$L5<>"",OM_FACTOR_IS_LOCAL<>"Yes"),"Carbon derived from LOI using the default factor of "&CARBON_FRACTION_OM&", which has not been calibrated locally. See R1. Reference. ","")&IF(AND(ISNUMBER($O5),$O5=0,ISNUMBER($E5)),"Section lies entirely below the reference depth — it counts to the full-profile stock only. ",""))
G6: =IF(OR($E6="",$F6=""),"",$F6-$E6) | N6: =IF($M6<>"",$M6,IF($L6<>"",$L6*CARBON_FRACTION_OM,"")) | O6: =IF(OR($E6="",$F6=""),"",MAX(0,MIN($F6,REFERENCE_DEPTH_CM)-MIN($E6,REFERENCE_DEPTH_CM))) | P6: =IF(OR($J6="",$N6="",$G6=""),"",$J6*($N6/100)*$G6*10) | Q6: =IF(OR($J6="",$N6="",$O6=""),"",$J6*($N6/100)*$O6*10) | R6: =IF(OR(NOT(ISNUMBER($P6)),NOT(ISNUMBER($G6)),$G6=0),0,$P6/$G6) | S6: =IF(OR($B6="",NOT(ISNUMBER($F6))),"",SUMIFS('3. Peat Data'!$P$5:$P$604,'3. Peat Data'!$B$5:$B$604,$B6,'3. Peat Data'!$F$5:$F$604,"<="&$F6)) | T6: =IF(AND($A6="",$B6="",$E6=""),"",IF(AND($B6<>"",COUNTIF('2. Core Log'!$A$5:$A$124,$B6)=0),"Core ID not in Core Log. ","")&IF(AND($A6<>"",COUNTIF('1. Plot & Site Log'!$A$5:$A$64,$A6)=0),"Plot ID not in Plot & Site Log. ","")&IF(AND(ISNUMBER($E6),ISNUMBER($F6),$F6<=$E6),"Bottom depth is not below top depth. ","")&IF($I6="","Say which bulk-density basis the lab reported. ","")&IF(AND(ISNUMBER($J6),OR($J6<QC_BD_MIN,$J6>QC_BD_MAX)),"Bulk density outside "&QC_BD_MIN&"–"&QC_BD_MAX&" g/cm³ for peat. Above the top of that range usually means the mineral contact has been passed. ","")&IF(AND(ISNUMBER($N6),$N6>QC_CARBON_PCT_MAX),"Carbon above "&QC_CARBON_PCT_MAX&"% — check units; this may be organic matter rather than carbon. ","")&IF(AND($L6<>"",$M6<>""),"Both LOI and measured carbon given — the measured value is used. ","")&IF(AND($M6="",$L6<>"",OM_FACTOR_IS_LOCAL<>"Yes"),"Carbon derived from LOI using the default factor of "&CARBON_FRACTION_OM&", which has not been calibrated locally. See R1. Reference. ","")&IF(AND(ISNUMBER($O6),$O6=0,ISNUMBER($E6)),"Section lies entirely below the reference depth — it counts to the full-profile stock only. ",""))
G7: =IF(OR($E7="",$F7=""),"",$F7-$E7) | N7: =IF($M7<>"",$M7,IF($L7<>"",$L7*CARBON_FRACTION_OM,"")) | O7: =IF(OR($E7="",$F7=""),"",MAX(0,MIN($F7,REFERENCE_DEPTH_CM)-MIN($E7,REFERENCE_DEPTH_CM))) | P7: =IF(OR($J7="",$N7="",$G7=""),"",$J7*($N7/100)*$G7*10) | Q7: =IF(OR($J7="",$N7="",$O7=""),"",$J7*($N7/100)*$O7*10) | R7: =IF(OR(NOT(ISNUMBER($P7)),NOT(ISNUMBER($G7)),$G7=0),0,$P7/$G7) | S7: =IF(OR($B7="",NOT(ISNUMBER($F7))),"",SUMIFS('3. Peat Data'!$P$5:$P$604,'3. Peat Data'!$B$5:$B$604,$B7,'3. Peat Data'!$F$5:$F$604,"<="&$F7)) | T7: =IF(AND($A7="",$B7="",$E7=""),"",IF(AND($B7<>"",COUNTIF('2. Core Log'!$A$5:$A$124,$B7)=0),"Core ID not in Core Log. ","")&IF(AND($A7<>"",COUNTIF('1. Plot & Site Log'!$A$5:$A$64,$A7)=0),"Plot ID not in Plot & Site Log. ","")&IF(AND(ISNUMBER($E7),ISNUMBER($F7),$F7<=$E7),"Bottom depth is not below top depth. ","")&IF($I7="","Say which bulk-density basis the lab reported. ","")&IF(AND(ISNUMBER($J7),OR($J7<QC_BD_MIN,$J7>QC_BD_MAX)),"Bulk density outside "&QC_BD_MIN&"–"&QC_BD_MAX&" g/cm³ for peat. Above the top of that range usually means the mineral contact has been passed. ","")&IF(AND(ISNUMBER($N7),$N7>QC_CARBON_PCT_MAX),"Carbon above "&QC_CARBON_PCT_MAX&"% — check units; this may be organic matter rather than carbon. ","")&IF(AND($L7<>"",$M7<>""),"Both LOI and measured carbon given — the measured value is used. ","")&IF(AND($M7="",$L7<>"",OM_FACTOR_IS_LOCAL<>"Yes"),"Carbon derived from LOI using the default factor of "&CARBON_FRACTION_OM&", which has not been calibrated locally. See R1. Reference. ","")&IF(AND(ISNUMBER($O7),$O7=0,ISNUMBER($E7)),"Section lies entirely below the reference depth — it counts to the full-profile stock only. ",""))
G8: =IF(OR($E8="",$F8=""),"",$F8-$E8) | N8: =IF($M8<>"",$M8,IF($L8<>"",$L8*CARBON_FRACTION_OM,"")) | O8: =IF(OR($E8="",$F8=""),"",MAX(0,MIN($F8,REFERENCE_DEPTH_CM)-MIN($E8,REFERENCE_DEPTH_CM))) | P8: =IF(OR($J8="",$N8="",$G8=""),"",$J8*($N8/100)*$G8*10) | Q8: =IF(OR($J8="",$N8="",$O8=""),"",$J8*($N8/100)*$O8*10) | R8: =IF(OR(NOT(ISNUMBER($P8)),NOT(ISNUMBER($G8)),$G8=0),0,$P8/$G8) | S8: =IF(OR($B8="",NOT(ISNUMBER($F8))),"",SUMIFS('3. Peat Data'!$P$5:$P$604,'3. Peat Data'!$B$5:$B$604,$B8,'3. Peat Data'!$F$5:$F$604,"<="&$F8)) | T8: =IF(AND($A8="",$B8="",$E8=""),"",IF(AND($B8<>"",COUNTIF('2. Core Log'!$A$5:$A$124,$B8)=0),"Core ID not in Core Log. ","")&IF(AND($A8<>"",COUNTIF('1. Plot & Site Log'!$A$5:$A$64,$A8)=0),"Plot ID not in Plot & Site Log. ","")&IF(AND(ISNUMBER($E8),ISNUMBER($F8),$F8<=$E8),"Bottom depth is not below top depth. ","")&IF($I8="","Say which bulk-density basis the lab reported. ","")&IF(AND(ISNUMBER($J8),OR($J8<QC_BD_MIN,$J8>QC_BD_MAX)),"Bulk density outside "&QC_BD_MIN&"–"&QC_BD_MAX&" g/cm³ for peat. Above the top of that range usually means the mineral contact has been passed. ","")&IF(AND(ISNUMBER($N8),$N8>QC_CARBON_PCT_MAX),"Carbon above "&QC_CARBON_PCT_MAX&"% — check units; this may be organic matter rather than carbon. ","")&IF(AND($L8<>"",$M8<>""),"Both LOI and measured carbon given — the measured value is used. ","")&IF(AND($M8="",$L8<>"",OM_FACTOR_IS_LOCAL<>"Yes"),"Carbon derived from LOI using the default factor of "&CARBON_FRACTION_OM&", which has not been calibrated locally. See R1. Reference. ","")&IF(AND(ISNUMBER($O8),$O8=0,ISNUMBER($E8)),"Section lies entirely below the reference depth — it counts to the full-profile stock only. ",""))
G9: =IF(OR($E9="",$F9=""),"",$F9-$E9) | N9: =IF($M9<>"",$M9,IF($L9<>"",$L9*CARBON_FRACTION_OM,"")) | O9: =IF(OR($E9="",$F9=""),"",MAX(0,MIN($F9,REFERENCE_DEPTH_CM)-MIN($E9,REFERENCE_DEPTH_CM))) | P9: =IF(OR($J9="",$N9="",$G9=""),"",$J9*($N9/100)*$G9*10) | Q9: =IF(OR($J9="",$N9="",$O9=""),"",$J9*($N9/100)*$O9*10) | R9: =IF(OR(NOT(ISNUMBER($P9)),NOT(ISNUMBER($G9)),$G9=0),0,$P9/$G9) | S9: =IF(OR($B9="",NOT(ISNUMBER($F9))),"",SUMIFS('3. Peat Data'!$P$5:$P$604,'3. Peat Data'!$B$5:$B$604,$B9,'3. Peat Data'!$F$5:$F$604,"<="&$F9)) | T9: =IF(AND($A9="",$B9="",$E9=""),"",IF(AND($B9<>"",COUNTIF('2. Core Log'!$A$5:$A$124,$B9)=0),"Core ID not in Core Log. ","")&IF(AND($A9<>"",COUNTIF('1. Plot & Site Log'!$A$5:$A$64,$A9)=0),"Plot ID not in Plot & Site Log. ","")&IF(AND(ISNUMBER($E9),ISNUMBER($F9),$F9<=$E9),"Bottom depth is not below top depth. ","")&IF($I9="","Say which bulk-density basis the lab reported. ","")&IF(AND(ISNUMBER($J9),OR($J9<QC_BD_MIN,$J9>QC_BD_MAX)),"Bulk density outside "&QC_BD_MIN&"–"&QC_BD_MAX&" g/cm³ for peat. Above the top of that range usually means the mineral contact has been passed. ","")&IF(AND(ISNUMBER($N9),$N9>QC_CARBON_PCT_MAX),"Carbon above "&QC_CARBON_PCT_MAX&"% — check units; this may be organic matter rather than carbon. ","")&IF(AND($L9<>"",$M9<>""),"Both LOI and measured carbon given — the measured value is used. ","")&IF(AND($M9="",$L9<>"",OM_FACTOR_IS_LOCAL<>"Yes"),"Carbon derived from LOI using the default factor of "&CARBON_FRACTION_OM&", which has not been calibrated locally. See R1. Reference. ","")&IF(AND(ISNUMBER($O9),$O9=0,ISNUMBER($E9)),"Section lies entirely below the reference depth — it counts to the full-profile stock only. ",""))
G10: =IF(OR($E10="",$F10=""),"",$F10-$E10) | N10: =IF($M10<>"",$M10,IF($L10<>"",$L10*CARBON_FRACTION_OM,"")) | O10: =IF(OR($E10="",$F10=""),"",MAX(0,MIN($F10,REFERENCE_DEPTH_CM)-MIN($E10,REFERENCE_DEPTH_CM))) | P10: =IF(OR($J10="",$N10="",$G10=""),"",$J10*($N10/100)*$G10*10) | Q10: =IF(OR($J10="",$N10="",$O10=""),"",$J10*($N10/100)*$O10*10) | R10: =IF(OR(NOT(ISNUMBER($P10)),NOT(ISNUMBER($G10)),$G10=0),0,$P10/$G10) | S10: =IF(OR($B10="",NOT(ISNUMBER($F10))),"",SUMIFS('3. Peat Data'!$P$5:$P$604,'3. Peat Data'!$B$5:$B$604,$B10,'3. Peat Data'!$F$5:$F$604,"<="&$F10)) | T10: =IF(AND($A10="",$B10="",$E10=""),"",IF(AND($B10<>"",COUNTIF('2. Core Log'!$A$5:$A$124,$B10)=0),"Core ID not in Core Log. ","")&IF(AND($A10<>"",COUNTIF('1. Plot & Site Log'!$A$5:$A$64,$A10)=0),"Plot ID not in Plot & Site Log. ","")&IF(AND(ISNUMBER($E10),ISNUMBER($F10),$F10<=$E10),"Bottom depth is not below top depth. ","")&IF($I10="","Say which bulk-density basis the lab reported. ","")&IF(AND(ISNUMBER($J10),OR($J10<QC_BD_MIN,$J10>QC_BD_MAX)),"Bulk density outside "&QC_BD_MIN&"–"&QC_BD_MAX&" g/cm³ for peat. Above the top of that range usually means the mineral contact has been passed. ","")&IF(AND(ISNUMBER($N10),$N10>QC_CARBON_PCT_MAX),"Carbon above "&QC_CARBON_PCT_MAX&"% — check units; this may be organic matter rather than carbon. ","")&IF(AND($L10<>"",$M10<>""),"Both LOI and measured carbon given — the measured value is used. ","")&IF(AND($M10="",$L10<>"",OM_FACTOR_IS_LOCAL<>"Yes"),"Carbon derived from LOI using the default factor of "&CARBON_FRACTION_OM&", which has not been calibrated locally. See R1. Reference. ","")&IF(AND(ISNUMBER($O10),$O10=0,ISNUMBER($E10)),"Section lies entirely below the reference depth — it counts to the full-profile stock only. ",""))
G11: =IF(OR($E11="",$F11=""),"",$F11-$E11) | N11: =IF($M11<>"",$M11,IF($L11<>"",$L11*CARBON_FRACTION_OM,"")) | O11: =IF(OR($E11="",$F11=""),"",MAX(0,MIN($F11,REFERENCE_DEPTH_CM)-MIN($E11,REFERENCE_DEPTH_CM))) | P11: =IF(OR($J11="",$N11="",$G11=""),"",$J11*($N11/100)*$G11*10) | Q11: =IF(OR($J11="",$N11="",$O11=""),"",$J11*($N11/100)*$O11*10) | R11: =IF(OR(NOT(ISNUMBER($P11)),NOT(ISNUMBER($G11)),$G11=0),0,$P11/$G11) | S11: =IF(OR($B11="",NOT(ISNUMBER($F11))),"",SUMIFS('3. Peat Data'!$P$5:$P$604,'3. Peat Data'!$B$5:$B$604,$B11,'3. Peat Data'!$F$5:$F$604,"<="&$F11)) | T11: =IF(AND($A11="",$B11="",$E11=""),"",IF(AND($B11<>"",COUNTIF('2. Core Log'!$A$5:$A$124,$B11)=0),"Core ID not in Core Log. ","")&IF(AND($A11<>"",COUNTIF('1. Plot & Site Log'!$A$5:$A$64,$A11)=0),"Plot ID not in Plot & Site Log. ","")&IF(AND(ISNUMBER($E11),ISNUMBER($F11),$F11<=$E11),"Bottom depth is not below top depth. ","")&IF($I11="","Say which bulk-density basis the lab reported. ","")&IF(AND(ISNUMBER($J11),OR($J11<QC_BD_MIN,$J11>QC_BD_MAX)),"Bulk density outside "&QC_BD_MIN&"–"&QC_BD_MAX&" g/cm³ for peat. Above the top of that range usually means the mineral contact has been passed. ","")&IF(AND(ISNUMBER($N11),$N11>QC_CARBON_PCT_MAX),"Carbon above "&QC_CARBON_PCT_MAX&"% — check units; this may be organic matter rather than carbon. ","")&IF(AND($L11<>"",$M11<>""),"Both LOI and measured carbon given — the measured value is used. ","")&IF(AND($M11="",$L11<>"",OM_FACTOR_IS_LOCAL<>"Yes"),"Carbon derived from LOI using the default factor of "&CARBON_FRACTION_OM&", which has not been calibrated locally. See R1. Reference. ","")&IF(AND(ISNUMBER($O11),$O11=0,ISNUMBER($E11)),"Section lies entirely below the reference depth — it counts to the full-profile stock only. ",""))
G12: =IF(OR($E12="",$F12=""),"",$F12-$E12) | N12: =IF($M12<>"",$M12,IF($L12<>"",$L12*CARBON_FRACTION_OM,"")) | O12: =IF(OR($E12="",$F12=""),"",MAX(0,MIN($F12,REFERENCE_DEPTH_CM)-MIN($E12,REFERENCE_DEPTH_CM))) | P12: =IF(OR($J12="",$N12="",$G12=""),"",$J12*($N12/100)*$G12*10) | Q12: =IF(OR($J12="",$N12="",$O12=""),"",$J12*($N12/100)*$O12*10) | R12: =IF(OR(NOT(ISNUMBER($P12)),NOT(ISNUMBER($G12)),$G12=0),0,$P12/$G12) | S12: =IF(OR($B12="",NOT(ISNUMBER($F12))),"",SUMIFS('3. Peat Data'!$P$5:$P$604,'3. Peat Data'!$B$5:$B$604,$B12,'3. Peat Data'!$F$5:$F$604,"<="&$F12)) | T12: =IF(AND($A12="",$B12="",$E12=""),"",IF(AND($B12<>"",COUNTIF('2. Core Log'!$A$5:$A$124,$B12)=0),"Core ID not in Core Log. ","")&IF(AND($A12<>"",COUNTIF('1. Plot & Site Log'!$A$5:$A$64,$A12)=0),"Plot ID not in Plot & Site Log. ","")&IF(AND(ISNUMBER($E12),ISNUMBER($F12),$F12<=$E12),"Bottom depth is not below top depth. ","")&IF($I12="","Say which bulk-density basis the lab reported. ","")&IF(AND(ISNUMBER($J12),OR($J12<QC_BD_MIN,$J12>QC_BD_MAX)),"Bulk density outside "&QC_BD_MIN&"–"&QC_BD_MAX&" g/cm³ for peat. Above the top of that range usually means the mineral contact has been passed. ","")&IF(AND(ISNUMBER($N12),$N12>QC_CARBON_PCT_MAX),"Carbon above "&QC_CARBON_PCT_MAX&"% — check units; this may be organic matter rather than carbon. ","")&IF(AND($L12<>"",$M12<>""),"Both LOI and measured carbon given — the measured value is used. ","")&IF(AND($M12="",$L12<>"",OM_FACTOR_IS_LOCAL<>"Yes"),"Carbon derived from LOI using the default factor of "&CARBON_FRACTION_OM&", which has not been calibrated locally. See R1. Reference. ","")&IF(AND(ISNUMBER($O12),$O12=0,ISNUMBER($E12)),"Section lies entirely below the reference depth — it counts to the full-profile stock only. ",""))
G13: =IF(OR($E13="",$F13=""),"",$F13-$E13) | N13: =IF($M13<>"",$M13,IF($L13<>"",$L13*CARBON_FRACTION_OM,"")) | O13: =IF(OR($E13="",$F13=""),"",MAX(0,MIN($F13,REFERENCE_DEPTH_CM)-MIN($E13,REFERENCE_DEPTH_CM))) | P13: =IF(OR($J13="",$N13="",$G13=""),"",$J13*($N13/100)*$G13*10) | Q13: =IF(OR($J13="",$N13="",$O13=""),"",$J13*($N13/100)*$O13*10) | R13: =IF(OR(NOT(ISNUMBER($P13)),NOT(ISNUMBER($G13)),$G13=0),0,$P13/$G13) | S13: =IF(OR($B13="",NOT(ISNUMBER($F13))),"",SUMIFS('3. Peat Data'!$P$5:$P$604,'3. Peat Data'!$B$5:$B$604,$B13,'3. Peat Data'!$F$5:$F$604,"<="&$F13)) | T13: =IF(AND($A13="",$B13="",$E13=""),"",IF(AND($B13<>"",COUNTIF('2. Core Log'!$A$5:$A$124,$B13)=0),"Core ID not in Core Log. ","")&IF(AND($A13<>"",COUNTIF('1. Plot & Site Log'!$A$5:$A$64,$A13)=0),"Plot ID not in Plot & Site Log. ","")&IF(AND(ISNUMBER($E13),ISNUMBER($F13),$F13<=$E13),"Bottom depth is not below top depth. ","")&IF($I13="","Say which bulk-density basis the lab reported. ","")&IF(AND(ISNUMBER($J13),OR($J13<QC_BD_MIN,$J13>QC_BD_MAX)),"Bulk density outside "&QC_BD_MIN&"–"&QC_BD_MAX&" g/cm³ for peat. Above the top of that range usually means the mineral contact has been passed. ","")&IF(AND(ISNUMBER($N13),$N13>QC_CARBON_PCT_MAX),"Carbon above "&QC_CARBON_PCT_MAX&"% — check units; this may be organic matter rather than carbon. ","")&IF(AND($L13<>"",$M13<>""),"Both LOI and measured carbon given — the measured value is used. ","")&IF(AND($M13="",$L13<>"",OM_FACTOR_IS_LOCAL<>"Yes"),"Carbon derived from LOI using the default factor of "&CARBON_FRACTION_OM&", which has not been calibrated locally. See R1. Reference. ","")&IF(AND(ISNUMBER($O13),$O13=0,ISNUMBER($E13)),"Section lies entirely below the reference depth — it counts to the full-profile stock only. ",""))
G14: =IF(OR($E14="",$F14=""),"",$F14-$E14) | N14: =IF($M14<>"",$M14,IF($L14<>"",$L14*CARBON_FRACTION_OM,"")) | O14: =IF(OR($E14="",$F14=""),"",MAX(0,MIN($F14,REFERENCE_DEPTH_CM)-MIN($E14,REFERENCE_DEPTH_CM))) | P14: =IF(OR($J14="",$N14="",$G14=""),"",$J14*($N14/100)*$G14*10) | Q14: =IF(OR($J14="",$N14="",$O14=""),"",$J14*($N14/100)*$O14*10) | R14: =IF(OR(NOT(ISNUMBER($P14)),NOT(ISNUMBER($G14)),$G14=0),0,$P14/$G14) | S14: =IF(OR($B14="",NOT(ISNUMBER($F14))),"",SUMIFS('3. Peat Data'!$P$5:$P$604,'3. Peat Data'!$B$5:$B$604,$B14,'3. Peat Data'!$F$5:$F$604,"<="&$F14)) | T14: =IF(AND($A14="",$B14="",$E14=""),"",IF(AND($B14<>"",COUNTIF('2. Core Log'!$A$5:$A$124,$B14)=0),"Core ID not in Core Log. ","")&IF(AND($A14<>"",COUNTIF('1. Plot & Site Log'!$A$5:$A$64,$A14)=0),"Plot ID not in Plot & Site Log. ","")&IF(AND(ISNUMBER($E14),ISNUMBER($F14),$F14<=$E14),"Bottom depth is not below top depth. ","")&IF($I14="","Say which bulk-density basis the lab reported. ","")&IF(AND(ISNUMBER($J14),OR($J14<QC_BD_MIN,$J14>QC_BD_MAX)),"Bulk density outside "&QC_BD_MIN&"–"&QC_BD_MAX&" g/cm³ for peat. Above the top of that range usually means the mineral contact has been passed. ","")&IF(AND(ISNUMBER($N14),$N14>QC_CARBON_PCT_MAX),"Carbon above "&QC_CARBON_PCT_MAX&"% — check units; this may be organic matter rather than carbon. ","")&IF(AND($L14<>"",$M14<>""),"Both LOI and measured carbon given — the measured value is used. ","")&IF(AND($M14="",$L14<>"",OM_FACTOR_IS_LOCAL<>"Yes"),"Carbon derived from LOI using the default factor of "&CARBON_FRACTION_OM&", which has not been calibrated locally. See R1. Reference. ","")&IF(AND(ISNUMBER($O14),$O14=0,ISNUMBER($E14)),"Section lies entirely below the reference depth — it counts to the full-profile stock only. ",""))
G15: =IF(OR($E15="",$F15=""),"",$F15-$E15) | N15: =IF($M15<>"",$M15,IF($L15<>"",$L15*CARBON_FRACTION_OM,"")) | O15: =IF(OR($E15="",$F15=""),"",MAX(0,MIN($F15,REFERENCE_DEPTH_CM)-MIN($E15,REFERENCE_DEPTH_CM))) | P15: =IF(OR($J15="",$N15="",$G15=""),"",$J15*($N15/100)*$G15*10) | Q15: =IF(OR($J15="",$N15="",$O15=""),"",$J15*($N15/100)*$O15*10) | R15: =IF(OR(NOT(ISNUMBER($P15)),NOT(ISNUMBER($G15)),$G15=0),0,$P15/$G15) | S15: =IF(OR($B15="",NOT(ISNUMBER($F15))),"",SUMIFS('3. Peat Data'!$P$5:$P$604,'3. Peat Data'!$B$5:$B$604,$B15,'3. Peat Data'!$F$5:$F$604,"<="&$F15)) | T15: =IF(AND($A15="",$B15="",$E15=""),"",IF(AND($B15<>"",COUNTIF('2. Core Log'!$A$5:$A$124,$B15)=0),"Core ID not in Core Log. ","")&IF(AND($A15<>"",COUNTIF('1. Plot & Site Log'!$A$5:$A$64,$A15)=0),"Plot ID not in Plot & Site Log. ","")&IF(AND(ISNUMBER($E15),ISNUMBER($F15),$F15<=$E15),"Bottom depth is not below top depth. ","")&IF($I15="","Say which bulk-density basis the lab reported. ","")&IF(AND(ISNUMBER($J15),OR($J15<QC_BD_MIN,$J15>QC_BD_MAX)),"Bulk density outside "&QC_BD_MIN&"–"&QC_BD_MAX&" g/cm³ for peat. Above the top of that range usually means the mineral contact has been passed. ","")&IF(AND(ISNUMBER($N15),$N15>QC_CARBON_PCT_MAX),"Carbon above "&QC_CARBON_PCT_MAX&"% — check units; this may be organic matter rather than carbon. ","")&IF(AND($L15<>"",$M15<>""),"Both LOI and measured carbon given — the measured value is used. ","")&IF(AND($M15="",$L15<>"",OM_FACTOR_IS_LOCAL<>"Yes"),"Carbon derived from LOI using the default factor of "&CARBON_FRACTION_OM&", which has not been calibrated locally. See R1. Reference. ","")&IF(AND(ISNUMBER($O15),$O15=0,ISNUMBER($E15)),"Section lies entirely below the reference depth — it counts to the full-profile stock only. ",""))
G16: =IF(OR($E16="",$F16=""),"",$F16-$E16) | N16: =IF($M16<>"",$M16,IF($L16<>"",$L16*CARBON_FRACTION_OM,"")) | O16: =IF(OR($E16="",$F16=""),"",MAX(0,MIN($F16,REFERENCE_DEPTH_CM)-MIN($E16,REFERENCE_DEPTH_CM))) | P16: =IF(OR($J16="",$N16="",$G16=""),"",$J16*($N16/100)*$G16*10) | Q16: =IF(OR($J16="",$N16="",$O16=""),"",$J16*($N16/100)*$O16*10) | R16: =IF(OR(NOT(ISNUMBER($P16)),NOT(ISNUMBER($G16)),$G16=0),0,$P16/$G16) | S16: =IF(OR($B16="",NOT(ISNUMBER($F16))),"",SUMIFS('3. Peat Data'!$P$5:$P$604,'3. Peat Data'!$B$5:$B$604,$B16,'3. Peat Data'!$F$5:$F$604,"<="&$F16)) | T16: =IF(AND($A16="",$B16="",$E16=""),"",IF(AND($B16<>"",COUNTIF('2. Core Log'!$A$5:$A$124,$B16)=0),"Core ID not in Core Log. ","")&IF(AND($A16<>"",COUNTIF('1. Plot & Site Log'!$A$5:$A$64,$A16)=0),"Plot ID not in Plot & Site Log. ","")&IF(AND(ISNUMBER($E16),ISNUMBER($F16),$F16<=$E16),"Bottom depth is not below top depth. ","")&IF($I16="","Say which bulk-density basis the lab reported. ","")&IF(AND(ISNUMBER($J16),OR($J16<QC_BD_MIN,$J16>QC_BD_MAX)),"Bulk density outside "&QC_BD_MIN&"–"&QC_BD_MAX&" g/cm³ for peat. Above the top of that range usually means the mineral contact has been passed. ","")&IF(AND(ISNUMBER($N16),$N16>QC_CARBON_PCT_MAX),"Carbon above "&QC_CARBON_PCT_MAX&"% — check units; this may be organic matter rather than carbon. ","")&IF(AND($L16<>"",$M16<>""),"Both LOI and measured carbon given — the measured value is used. ","")&IF(AND($M16="",$L16<>"",OM_FACTOR_IS_LOCAL<>"Yes"),"Carbon derived from LOI using the default factor of "&CARBON_FRACTION_OM&", which has not been calibrated locally. See R1. Reference. ","")&IF(AND(ISNUMBER($O16),$O16=0,ISNUMBER($E16)),"Section lies entirely below the reference depth — it counts to the full-profile stock only. ",""))
... G604: =IF(OR($E604="",$F604=""),"",$F604-$E604) | N604: =IF($M604<>"",$M604,IF($L604<>"",$L604*CARBON_FRACTION_OM,"")) | O604: =IF(OR($E604="",$F604=""),"",MAX(0,MIN($F604,REFERENCE_DEPTH_CM)-MIN($E604,REFERENCE_DEPTH_CM))) | P604: =IF(OR($J604="",$N604="",$G604=""),"",$J604*($N604/100)*$G604*10) | Q604: =IF(OR($J604="",$N604="",$O604=""),"",$J604*($N604/100)*$O604*10) | R604: =IF(OR(NOT(ISNUMBER($P604)),NOT(ISNUMBER($G604)),$G604=0),0,$P604/$G604) | S604: =IF(OR($B604="",NOT(ISNUMBER($F604))),"",SUMIFS('3. Peat Data'!$P$5:$P$604,'3. Peat Data'!$B$5:$B$604,$B604,'3. Peat Data'!$F$5:$F$604,"<="&$F604)) | T604: =IF(AND($A604="",$B604="",$E604=""),"",IF(AND($B604<>"",COUNTIF('2. Core Log'!$A$5:$A$124,$B604)=0),"Core ID not in Core Log. ","")&IF(AND($A604<>"",COUNTIF('1. Plot & Site Log'!$A$5:$A$64,$A604)=0),"Plot ID not in Plot & Site Log. ","")&IF(AND(ISNUMBER($E604),ISNUMBER($F604),$F604<=$E604),"Bottom depth is not below top depth. ","")&IF($I604="","Say which bulk-density basis the lab reported. ","")&IF(AND(ISNUMBER($J604),OR($J604<QC_BD_MIN,$J604>QC_BD_MAX)),"Bulk density outside "&QC_BD_MIN&"–"&QC_BD_MAX&" g/cm³ for peat. Above the top of that range usually means the mineral contact has been passed. ","")&IF(AND(ISNUMBER($N604),$N604>QC_CARBON_PCT_MAX),"Carbon above "&QC_CARBON_PCT_MAX&"% — check units; this may be organic matter rather than carbon. ","")&IF(AND($L604<>"",$M604<>""),"Both LOI and measured carbon given — the measured value is used. ","")&IF(AND($M604="",$L604<>"",OM_FACTOR_IS_LOCAL<>"Yes"),"Carbon derived from LOI using the default factor of "&CARBON_FRACTION_OM&", which has not been calibrated locally. See R1. Reference. ","")&IF(AND(ISNUMBER($O604),$O604=0,ISNUMBER($E604)),"Section lies entirely below the reference depth — it counts to the full-profile stock only. ",""))

Sheet 4. Chronology
A1: CHRONOLOGY
A2: OPTIONAL — only if the core has been dated. ONE ROW PER DATED HORIZON. Age is in years BEFORE THE CORING YEAR, not years BP (which is referenced to 1950). The age-depth modelling itself happens in R — see Part 5 — and what you type here are its outputs. Carbon comes from the peat sheet, so nothing is entered twice.
A4: Core ID | B4: Depth (cm) | C4: Age (yr before coring) | D4: Age ± (yr) | E4: Date source | F4: Cumulative carbon at depth (kg C/m²) | G4: Interval SAR (cm/yr) | H4: Interval CAR (g C/m²/yr) | I4: QC flags | J4: _recent | K4: _prevdepth
F5: =IF(OR($A5="",NOT(ISNUMBER($B5))),"",SUMIFS('3. Peat Data'!$P$5:$P$604,'3. Peat Data'!$B$5:$B$604,$A5,'3. Peat Data'!$F$5:$F$604,"<="&$B5)+SUMPRODUCT(('3. Peat Data'!$B$5:$B$604=$A5)*('3. Peat Data'!$E$5:$E$604<$B5)*('3. Peat Data'!$F$5:$F$604>$B5)*'3. Peat Data'!$R$5:$R$604*($B5-'3. Peat Data'!$E$5:$E$604))) | G5: =IF(OR($A5="",NOT(ISNUMBER($B5)),NOT(ISNUMBER($C5))),"",IFERROR(($B5-$K5)/($C5-IF($K5=0,0,SUMIFS('4. Chronology'!$C$5:$C$204,'4. Chronology'!$A$5:$A$204,$A5,'4. Chronology'!$B$5:$B$204,$K5))),"")) | H5: =IF(OR($A5="",NOT(ISNUMBER($F5)),NOT(ISNUMBER($C5))),"",IFERROR((($F5-IF($K5=0,0,SUMIFS('4. Chronology'!$F$5:$F$204,'4. Chronology'!$A$5:$A$204,$A5,'4. Chronology'!$B$5:$B$204,$K5)))*1000)/($C5-IF($K5=0,0,SUMIFS('4. Chronology'!$C$5:$C$204,'4. Chronology'!$A$5:$A$204,$A5,'4. Chronology'!$B$5:$B$204,$K5))),"")) | I5: =IF($A5="","",IF(COUNTIF('2. Core Log'!$A$5:$A$124,$A5)=0,"Core ID not in Core Log. ","")&IF($E5="","No date source given — RERCA and LORCA need to know which method produced this age. ","")&IF(AND(ISNUMBER($C5),$C5<0),"Negative age: this horizon post-dates the coring year. Check the conversion. ","")&IF(AND(ISNUMBER($G5),$G5<0),"Age reversal — this horizon is younger than one above it. A mixed or disturbed profile may not be datable at all. ","")&IF(AND(ISNUMBER($D5),ISNUMBER($C5),$C5>0,$D5/$C5>0.5),"Age uncertainty exceeds 50% of the age. Usable as an indication only. ","")&IF(AND($D5="",$C5<>""),"No uncertainty given. Every radiometric age has one; a rate without it cannot be defended. ","")) | J5: =IF($E5="",0,IF(OR(LEFT($E5,6)="Pb-210",LEFT($E5,6)="Cs-137"),1,0)) | K5: =IF(OR($A5="",NOT(ISNUMBER($B5))),"",SUMPRODUCT(MAX(('4. Chronology'!$A$5:$A$204=$A5)*('4. Chronology'!$B$5:$B$204<$B5)*'4. Chronology'!$B$5:$B$204)))
F6: =IF(OR($A6="",NOT(ISNUMBER($B6))),"",SUMIFS('3. Peat Data'!$P$5:$P$604,'3. Peat Data'!$B$5:$B$604,$A6,'3. Peat Data'!$F$5:$F$604,"<="&$B6)+SUMPRODUCT(('3. Peat Data'!$B$5:$B$604=$A6)*('3. Peat Data'!$E$5:$E$604<$B6)*('3. Peat Data'!$F$5:$F$604>$B6)*'3. Peat Data'!$R$5:$R$604*($B6-'3. Peat Data'!$E$5:$E$604))) | G6: =IF(OR($A6="",NOT(ISNUMBER($B6)),NOT(ISNUMBER($C6))),"",IFERROR(($B6-$K6)/($C6-IF($K6=0,0,SUMIFS('4. Chronology'!$C$5:$C$204,'4. Chronology'!$A$5:$A$204,$A6,'4. Chronology'!$B$5:$B$204,$K6))),"")) | H6: =IF(OR($A6="",NOT(ISNUMBER($F6)),NOT(ISNUMBER($C6))),"",IFERROR((($F6-IF($K6=0,0,SUMIFS('4. Chronology'!$F$5:$F$204,'4. Chronology'!$A$5:$A$204,$A6,'4. Chronology'!$B$5:$B$204,$K6)))*1000)/($C6-IF($K6=0,0,SUMIFS('4. Chronology'!$C$5:$C$204,'4. Chronology'!$A$5:$A$204,$A6,'4. Chronology'!$B$5:$B$204,$K6))),"")) | I6: =IF($A6="","",IF(COUNTIF('2. Core Log'!$A$5:$A$124,$A6)=0,"Core ID not in Core Log. ","")&IF($E6="","No date source given — RERCA and LORCA need to know which method produced this age. ","")&IF(AND(ISNUMBER($C6),$C6<0),"Negative age: this horizon post-dates the coring year. Check the conversion. ","")&IF(AND(ISNUMBER($G6),$G6<0),"Age reversal — this horizon is younger than one above it. A mixed or disturbed profile may not be datable at all. ","")&IF(AND(ISNUMBER($D6),ISNUMBER($C6),$C6>0,$D6/$C6>0.5),"Age uncertainty exceeds 50% of the age. Usable as an indication only. ","")&IF(AND($D6="",$C6<>""),"No uncertainty given. Every radiometric age has one; a rate without it cannot be defended. ","")) | J6: =IF($E6="",0,IF(OR(LEFT($E6,6)="Pb-210",LEFT($E6,6)="Cs-137"),1,0)) | K6: =IF(OR($A6="",NOT(ISNUMBER($B6))),"",SUMPRODUCT(MAX(('4. Chronology'!$A$5:$A$204=$A6)*('4. Chronology'!$B$5:$B$204<$B6)*'4. Chronology'!$B$5:$B$204)))
F7: =IF(OR($A7="",NOT(ISNUMBER($B7))),"",SUMIFS('3. Peat Data'!$P$5:$P$604,'3. Peat Data'!$B$5:$B$604,$A7,'3. Peat Data'!$F$5:$F$604,"<="&$B7)+SUMPRODUCT(('3. Peat Data'!$B$5:$B$604=$A7)*('3. Peat Data'!$E$5:$E$604<$B7)*('3. Peat Data'!$F$5:$F$604>$B7)*'3. Peat Data'!$R$5:$R$604*($B7-'3. Peat Data'!$E$5:$E$604))) | G7: =IF(OR($A7="",NOT(ISNUMBER($B7)),NOT(ISNUMBER($C7))),"",IFERROR(($B7-$K7)/($C7-IF($K7=0,0,SUMIFS('4. Chronology'!$C$5:$C$204,'4. Chronology'!$A$5:$A$204,$A7,'4. Chronology'!$B$5:$B$204,$K7))),"")) | H7: =IF(OR($A7="",NOT(ISNUMBER($F7)),NOT(ISNUMBER($C7))),"",IFERROR((($F7-IF($K7=0,0,SUMIFS('4. Chronology'!$F$5:$F$204,'4. Chronology'!$A$5:$A$204,$A7,'4. Chronology'!$B$5:$B$204,$K7)))*1000)/($C7-IF($K7=0,0,SUMIFS('4. Chronology'!$C$5:$C$204,'4. Chronology'!$A$5:$A$204,$A7,'4. Chronology'!$B$5:$B$204,$K7))),"")) | I7: =IF($A7="","",IF(COUNTIF('2. Core Log'!$A$5:$A$124,$A7)=0,"Core ID not in Core Log. ","")&IF($E7="","No date source given — RERCA and LORCA need to know which method produced this age. ","")&IF(AND(ISNUMBER($C7),$C7<0),"Negative age: this horizon post-dates the coring year. Check the conversion. ","")&IF(AND(ISNUMBER($G7),$G7<0),"Age reversal — this horizon is younger than one above it. A mixed or disturbed profile may not be datable at all. ","")&IF(AND(ISNUMBER($D7),ISNUMBER($C7),$C7>0,$D7/$C7>0.5),"Age uncertainty exceeds 50% of the age. Usable as an indication only. ","")&IF(AND($D7="",$C7<>""),"No uncertainty given. Every radiometric age has one; a rate without it cannot be defended. ","")) | J7: =IF($E7="",0,IF(OR(LEFT($E7,6)="Pb-210",LEFT($E7,6)="Cs-137"),1,0)) | K7: =IF(OR($A7="",NOT(ISNUMBER($B7))),"",SUMPRODUCT(MAX(('4. Chronology'!$A$5:$A$204=$A7)*('4. Chronology'!$B$5:$B$204<$B7)*'4. Chronology'!$B$5:$B$204)))
F8: =IF(OR($A8="",NOT(ISNUMBER($B8))),"",SUMIFS('3. Peat Data'!$P$5:$P$604,'3. Peat Data'!$B$5:$B$604,$A8,'3. Peat Data'!$F$5:$F$604,"<="&$B8)+SUMPRODUCT(('3. Peat Data'!$B$5:$B$604=$A8)*('3. Peat Data'!$E$5:$E$604<$B8)*('3. Peat Data'!$F$5:$F$604>$B8)*'3. Peat Data'!$R$5:$R$604*($B8-'3. Peat Data'!$E$5:$E$604))) | G8: =IF(OR($A8="",NOT(ISNUMBER($B8)),NOT(ISNUMBER($C8))),"",IFERROR(($B8-$K8)/($C8-IF($K8=0,0,SUMIFS('4. Chronology'!$C$5:$C$204,'4. Chronology'!$A$5:$A$204,$A8,'4. Chronology'!$B$5:$B$204,$K8))),"")) | H8: =IF(OR($A8="",NOT(ISNUMBER($F8)),NOT(ISNUMBER($C8))),"",IFERROR((($F8-IF($K8=0,0,SUMIFS('4. Chronology'!$F$5:$F$204,'4. Chronology'!$A$5:$A$204,$A8,'4. Chronology'!$B$5:$B$204,$K8)))*1000)/($C8-IF($K8=0,0,SUMIFS('4. Chronology'!$C$5:$C$204,'4. Chronology'!$A$5:$A$204,$A8,'4. Chronology'!$B$5:$B$204,$K8))),"")) | I8: =IF($A8="","",IF(COUNTIF('2. Core Log'!$A$5:$A$124,$A8)=0,"Core ID not in Core Log. ","")&IF($E8="","No date source given — RERCA and LORCA need to know which method produced this age. ","")&IF(AND(ISNUMBER($C8),$C8<0),"Negative age: this horizon post-dates the coring year. Check the conversion. ","")&IF(AND(ISNUMBER($G8),$G8<0),"Age reversal — this horizon is younger than one above it. A mixed or disturbed profile may not be datable at all. ","")&IF(AND(ISNUMBER($D8),ISNUMBER($C8),$C8>0,$D8/$C8>0.5),"Age uncertainty exceeds 50% of the age. Usable as an indication only. ","")&IF(AND($D8="",$C8<>""),"No uncertainty given. Every radiometric age has one; a rate without it cannot be defended. ","")) | J8: =IF($E8="",0,IF(OR(LEFT($E8,6)="Pb-210",LEFT($E8,6)="Cs-137"),1,0)) | K8: =IF(OR($A8="",NOT(ISNUMBER($B8))),"",SUMPRODUCT(MAX(('4. Chronology'!$A$5:$A$204=$A8)*('4. Chronology'!$B$5:$B$204<$B8)*'4. Chronology'!$B$5:$B$204)))
